2024-01-02 00:51:08,887 T0002: INFO  Connecting to device (V1): sonic_ssh: None:22 ..
2024-01-02 00:51:08,887 T0002: INFO  TRY Authentication: None:22 admin YourPaSsWoRd
2024-01-02 00:51:08,888 T0002: INFO  ======== Connection: Connection Unknown Error.. ======
2024-01-02 00:51:08,889 T0002: INFO  Traceback (most recent call last):
2024-01-02 00:51:08,890 T0002: INFO    File "/repo/spytest/access/netmiko_connection.py", line 82, in __init__
2024-01-02 00:51:08,890 T0002: INFO      super(NetmikoConnection, self).__init__(**kwargs)
2024-01-02 00:51:08,891 T0002: INFO    File "/usr/local/lib/python3.8/dist-packages/netmiko/base_connection.py", line 244, in __init__
2024-01-02 00:51:08,892 T0002: INFO      raise ValueError("Either ip or host must be set")
2024-01-02 00:51:08,892 T0002: INFO  ValueError: Either ip or host must be se
2024-01-02 00:51:08,893 T0002: INFO  StackTraceCallStack:
2024-01-02 00:51:08,893 T0002: INFO  [0] spytest/access/netmiko_connection.py:104 __init__ self.log_exception(msg, call_stack=True, dump=True)
2024-01-02 00:51:08,894 T0002: INFO  [1] spytest/access/connection.py:48 _DeviceConnection return NetmikoConnection(**kwargs)
2024-01-02 00:51:08,895 T0002: INFO  [2] spytest/access/connection.py:160 DeviceConnection hndl = _DeviceConnection(devname, ip_port, logger, **kwargs)
2024-01-02 00:51:08,895 T0002: INFO  [3] spytest/net.py:694 _do_connect_cinfo net_connect = DeviceConnection(devname=dut_name, logger=self.logger, **cinfo)
2024-01-02 00:51:08,896 T0002: INFO  [4] spytest/net.py:723 _connect_to_device net_connect = self._do_connect_cinfo(cinfo, retry, msgs, devname)
2024-01-02 00:51:08,897 T0002: INFO  [5] spytest/net.py:1118 connect_to_device_real net_connect = self._connect_to_device(connection_param, access, retry=retry)
2024-01-02 00:51:08,897 T0002: INFO  [6] spytest/net.py:1064 connect_to_device show_ver_output = self.connect_to_device_real(access, retry, recon, recover)
2024-01-02 00:51:08,898 T0002: INFO  [7] utilities/parallel.py:159 _thread_func retvals[index] = func(*args, **kwargs)
2024-01-02 00:51:08,899 T0002: INFO  [8] utilities/parallel.py:182 exec_foreach2 _thread_func(*args, **kwargs)
2024-01-02 00:51:08,899 T0002: INFO  [9] spytest/net.py:1584 connect_all_devices rvs, exps = putils.exec_foreach2(faster_init, on_except, self.topo.duts,
2024-01-02 00:51:08,900 T0002: INFO  [10] utilities/parallel.py:219 _thread_func retvals[index] = func(*args, **kwargs)
2024-01-02 00:51:08,900 T0002: INFO  --------------------------------------------
2024-01-02 00:51:08,901 T0002: INFO  ============================================
2024-01-02 00:51:08,901 T0002: WARN  Exception(None:22): Runtime Exception: Connection Unknown Error..
2024-01-02 00:51:08,901 T0002: INFO  TRY ALT Authentication: None:22 admin broadcom
2024-01-02 00:51:08,902 T0002: INFO  ======== Connection: Connection Unknown Error.. ======
2024-01-02 00:51:08,903 T0002: INFO  Traceback (most recent call last):
2024-01-02 00:51:08,903 T0002: INFO    File "/repo/spytest/access/netmiko_connection.py", line 82, in __init__
2024-01-02 00:51:08,904 T0002: INFO      super(NetmikoConnection, self).__init__(**kwargs)
2024-01-02 00:51:08,904 T0002: INFO    File "/usr/local/lib/python3.8/dist-packages/netmiko/base_connection.py", line 244, in __init__
2024-01-02 00:51:08,905 T0002: INFO      raise ValueError("Either ip or host must be set")
2024-01-02 00:51:08,905 T0002: INFO  ValueError: Either ip or host must be se
2024-01-02 00:51:08,906 T0002: INFO  StackTraceCallStack:
2024-01-02 00:51:08,907 T0002: INFO  [0] spytest/access/netmiko_connection.py:104 __init__ self.log_exception(msg, call_stack=True, dump=True)
2024-01-02 00:51:08,907 T0002: INFO  [1] spytest/access/connection.py:48 _DeviceConnection return NetmikoConnection(**kwargs)
2024-01-02 00:51:08,908 T0002: INFO  [2] spytest/access/connection.py:160 DeviceConnection hndl = _DeviceConnection(devname, ip_port, logger, **kwargs)
2024-01-02 00:51:08,908 T0002: INFO  [3] spytest/net.py:694 _do_connect_cinfo net_connect = DeviceConnection(devname=dut_name, logger=self.logger, **cinfo)
2024-01-02 00:51:08,909 T0002: INFO  [4] spytest/net.py:723 _connect_to_device net_connect = self._do_connect_cinfo(cinfo, retry, msgs, devname)
2024-01-02 00:51:08,910 T0002: INFO  [5] spytest/net.py:1118 connect_to_device_real net_connect = self._connect_to_device(connection_param, access, retry=retry)
2024-01-02 00:51:08,910 T0002: INFO  [6] spytest/net.py:1064 connect_to_device show_ver_output = self.connect_to_device_real(access, retry, recon, recover)
2024-01-02 00:51:08,911 T0002: INFO  [7] utilities/parallel.py:159 _thread_func retvals[index] = func(*args, **kwargs)
2024-01-02 00:51:08,911 T0002: INFO  [8] utilities/parallel.py:182 exec_foreach2 _thread_func(*args, **kwargs)
2024-01-02 00:51:08,912 T0002: INFO  [9] spytest/net.py:1584 connect_all_devices rvs, exps = putils.exec_foreach2(faster_init, on_except, self.topo.duts,
2024-01-02 00:51:08,913 T0002: INFO  [10] utilities/parallel.py:219 _thread_func retvals[index] = func(*args, **kwargs)
2024-01-02 00:51:08,913 T0002: INFO  --------------------------------------------
2024-01-02 00:51:08,914 T0002: INFO  ============================================
2024-01-02 00:51:08,914 T0002: WARN  Exception(None:22): Runtime Exception: Connection Unknown Error..
2024-01-02 00:51:08,914 T0002: INFO  connection-Err..
2024-01-02 00:51:12,921 T0002: INFO  Re-Trying 2..
2024-01-02 00:51:12,922 T0002: INFO  TRY Authentication: None:22 admin YourPaSsWoRd
2024-01-02 00:51:12,924 T0002: INFO  ======== Connection: Connection Unknown Error.. ======
2024-01-02 00:51:12,927 T0002: INFO  Traceback (most recent call last):
2024-01-02 00:51:12,929 T0002: INFO    File "/repo/spytest/access/netmiko_connection.py", line 82, in __init__
2024-01-02 00:51:12,931 T0002: INFO      super(NetmikoConnection, self).__init__(**kwargs)
2024-01-02 00:51:12,933 T0002: INFO    File "/usr/local/lib/python3.8/dist-packages/netmiko/base_connection.py", line 244, in __init__
2024-01-02 00:51:12,934 T0002: INFO      raise ValueError("Either ip or host must be set")
2024-01-02 00:51:12,935 T0002: INFO  ValueError: Either ip or host must be se
2024-01-02 00:51:12,935 T0002: INFO  StackTraceCallStack:
2024-01-02 00:51:12,936 T0002: INFO  [0] spytest/access/netmiko_connection.py:104 __init__ self.log_exception(msg, call_stack=True, dump=True)
2024-01-02 00:51:12,937 T0002: INFO  [1] spytest/access/connection.py:48 _DeviceConnection return NetmikoConnection(**kwargs)
2024-01-02 00:51:12,937 T0002: INFO  [2] spytest/access/connection.py:160 DeviceConnection hndl = _DeviceConnection(devname, ip_port, logger, **kwargs)
2024-01-02 00:51:12,938 T0002: INFO  [3] spytest/net.py:694 _do_connect_cinfo net_connect = DeviceConnection(devname=dut_name, logger=self.logger, **cinfo)
2024-01-02 00:51:12,939 T0002: INFO  [4] spytest/net.py:723 _connect_to_device net_connect = self._do_connect_cinfo(cinfo, retry, msgs, devname)
2024-01-02 00:51:12,939 T0002: INFO  [5] spytest/net.py:1118 connect_to_device_real net_connect = self._connect_to_device(connection_param, access, retry=retry)
2024-01-02 00:51:12,940 T0002: INFO  [6] spytest/net.py:1064 connect_to_device show_ver_output = self.connect_to_device_real(access, retry, recon, recover)
2024-01-02 00:51:12,940 T0002: INFO  [7] utilities/parallel.py:159 _thread_func retvals[index] = func(*args, **kwargs)
2024-01-02 00:51:12,941 T0002: INFO  [8] utilities/parallel.py:182 exec_foreach2 _thread_func(*args, **kwargs)
2024-01-02 00:51:12,941 T0002: INFO  [9] spytest/net.py:1584 connect_all_devices rvs, exps = putils.exec_foreach2(faster_init, on_except, self.topo.duts,
2024-01-02 00:51:12,942 T0002: INFO  [10] utilities/parallel.py:219 _thread_func retvals[index] = func(*args, **kwargs)
2024-01-02 00:51:12,942 T0002: INFO  --------------------------------------------
2024-01-02 00:51:12,943 T0002: INFO  ============================================
2024-01-02 00:51:12,943 T0002: WARN  Exception(None:22): Runtime Exception: Connection Unknown Error..
2024-01-02 00:51:12,943 T0002: INFO  TRY ALT Authentication: None:22 admin broadcom
2024-01-02 00:51:12,944 T0002: INFO  ======== Connection: Connection Unknown Error.. ======
2024-01-02 00:51:12,945 T0002: INFO  Traceback (most recent call last):
2024-01-02 00:51:12,945 T0002: INFO    File "/repo/spytest/access/netmiko_connection.py", line 82, in __init__
2024-01-02 00:51:12,946 T0002: INFO      super(NetmikoConnection, self).__init__(**kwargs)
2024-01-02 00:51:12,946 T0002: INFO    File "/usr/local/lib/python3.8/dist-packages/netmiko/base_connection.py", line 244, in __init__
2024-01-02 00:51:12,947 T0002: INFO      raise ValueError("Either ip or host must be set")
2024-01-02 00:51:12,947 T0002: INFO  ValueError: Either ip or host must be se
2024-01-02 00:51:12,948 T0002: INFO  StackTraceCallStack:
2024-01-02 00:51:12,948 T0002: INFO  [0] spytest/access/netmiko_connection.py:104 __init__ self.log_exception(msg, call_stack=True, dump=True)
2024-01-02 00:51:12,949 T0002: INFO  [1] spytest/access/connection.py:48 _DeviceConnection return NetmikoConnection(**kwargs)
2024-01-02 00:51:12,949 T0002: INFO  [2] spytest/access/connection.py:160 DeviceConnection hndl = _DeviceConnection(devname, ip_port, logger, **kwargs)
2024-01-02 00:51:12,950 T0002: INFO  [3] spytest/net.py:694 _do_connect_cinfo net_connect = DeviceConnection(devname=dut_name, logger=self.logger, **cinfo)
2024-01-02 00:51:12,951 T0002: INFO  [4] spytest/net.py:723 _connect_to_device net_connect = self._do_connect_cinfo(cinfo, retry, msgs, devname)
2024-01-02 00:51:12,951 T0002: INFO  [5] spytest/net.py:1118 connect_to_device_real net_connect = self._connect_to_device(connection_param, access, retry=retry)
2024-01-02 00:51:12,952 T0002: INFO  [6] spytest/net.py:1064 connect_to_device show_ver_output = self.connect_to_device_real(access, retry, recon, recover)
2024-01-02 00:51:12,952 T0002: INFO  [7] utilities/parallel.py:159 _thread_func retvals[index] = func(*args, **kwargs)
2024-01-02 00:51:12,953 T0002: INFO  [8] utilities/parallel.py:182 exec_foreach2 _thread_func(*args, **kwargs)
2024-01-02 00:51:12,953 T0002: INFO  [9] spytest/net.py:1584 connect_all_devices rvs, exps = putils.exec_foreach2(faster_init, on_except, self.topo.duts,
2024-01-02 00:51:12,954 T0002: INFO  [10] utilities/parallel.py:219 _thread_func retvals[index] = func(*args, **kwargs)
2024-01-02 00:51:12,954 T0002: INFO  --------------------------------------------
2024-01-02 00:51:12,955 T0002: INFO  ============================================
2024-01-02 00:51:12,955 T0002: WARN  Exception(None:22): Runtime Exception: Connection Unknown Error..
2024-01-02 00:51:12,955 T0002: INFO  connection-Err..
2024-01-02 00:51:20,965 T0002: INFO  Re-Trying 3..
2024-01-02 00:51:20,965 T0002: INFO  TRY Authentication: None:22 admin YourPaSsWoRd
2024-01-02 00:51:20,967 T0002: INFO  ======== Connection: Connection Unknown Error.. ======
2024-01-02 00:51:20,970 T0002: INFO  Traceback (most recent call last):
2024-01-02 00:51:20,972 T0002: INFO    File "/repo/spytest/access/netmiko_connection.py", line 82, in __init__
2024-01-02 00:51:20,974 T0002: INFO      super(NetmikoConnection, self).__init__(**kwargs)
2024-01-02 00:51:20,975 T0002: INFO    File "/usr/local/lib/python3.8/dist-packages/netmiko/base_connection.py", line 244, in __init__
2024-01-02 00:51:20,975 T0002: INFO      raise ValueError("Either ip or host must be set")
2024-01-02 00:51:20,976 T0002: INFO  ValueError: Either ip or host must be se
2024-01-02 00:51:20,976 T0002: INFO  StackTraceCallStack:
2024-01-02 00:51:20,977 T0002: INFO  [0] spytest/access/netmiko_connection.py:104 __init__ self.log_exception(msg, call_stack=True, dump=True)
2024-01-02 00:51:20,977 T0002: INFO  [1] spytest/access/connection.py:48 _DeviceConnection return NetmikoConnection(**kwargs)
2024-01-02 00:51:20,978 T0002: INFO  [2] spytest/access/connection.py:160 DeviceConnection hndl = _DeviceConnection(devname, ip_port, logger, **kwargs)
2024-01-02 00:51:20,978 T0002: INFO  [3] spytest/net.py:694 _do_connect_cinfo net_connect = DeviceConnection(devname=dut_name, logger=self.logger, **cinfo)
2024-01-02 00:51:20,979 T0002: INFO  [4] spytest/net.py:723 _connect_to_device net_connect = self._do_connect_cinfo(cinfo, retry, msgs, devname)
2024-01-02 00:51:20,979 T0002: INFO  [5] spytest/net.py:1118 connect_to_device_real net_connect = self._connect_to_device(connection_param, access, retry=retry)
2024-01-02 00:51:20,980 T0002: INFO  [6] spytest/net.py:1064 connect_to_device show_ver_output = self.connect_to_device_real(access, retry, recon, recover)
2024-01-02 00:51:20,980 T0002: INFO  [7] utilities/parallel.py:159 _thread_func retvals[index] = func(*args, **kwargs)
2024-01-02 00:51:20,981 T0002: INFO  [8] utilities/parallel.py:182 exec_foreach2 _thread_func(*args, **kwargs)
2024-01-02 00:51:20,982 T0002: INFO  [9] spytest/net.py:1584 connect_all_devices rvs, exps = putils.exec_foreach2(faster_init, on_except, self.topo.duts,
2024-01-02 00:51:20,982 T0002: INFO  [10] utilities/parallel.py:219 _thread_func retvals[index] = func(*args, **kwargs)
2024-01-02 00:51:20,983 T0002: INFO  --------------------------------------------
2024-01-02 00:51:20,983 T0002: INFO  ============================================
2024-01-02 00:51:20,983 T0002: WARN  Exception(None:22): Runtime Exception: Connection Unknown Error..
2024-01-02 00:51:20,983 T0002: INFO  TRY ALT Authentication: None:22 admin broadcom
2024-01-02 00:51:20,984 T0002: INFO  ======== Connection: Connection Unknown Error.. ======
2024-01-02 00:51:20,984 T0002: INFO  Traceback (most recent call last):
2024-01-02 00:51:20,985 T0002: INFO    File "/repo/spytest/access/netmiko_connection.py", line 82, in __init__
2024-01-02 00:51:20,986 T0002: INFO      super(NetmikoConnection, self).__init__(**kwargs)
2024-01-02 00:51:20,986 T0002: INFO    File "/usr/local/lib/python3.8/dist-packages/netmiko/base_connection.py", line 244, in __init__
2024-01-02 00:51:20,987 T0002: INFO      raise ValueError("Either ip or host must be set")
2024-01-02 00:51:20,987 T0002: INFO  ValueError: Either ip or host must be se
2024-01-02 00:51:20,988 T0002: INFO  StackTraceCallStack:
2024-01-02 00:51:20,988 T0002: INFO  [0] spytest/access/netmiko_connection.py:104 __init__ self.log_exception(msg, call_stack=True, dump=True)
2024-01-02 00:51:20,989 T0002: INFO  [1] spytest/access/connection.py:48 _DeviceConnection return NetmikoConnection(**kwargs)
2024-01-02 00:51:20,989 T0002: INFO  [2] spytest/access/connection.py:160 DeviceConnection hndl = _DeviceConnection(devname, ip_port, logger, **kwargs)
2024-01-02 00:51:20,990 T0002: INFO  [3] spytest/net.py:694 _do_connect_cinfo net_connect = DeviceConnection(devname=dut_name, logger=self.logger, **cinfo)
2024-01-02 00:51:20,990 T0002: INFO  [4] spytest/net.py:723 _connect_to_device net_connect = self._do_connect_cinfo(cinfo, retry, msgs, devname)
2024-01-02 00:51:20,991 T0002: INFO  [5] spytest/net.py:1118 connect_to_device_real net_connect = self._connect_to_device(connection_param, access, retry=retry)
2024-01-02 00:51:20,991 T0002: INFO  [6] spytest/net.py:1064 connect_to_device show_ver_output = self.connect_to_device_real(access, retry, recon, recover)
2024-01-02 00:51:20,992 T0002: INFO  [7] utilities/parallel.py:159 _thread_func retvals[index] = func(*args, **kwargs)
2024-01-02 00:51:20,992 T0002: INFO  [8] utilities/parallel.py:182 exec_foreach2 _thread_func(*args, **kwargs)
2024-01-02 00:51:20,993 T0002: INFO  [9] spytest/net.py:1584 connect_all_devices rvs, exps = putils.exec_foreach2(faster_init, on_except, self.topo.duts,
2024-01-02 00:51:20,993 T0002: INFO  [10] utilities/parallel.py:219 _thread_func retvals[index] = func(*args, **kwargs)
2024-01-02 00:51:20,994 T0002: INFO  --------------------------------------------
2024-01-02 00:51:20,994 T0002: INFO  ============================================
2024-01-02 00:51:20,994 T0002: WARN  Exception(None:22): Runtime Exception: Connection Unknown Error..
2024-01-02 00:51:20,995 T0002: INFO  connection-Err..
2024-01-02 00:51:33,008 T0002: INFO  Re-Trying 4..
2024-01-02 00:51:33,009 T0002: INFO  TRY Authentication: None:22 admin YourPaSsWoRd
2024-01-02 00:51:33,011 T0002: INFO  ======== Connection: Connection Unknown Error.. ======
2024-01-02 00:51:33,013 T0002: INFO  Traceback (most recent call last):
2024-01-02 00:51:33,015 T0002: INFO    File "/repo/spytest/access/netmiko_connection.py", line 82, in __init__
2024-01-02 00:51:33,017 T0002: INFO      super(NetmikoConnection, self).__init__(**kwargs)
2024-01-02 00:51:33,018 T0002: INFO    File "/usr/local/lib/python3.8/dist-packages/netmiko/base_connection.py", line 244, in __init__
2024-01-02 00:51:33,019 T0002: INFO      raise ValueError("Either ip or host must be set")
2024-01-02 00:51:33,020 T0002: INFO  ValueError: Either ip or host must be se
2024-01-02 00:51:33,020 T0002: INFO  StackTraceCallStack:
2024-01-02 00:51:33,021 T0002: INFO  [0] spytest/access/netmiko_connection.py:104 __init__ self.log_exception(msg, call_stack=True, dump=True)
2024-01-02 00:51:33,021 T0002: INFO  [1] spytest/access/connection.py:48 _DeviceConnection return NetmikoConnection(**kwargs)
2024-01-02 00:51:33,022 T0002: INFO  [2] spytest/access/connection.py:160 DeviceConnection hndl = _DeviceConnection(devname, ip_port, logger, **kwargs)
2024-01-02 00:51:33,022 T0002: INFO  [3] spytest/net.py:694 _do_connect_cinfo net_connect = DeviceConnection(devname=dut_name, logger=self.logger, **cinfo)
2024-01-02 00:51:33,023 T0002: INFO  [4] spytest/net.py:723 _connect_to_device net_connect = self._do_connect_cinfo(cinfo, retry, msgs, devname)
2024-01-02 00:51:33,023 T0002: INFO  [5] spytest/net.py:1118 connect_to_device_real net_connect = self._connect_to_device(connection_param, access, retry=retry)
2024-01-02 00:51:33,024 T0002: INFO  [6] spytest/net.py:1064 connect_to_device show_ver_output = self.connect_to_device_real(access, retry, recon, recover)
2024-01-02 00:51:33,024 T0002: INFO  [7] utilities/parallel.py:159 _thread_func retvals[index] = func(*args, **kwargs)
2024-01-02 00:51:33,025 T0002: INFO  [8] utilities/parallel.py:182 exec_foreach2 _thread_func(*args, **kwargs)
2024-01-02 00:51:33,025 T0002: INFO  [9] spytest/net.py:1584 connect_all_devices rvs, exps = putils.exec_foreach2(faster_init, on_except, self.topo.duts,
2024-01-02 00:51:33,026 T0002: INFO  [10] utilities/parallel.py:219 _thread_func retvals[index] = func(*args, **kwargs)
2024-01-02 00:51:33,026 T0002: INFO  --------------------------------------------
2024-01-02 00:51:33,027 T0002: INFO  ============================================
2024-01-02 00:51:33,027 T0002: WARN  Exception(None:22): Runtime Exception: Connection Unknown Error..
2024-01-02 00:51:33,027 T0002: INFO  TRY ALT Authentication: None:22 admin broadcom
2024-01-02 00:51:33,028 T0002: INFO  ======== Connection: Connection Unknown Error.. ======
2024-01-02 00:51:33,028 T0002: INFO  Traceback (most recent call last):
2024-01-02 00:51:33,029 T0002: INFO    File "/repo/spytest/access/netmiko_connection.py", line 82, in __init__
2024-01-02 00:51:33,029 T0002: INFO      super(NetmikoConnection, self).__init__(**kwargs)
2024-01-02 00:51:33,030 T0002: INFO    File "/usr/local/lib/python3.8/dist-packages/netmiko/base_connection.py", line 244, in __init__
2024-01-02 00:51:33,030 T0002: INFO      raise ValueError("Either ip or host must be set")
2024-01-02 00:51:33,031 T0002: INFO  ValueError: Either ip or host must be se
2024-01-02 00:51:33,031 T0002: INFO  StackTraceCallStack:
2024-01-02 00:51:33,032 T0002: INFO  [0] spytest/access/netmiko_connection.py:104 __init__ self.log_exception(msg, call_stack=True, dump=True)
2024-01-02 00:51:33,032 T0002: INFO  [1] spytest/access/connection.py:48 _DeviceConnection return NetmikoConnection(**kwargs)
2024-01-02 00:51:33,033 T0002: INFO  [2] spytest/access/connection.py:160 DeviceConnection hndl = _DeviceConnection(devname, ip_port, logger, **kwargs)
2024-01-02 00:51:33,033 T0002: INFO  [3] spytest/net.py:694 _do_connect_cinfo net_connect = DeviceConnection(devname=dut_name, logger=self.logger, **cinfo)
2024-01-02 00:51:33,034 T0002: INFO  [4] spytest/net.py:723 _connect_to_device net_connect = self._do_connect_cinfo(cinfo, retry, msgs, devname)
2024-01-02 00:51:33,034 T0002: INFO  [5] spytest/net.py:1118 connect_to_device_real net_connect = self._connect_to_device(connection_param, access, retry=retry)
2024-01-02 00:51:33,035 T0002: INFO  [6] spytest/net.py:1064 connect_to_device show_ver_output = self.connect_to_device_real(access, retry, recon, recover)
2024-01-02 00:51:33,035 T0002: INFO  [7] utilities/parallel.py:159 _thread_func retvals[index] = func(*args, **kwargs)
2024-01-02 00:51:33,036 T0002: INFO  [8] utilities/parallel.py:182 exec_foreach2 _thread_func(*args, **kwargs)
2024-01-02 00:51:33,037 T0002: INFO  [9] spytest/net.py:1584 connect_all_devices rvs, exps = putils.exec_foreach2(faster_init, on_except, self.topo.duts,
2024-01-02 00:51:33,037 T0002: INFO  [10] utilities/parallel.py:219 _thread_func retvals[index] = func(*args, **kwargs)
2024-01-02 00:51:33,037 T0002: INFO  --------------------------------------------
2024-01-02 00:51:33,038 T0002: INFO  ============================================
2024-01-02 00:51:33,038 T0002: WARN  Exception(None:22): Runtime Exception: Connection Unknown Error..
2024-01-02 00:51:33,038 T0002: INFO  connection-Err..
2024-01-02 00:51:49,056 T0002: INFO  Re-Trying 5..
2024-01-02 00:51:49,057 T0002: INFO  TRY Authentication: None:22 admin YourPaSsWoRd
2024-01-02 00:51:49,059 T0002: INFO  ======== Connection: Connection Unknown Error.. ======
2024-01-02 00:51:49,061 T0002: INFO  Traceback (most recent call last):
2024-01-02 00:51:49,063 T0002: INFO    File "/repo/spytest/access/netmiko_connection.py", line 82, in __init__
2024-01-02 00:51:49,065 T0002: INFO      super(NetmikoConnection, self).__init__(**kwargs)
2024-01-02 00:51:49,067 T0002: INFO    File "/usr/local/lib/python3.8/dist-packages/netmiko/base_connection.py", line 244, in __init__
2024-01-02 00:51:49,067 T0002: INFO      raise ValueError("Either ip or host must be set")
2024-01-02 00:51:49,068 T0002: INFO  ValueError: Either ip or host must be se
2024-01-02 00:51:49,068 T0002: INFO  StackTraceCallStack:
2024-01-02 00:51:49,069 T0002: INFO  [0] spytest/access/netmiko_connection.py:104 __init__ self.log_exception(msg, call_stack=True, dump=True)
2024-01-02 00:51:49,069 T0002: INFO  [1] spytest/access/connection.py:48 _DeviceConnection return NetmikoConnection(**kwargs)
2024-01-02 00:51:49,070 T0002: INFO  [2] spytest/access/connection.py:160 DeviceConnection hndl = _DeviceConnection(devname, ip_port, logger, **kwargs)
2024-01-02 00:51:49,070 T0002: INFO  [3] spytest/net.py:694 _do_connect_cinfo net_connect = DeviceConnection(devname=dut_name, logger=self.logger, **cinfo)
2024-01-02 00:51:49,071 T0002: INFO  [4] spytest/net.py:723 _connect_to_device net_connect = self._do_connect_cinfo(cinfo, retry, msgs, devname)
2024-01-02 00:51:49,071 T0002: INFO  [5] spytest/net.py:1118 connect_to_device_real net_connect = self._connect_to_device(connection_param, access, retry=retry)
2024-01-02 00:51:49,072 T0002: INFO  [6] spytest/net.py:1064 connect_to_device show_ver_output = self.connect_to_device_real(access, retry, recon, recover)
2024-01-02 00:51:49,072 T0002: INFO  [7] utilities/parallel.py:159 _thread_func retvals[index] = func(*args, **kwargs)
2024-01-02 00:51:49,073 T0002: INFO  [8] utilities/parallel.py:182 exec_foreach2 _thread_func(*args, **kwargs)
2024-01-02 00:51:49,073 T0002: INFO  [9] spytest/net.py:1584 connect_all_devices rvs, exps = putils.exec_foreach2(faster_init, on_except, self.topo.duts,
2024-01-02 00:51:49,074 T0002: INFO  [10] utilities/parallel.py:219 _thread_func retvals[index] = func(*args, **kwargs)
2024-01-02 00:51:49,074 T0002: INFO  --------------------------------------------
2024-01-02 00:51:49,075 T0002: INFO  ============================================
2024-01-02 00:51:49,075 T0002: WARN  Exception(None:22): Runtime Exception: Connection Unknown Error..
2024-01-02 00:51:49,075 T0002: INFO  TRY ALT Authentication: None:22 admin broadcom
2024-01-02 00:51:49,076 T0002: INFO  ======== Connection: Connection Unknown Error.. ======
2024-01-02 00:51:49,076 T0002: INFO  Traceback (most recent call last):
2024-01-02 00:51:49,077 T0002: INFO    File "/repo/spytest/access/netmiko_connection.py", line 82, in __init__
2024-01-02 00:51:49,077 T0002: INFO      super(NetmikoConnection, self).__init__(**kwargs)
2024-01-02 00:51:49,078 T0002: INFO    File "/usr/local/lib/python3.8/dist-packages/netmiko/base_connection.py", line 244, in __init__
2024-01-02 00:51:49,078 T0002: INFO      raise ValueError("Either ip or host must be set")
2024-01-02 00:51:49,079 T0002: INFO  ValueError: Either ip or host must be se
2024-01-02 00:51:49,080 T0002: INFO  StackTraceCallStack:
2024-01-02 00:51:49,080 T0002: INFO  [0] spytest/access/netmiko_connection.py:104 __init__ self.log_exception(msg, call_stack=True, dump=True)
2024-01-02 00:51:49,081 T0002: INFO  [1] spytest/access/connection.py:48 _DeviceConnection return NetmikoConnection(**kwargs)
2024-01-02 00:51:49,081 T0002: INFO  [2] spytest/access/connection.py:160 DeviceConnection hndl = _DeviceConnection(devname, ip_port, logger, **kwargs)
2024-01-02 00:51:49,082 T0002: INFO  [3] spytest/net.py:694 _do_connect_cinfo net_connect = DeviceConnection(devname=dut_name, logger=self.logger, **cinfo)
2024-01-02 00:51:49,082 T0002: INFO  [4] spytest/net.py:723 _connect_to_device net_connect = self._do_connect_cinfo(cinfo, retry, msgs, devname)
2024-01-02 00:51:49,083 T0002: INFO  [5] spytest/net.py:1118 connect_to_device_real net_connect = self._connect_to_device(connection_param, access, retry=retry)
2024-01-02 00:51:49,083 T0002: INFO  [6] spytest/net.py:1064 connect_to_device show_ver_output = self.connect_to_device_real(access, retry, recon, recover)
2024-01-02 00:51:49,084 T0002: INFO  [7] utilities/parallel.py:159 _thread_func retvals[index] = func(*args, **kwargs)
2024-01-02 00:51:49,084 T0002: INFO  [8] utilities/parallel.py:182 exec_foreach2 _thread_func(*args, **kwargs)
2024-01-02 00:51:49,085 T0002: INFO  [9] spytest/net.py:1584 connect_all_devices rvs, exps = putils.exec_foreach2(faster_init, on_except, self.topo.duts,
2024-01-02 00:51:49,085 T0002: INFO  [10] utilities/parallel.py:219 _thread_func retvals[index] = func(*args, **kwargs)
2024-01-02 00:51:49,086 T0002: INFO  --------------------------------------------
2024-01-02 00:51:49,086 T0002: INFO  ============================================
2024-01-02 00:51:49,086 T0002: WARN  Exception(None:22): Runtime Exception: Connection Unknown Error..
2024-01-02 00:51:49,087 T0002: INFO  connection-Err..
2024-01-02 00:52:09,108 T0002: INFO  Re-Trying 6..
2024-01-02 00:52:09,109 T0002: INFO  TRY Authentication: None:22 admin YourPaSsWoRd
2024-01-02 00:52:09,111 T0002: INFO  ======== Connection: Connection Unknown Error.. ======
2024-01-02 00:52:09,113 T0002: INFO  Traceback (most recent call last):
2024-01-02 00:52:09,115 T0002: INFO    File "/repo/spytest/access/netmiko_connection.py", line 82, in __init__
2024-01-02 00:52:09,117 T0002: INFO      super(NetmikoConnection, self).__init__(**kwargs)
2024-01-02 00:52:09,119 T0002: INFO    File "/usr/local/lib/python3.8/dist-packages/netmiko/base_connection.py", line 244, in __init__
2024-01-02 00:52:09,119 T0002: INFO      raise ValueError("Either ip or host must be set")
2024-01-02 00:52:09,120 T0002: INFO  ValueError: Either ip or host must be se
2024-01-02 00:52:09,120 T0002: INFO  StackTraceCallStack:
2024-01-02 00:52:09,121 T0002: INFO  [0] spytest/access/netmiko_connection.py:104 __init__ self.log_exception(msg, call_stack=True, dump=True)
2024-01-02 00:52:09,121 T0002: INFO  [1] spytest/access/connection.py:48 _DeviceConnection return NetmikoConnection(**kwargs)
2024-01-02 00:52:09,122 T0002: INFO  [2] spytest/access/connection.py:160 DeviceConnection hndl = _DeviceConnection(devname, ip_port, logger, **kwargs)
2024-01-02 00:52:09,122 T0002: INFO  [3] spytest/net.py:694 _do_connect_cinfo net_connect = DeviceConnection(devname=dut_name, logger=self.logger, **cinfo)
2024-01-02 00:52:09,123 T0002: INFO  [4] spytest/net.py:723 _connect_to_device net_connect = self._do_connect_cinfo(cinfo, retry, msgs, devname)
2024-01-02 00:52:09,123 T0002: INFO  [5] spytest/net.py:1118 connect_to_device_real net_connect = self._connect_to_device(connection_param, access, retry=retry)
2024-01-02 00:52:09,124 T0002: INFO  [6] spytest/net.py:1064 connect_to_device show_ver_output = self.connect_to_device_real(access, retry, recon, recover)
2024-01-02 00:52:09,124 T0002: INFO  [7] utilities/parallel.py:159 _thread_func retvals[index] = func(*args, **kwargs)
2024-01-02 00:52:09,125 T0002: INFO  [8] utilities/parallel.py:182 exec_foreach2 _thread_func(*args, **kwargs)
2024-01-02 00:52:09,125 T0002: INFO  [9] spytest/net.py:1584 connect_all_devices rvs, exps = putils.exec_foreach2(faster_init, on_except, self.topo.duts,
2024-01-02 00:52:09,126 T0002: INFO  [10] utilities/parallel.py:219 _thread_func retvals[index] = func(*args, **kwargs)
2024-01-02 00:52:09,126 T0002: INFO  --------------------------------------------
2024-01-02 00:52:09,127 T0002: INFO  ============================================
2024-01-02 00:52:09,127 T0002: WARN  Exception(None:22): Runtime Exception: Connection Unknown Error..
2024-01-02 00:52:09,127 T0002: INFO  TRY ALT Authentication: None:22 admin broadcom
2024-01-02 00:52:09,128 T0002: INFO  ======== Connection: Connection Unknown Error.. ======
2024-01-02 00:52:09,128 T0002: INFO  Traceback (most recent call last):
2024-01-02 00:52:09,129 T0002: INFO    File "/repo/spytest/access/netmiko_connection.py", line 82, in __init__
2024-01-02 00:52:09,129 T0002: INFO      super(NetmikoConnection, self).__init__(**kwargs)
2024-01-02 00:52:09,130 T0002: INFO    File "/usr/local/lib/python3.8/dist-packages/netmiko/base_connection.py", line 244, in __init__
2024-01-02 00:52:09,130 T0002: INFO      raise ValueError("Either ip or host must be set")
2024-01-02 00:52:09,131 T0002: INFO  ValueError: Either ip or host must be se
2024-01-02 00:52:09,131 T0002: INFO  StackTraceCallStack:
2024-01-02 00:52:09,132 T0002: INFO  [0] spytest/access/netmiko_connection.py:104 __init__ self.log_exception(msg, call_stack=True, dump=True)
2024-01-02 00:52:09,132 T0002: INFO  [1] spytest/access/connection.py:48 _DeviceConnection return NetmikoConnection(**kwargs)
2024-01-02 00:52:09,133 T0002: INFO  [2] spytest/access/connection.py:160 DeviceConnection hndl = _DeviceConnection(devname, ip_port, logger, **kwargs)
2024-01-02 00:52:09,133 T0002: INFO  [3] spytest/net.py:694 _do_connect_cinfo net_connect = DeviceConnection(devname=dut_name, logger=self.logger, **cinfo)
2024-01-02 00:52:09,134 T0002: INFO  [4] spytest/net.py:723 _connect_to_device net_connect = self._do_connect_cinfo(cinfo, retry, msgs, devname)
2024-01-02 00:52:09,135 T0002: INFO  [5] spytest/net.py:1118 connect_to_device_real net_connect = self._connect_to_device(connection_param, access, retry=retry)
2024-01-02 00:52:09,135 T0002: INFO  [6] spytest/net.py:1064 connect_to_device show_ver_output = self.connect_to_device_real(access, retry, recon, recover)
2024-01-02 00:52:09,136 T0002: INFO  [7] utilities/parallel.py:159 _thread_func retvals[index] = func(*args, **kwargs)
2024-01-02 00:52:09,136 T0002: INFO  [8] utilities/parallel.py:182 exec_foreach2 _thread_func(*args, **kwargs)
2024-01-02 00:52:09,137 T0002: INFO  [9] spytest/net.py:1584 connect_all_devices rvs, exps = putils.exec_foreach2(faster_init, on_except, self.topo.duts,
2024-01-02 00:52:09,137 T0002: INFO  [10] utilities/parallel.py:219 _thread_func retvals[index] = func(*args, **kwargs)
2024-01-02 00:52:09,138 T0002: INFO  --------------------------------------------
2024-01-02 00:52:09,138 T0002: INFO  ============================================
2024-01-02 00:52:09,138 T0002: WARN  Exception(None:22): Runtime Exception: Connection Unknown Error..
2024-01-02 00:52:09,139 T0002: INFO  connection-Err..
2024-01-02 00:52:33,164 T0002: INFO  Re-Trying 7..
2024-01-02 00:52:33,165 T0002: INFO  TRY Authentication: None:22 admin YourPaSsWoRd
2024-01-02 00:52:33,167 T0002: INFO  ======== Connection: Connection Unknown Error.. ======
2024-01-02 00:52:33,169 T0002: INFO  Traceback (most recent call last):
2024-01-02 00:52:33,171 T0002: INFO    File "/repo/spytest/access/netmiko_connection.py", line 82, in __init__
2024-01-02 00:52:33,173 T0002: INFO      super(NetmikoConnection, self).__init__(**kwargs)
2024-01-02 00:52:33,174 T0002: INFO    File "/usr/local/lib/python3.8/dist-packages/netmiko/base_connection.py", line 244, in __init__
2024-01-02 00:52:33,175 T0002: INFO      raise ValueError("Either ip or host must be set")
2024-01-02 00:52:33,175 T0002: INFO  ValueError: Either ip or host must be se
2024-01-02 00:52:33,176 T0002: INFO  StackTraceCallStack:
2024-01-02 00:52:33,176 T0002: INFO  [0] spytest/access/netmiko_connection.py:104 __init__ self.log_exception(msg, call_stack=True, dump=True)
2024-01-02 00:52:33,177 T0002: INFO  [1] spytest/access/connection.py:48 _DeviceConnection return NetmikoConnection(**kwargs)
2024-01-02 00:52:33,178 T0002: INFO  [2] spytest/access/connection.py:160 DeviceConnection hndl = _DeviceConnection(devname, ip_port, logger, **kwargs)
2024-01-02 00:52:33,178 T0002: INFO  [3] spytest/net.py:694 _do_connect_cinfo net_connect = DeviceConnection(devname=dut_name, logger=self.logger, **cinfo)
2024-01-02 00:52:33,179 T0002: INFO  [4] spytest/net.py:723 _connect_to_device net_connect = self._do_connect_cinfo(cinfo, retry, msgs, devname)
2024-01-02 00:52:33,179 T0002: INFO  [5] spytest/net.py:1118 connect_to_device_real net_connect = self._connect_to_device(connection_param, access, retry=retry)
2024-01-02 00:52:33,180 T0002: INFO  [6] spytest/net.py:1064 connect_to_device show_ver_output = self.connect_to_device_real(access, retry, recon, recover)
2024-01-02 00:52:33,180 T0002: INFO  [7] utilities/parallel.py:159 _thread_func retvals[index] = func(*args, **kwargs)
2024-01-02 00:52:33,181 T0002: INFO  [8] utilities/parallel.py:182 exec_foreach2 _thread_func(*args, **kwargs)
2024-01-02 00:52:33,181 T0002: INFO  [9] spytest/net.py:1584 connect_all_devices rvs, exps = putils.exec_foreach2(faster_init, on_except, self.topo.duts,
2024-01-02 00:52:33,182 T0002: INFO  [10] utilities/parallel.py:219 _thread_func retvals[index] = func(*args, **kwargs)
2024-01-02 00:52:33,182 T0002: INFO  --------------------------------------------
2024-01-02 00:52:33,183 T0002: INFO  ============================================
2024-01-02 00:52:33,183 T0002: WARN  Exception(None:22): Runtime Exception: Connection Unknown Error..
2024-01-02 00:52:33,183 T0002: INFO  TRY ALT Authentication: None:22 admin broadcom
2024-01-02 00:52:33,183 T0002: INFO  ======== Connection: Connection Unknown Error.. ======
2024-01-02 00:52:33,184 T0002: INFO  Traceback (most recent call last):
2024-01-02 00:52:33,185 T0002: INFO    File "/repo/spytest/access/netmiko_connection.py", line 82, in __init__
2024-01-02 00:52:33,185 T0002: INFO      super(NetmikoConnection, self).__init__(**kwargs)
2024-01-02 00:52:33,186 T0002: INFO    File "/usr/local/lib/python3.8/dist-packages/netmiko/base_connection.py", line 244, in __init__
2024-01-02 00:52:33,186 T0002: INFO      raise ValueError("Either ip or host must be set")
2024-01-02 00:52:33,187 T0002: INFO  ValueError: Either ip or host must be se
2024-01-02 00:52:33,187 T0002: INFO  StackTraceCallStack:
2024-01-02 00:52:33,188 T0002: INFO  [0] spytest/access/netmiko_connection.py:104 __init__ self.log_exception(msg, call_stack=True, dump=True)
2024-01-02 00:52:33,188 T0002: INFO  [1] spytest/access/connection.py:48 _DeviceConnection return NetmikoConnection(**kwargs)
2024-01-02 00:52:33,189 T0002: INFO  [2] spytest/access/connection.py:160 DeviceConnection hndl = _DeviceConnection(devname, ip_port, logger, **kwargs)
2024-01-02 00:52:33,189 T0002: INFO  [3] spytest/net.py:694 _do_connect_cinfo net_connect = DeviceConnection(devname=dut_name, logger=self.logger, **cinfo)
2024-01-02 00:52:33,190 T0002: INFO  [4] spytest/net.py:723 _connect_to_device net_connect = self._do_connect_cinfo(cinfo, retry, msgs, devname)
2024-01-02 00:52:33,191 T0002: INFO  [5] spytest/net.py:1118 connect_to_device_real net_connect = self._connect_to_device(connection_param, access, retry=retry)
2024-01-02 00:52:33,191 T0002: INFO  [6] spytest/net.py:1064 connect_to_device show_ver_output = self.connect_to_device_real(access, retry, recon, recover)
2024-01-02 00:52:33,192 T0002: INFO  [7] utilities/parallel.py:159 _thread_func retvals[index] = func(*args, **kwargs)
2024-01-02 00:52:33,192 T0002: INFO  [8] utilities/parallel.py:182 exec_foreach2 _thread_func(*args, **kwargs)
2024-01-02 00:52:33,193 T0002: INFO  [9] spytest/net.py:1584 connect_all_devices rvs, exps = putils.exec_foreach2(faster_init, on_except, self.topo.duts,
2024-01-02 00:52:33,193 T0002: INFO  [10] utilities/parallel.py:219 _thread_func retvals[index] = func(*args, **kwargs)
2024-01-02 00:52:33,194 T0002: INFO  --------------------------------------------
2024-01-02 00:52:33,194 T0002: INFO  ============================================
2024-01-02 00:52:33,195 T0002: WARN  Exception(None:22): Runtime Exception: Connection Unknown Error..
2024-01-02 00:52:33,195 T0002: INFO  connection-Err..
2024-01-02 00:53:01,225 T0002: INFO  Re-Trying 8..
2024-01-02 00:53:01,225 T0002: INFO  TRY Authentication: None:22 admin YourPaSsWoRd
2024-01-02 00:53:01,227 T0002: INFO  ======== Connection: Connection Unknown Error.. ======
2024-01-02 00:53:01,230 T0002: INFO  Traceback (most recent call last):
2024-01-02 00:53:01,232 T0002: INFO    File "/repo/spytest/access/netmiko_connection.py", line 82, in __init__
2024-01-02 00:53:01,233 T0002: INFO      super(NetmikoConnection, self).__init__(**kwargs)
2024-01-02 00:53:01,234 T0002: INFO    File "/usr/local/lib/python3.8/dist-packages/netmiko/base_connection.py", line 244, in __init__
2024-01-02 00:53:01,235 T0002: INFO      raise ValueError("Either ip or host must be set")
2024-01-02 00:53:01,236 T0002: INFO  ValueError: Either ip or host must be se
2024-01-02 00:53:01,237 T0002: INFO  StackTraceCallStack:
2024-01-02 00:53:01,238 T0002: INFO  [0] spytest/access/netmiko_connection.py:104 __init__ self.log_exception(msg, call_stack=True, dump=True)
2024-01-02 00:53:01,238 T0002: INFO  [1] spytest/access/connection.py:48 _DeviceConnection return NetmikoConnection(**kwargs)
2024-01-02 00:53:01,239 T0002: INFO  [2] spytest/access/connection.py:160 DeviceConnection hndl = _DeviceConnection(devname, ip_port, logger, **kwargs)
2024-01-02 00:53:01,239 T0002: INFO  [3] spytest/net.py:694 _do_connect_cinfo net_connect = DeviceConnection(devname=dut_name, logger=self.logger, **cinfo)
2024-01-02 00:53:01,240 T0002: INFO  [4] spytest/net.py:723 _connect_to_device net_connect = self._do_connect_cinfo(cinfo, retry, msgs, devname)
2024-01-02 00:53:01,240 T0002: INFO  [5] spytest/net.py:1118 connect_to_device_real net_connect = self._connect_to_device(connection_param, access, retry=retry)
2024-01-02 00:53:01,241 T0002: INFO  [6] spytest/net.py:1064 connect_to_device show_ver_output = self.connect_to_device_real(access, retry, recon, recover)
2024-01-02 00:53:01,241 T0002: INFO  [7] utilities/parallel.py:159 _thread_func retvals[index] = func(*args, **kwargs)
2024-01-02 00:53:01,242 T0002: INFO  [8] utilities/parallel.py:182 exec_foreach2 _thread_func(*args, **kwargs)
2024-01-02 00:53:01,243 T0002: INFO  [9] spytest/net.py:1584 connect_all_devices rvs, exps = putils.exec_foreach2(faster_init, on_except, self.topo.duts,
2024-01-02 00:53:01,243 T0002: INFO  [10] utilities/parallel.py:219 _thread_func retvals[index] = func(*args, **kwargs)
2024-01-02 00:53:01,244 T0002: INFO  --------------------------------------------
2024-01-02 00:53:01,244 T0002: INFO  ============================================
2024-01-02 00:53:01,244 T0002: WARN  Exception(None:22): Runtime Exception: Connection Unknown Error..
2024-01-02 00:53:01,244 T0002: INFO  TRY ALT Authentication: None:22 admin broadcom
2024-01-02 00:53:01,245 T0002: INFO  ======== Connection: Connection Unknown Error.. ======
2024-01-02 00:53:01,246 T0002: INFO  Traceback (most recent call last):
2024-01-02 00:53:01,246 T0002: INFO    File "/repo/spytest/access/netmiko_connection.py", line 82, in __init__
2024-01-02 00:53:01,247 T0002: INFO      super(NetmikoConnection, self).__init__(**kwargs)
2024-01-02 00:53:01,247 T0002: INFO    File "/usr/local/lib/python3.8/dist-packages/netmiko/base_connection.py", line 244, in __init__
2024-01-02 00:53:01,248 T0002: INFO      raise ValueError("Either ip or host must be set")
2024-01-02 00:53:01,248 T0002: INFO  ValueError: Either ip or host must be se
2024-01-02 00:53:01,249 T0002: INFO  StackTraceCallStack:
2024-01-02 00:53:01,249 T0002: INFO  [0] spytest/access/netmiko_connection.py:104 __init__ self.log_exception(msg, call_stack=True, dump=True)
2024-01-02 00:53:01,250 T0002: INFO  [1] spytest/access/connection.py:48 _DeviceConnection return NetmikoConnection(**kwargs)
2024-01-02 00:53:01,250 T0002: INFO  [2] spytest/access/connection.py:160 DeviceConnection hndl = _DeviceConnection(devname, ip_port, logger, **kwargs)
2024-01-02 00:53:01,251 T0002: INFO  [3] spytest/net.py:694 _do_connect_cinfo net_connect = DeviceConnection(devname=dut_name, logger=self.logger, **cinfo)
2024-01-02 00:53:01,251 T0002: INFO  [4] spytest/net.py:723 _connect_to_device net_connect = self._do_connect_cinfo(cinfo, retry, msgs, devname)
2024-01-02 00:53:01,252 T0002: INFO  [5] spytest/net.py:1118 connect_to_device_real net_connect = self._connect_to_device(connection_param, access, retry=retry)
2024-01-02 00:53:01,252 T0002: INFO  [6] spytest/net.py:1064 connect_to_device show_ver_output = self.connect_to_device_real(access, retry, recon, recover)
2024-01-02 00:53:01,253 T0002: INFO  [7] utilities/parallel.py:159 _thread_func retvals[index] = func(*args, **kwargs)
2024-01-02 00:53:01,253 T0002: INFO  [8] utilities/parallel.py:182 exec_foreach2 _thread_func(*args, **kwargs)
2024-01-02 00:53:01,254 T0002: INFO  [9] spytest/net.py:1584 connect_all_devices rvs, exps = putils.exec_foreach2(faster_init, on_except, self.topo.duts,
2024-01-02 00:53:01,254 T0002: INFO  [10] utilities/parallel.py:219 _thread_func retvals[index] = func(*args, **kwargs)
2024-01-02 00:53:01,255 T0002: INFO  --------------------------------------------
2024-01-02 00:53:01,255 T0002: INFO  ============================================
2024-01-02 00:53:01,256 T0002: WARN  Exception(None:22): Runtime Exception: Connection Unknown Error..
2024-01-02 00:53:01,256 T0002: INFO  connection-Err..
2024-01-02 00:53:33,290 T0002: INFO  Re-Trying 9..
2024-01-02 00:53:33,290 T0002: INFO  TRY Authentication: None:22 admin YourPaSsWoRd
2024-01-02 00:53:33,292 T0002: INFO  ======== Connection: Connection Unknown Error.. ======
2024-01-02 00:53:33,295 T0002: INFO  Traceback (most recent call last):
2024-01-02 00:53:33,296 T0002: INFO    File "/repo/spytest/access/netmiko_connection.py", line 82, in __init__
2024-01-02 00:53:33,298 T0002: INFO      super(NetmikoConnection, self).__init__(**kwargs)
2024-01-02 00:53:33,300 T0002: INFO    File "/usr/local/lib/python3.8/dist-packages/netmiko/base_connection.py", line 244, in __init__
2024-01-02 00:53:33,302 T0002: INFO      raise ValueError("Either ip or host must be set")
2024-01-02 00:53:33,303 T0002: INFO  ValueError: Either ip or host must be se
2024-01-02 00:53:33,303 T0002: INFO  StackTraceCallStack:
2024-01-02 00:53:33,304 T0002: INFO  [0] spytest/access/netmiko_connection.py:104 __init__ self.log_exception(msg, call_stack=True, dump=True)
2024-01-02 00:53:33,304 T0002: INFO  [1] spytest/access/connection.py:48 _DeviceConnection return NetmikoConnection(**kwargs)
2024-01-02 00:53:33,305 T0002: INFO  [2] spytest/access/connection.py:160 DeviceConnection hndl = _DeviceConnection(devname, ip_port, logger, **kwargs)
2024-01-02 00:53:33,305 T0002: INFO  [3] spytest/net.py:694 _do_connect_cinfo net_connect = DeviceConnection(devname=dut_name, logger=self.logger, **cinfo)
2024-01-02 00:53:33,306 T0002: INFO  [4] spytest/net.py:723 _connect_to_device net_connect = self._do_connect_cinfo(cinfo, retry, msgs, devname)
2024-01-02 00:53:33,307 T0002: INFO  [5] spytest/net.py:1118 connect_to_device_real net_connect = self._connect_to_device(connection_param, access, retry=retry)
2024-01-02 00:53:33,307 T0002: INFO  [6] spytest/net.py:1064 connect_to_device show_ver_output = self.connect_to_device_real(access, retry, recon, recover)
2024-01-02 00:53:33,308 T0002: INFO  [7] utilities/parallel.py:159 _thread_func retvals[index] = func(*args, **kwargs)
2024-01-02 00:53:33,308 T0002: INFO  [8] utilities/parallel.py:182 exec_foreach2 _thread_func(*args, **kwargs)
2024-01-02 00:53:33,309 T0002: INFO  [9] spytest/net.py:1584 connect_all_devices rvs, exps = putils.exec_foreach2(faster_init, on_except, self.topo.duts,
2024-01-02 00:53:33,309 T0002: INFO  [10] utilities/parallel.py:219 _thread_func retvals[index] = func(*args, **kwargs)
2024-01-02 00:53:33,310 T0002: INFO  --------------------------------------------
2024-01-02 00:53:33,310 T0002: INFO  ============================================
2024-01-02 00:53:33,310 T0002: WARN  Exception(None:22): Runtime Exception: Connection Unknown Error..
2024-01-02 00:53:33,310 T0002: INFO  TRY ALT Authentication: None:22 admin broadcom
2024-01-02 00:53:33,311 T0002: INFO  ======== Connection: Connection Unknown Error.. ======
2024-01-02 00:53:33,312 T0002: INFO  Traceback (most recent call last):
2024-01-02 00:53:33,312 T0002: INFO    File "/repo/spytest/access/netmiko_connection.py", line 82, in __init__
2024-01-02 00:53:33,313 T0002: INFO      super(NetmikoConnection, self).__init__(**kwargs)
2024-01-02 00:53:33,313 T0002: INFO    File "/usr/local/lib/python3.8/dist-packages/netmiko/base_connection.py", line 244, in __init__
2024-01-02 00:53:33,314 T0002: INFO      raise ValueError("Either ip or host must be set")
2024-01-02 00:53:33,314 T0002: INFO  ValueError: Either ip or host must be se
2024-01-02 00:53:33,315 T0002: INFO  StackTraceCallStack:
2024-01-02 00:53:33,315 T0002: INFO  [0] spytest/access/netmiko_connection.py:104 __init__ self.log_exception(msg, call_stack=True, dump=True)
2024-01-02 00:53:33,316 T0002: INFO  [1] spytest/access/connection.py:48 _DeviceConnection return NetmikoConnection(**kwargs)
2024-01-02 00:53:33,316 T0002: INFO  [2] spytest/access/connection.py:160 DeviceConnection hndl = _DeviceConnection(devname, ip_port, logger, **kwargs)
2024-01-02 00:53:33,317 T0002: INFO  [3] spytest/net.py:694 _do_connect_cinfo net_connect = DeviceConnection(devname=dut_name, logger=self.logger, **cinfo)
2024-01-02 00:53:33,317 T0002: INFO  [4] spytest/net.py:723 _connect_to_device net_connect = self._do_connect_cinfo(cinfo, retry, msgs, devname)
2024-01-02 00:53:33,318 T0002: INFO  [5] spytest/net.py:1118 connect_to_device_real net_connect = self._connect_to_device(connection_param, access, retry=retry)
2024-01-02 00:53:33,318 T0002: INFO  [6] spytest/net.py:1064 connect_to_device show_ver_output = self.connect_to_device_real(access, retry, recon, recover)
2024-01-02 00:53:33,319 T0002: INFO  [7] utilities/parallel.py:159 _thread_func retvals[index] = func(*args, **kwargs)
2024-01-02 00:53:33,319 T0002: INFO  [8] utilities/parallel.py:182 exec_foreach2 _thread_func(*args, **kwargs)
2024-01-02 00:53:33,320 T0002: INFO  [9] spytest/net.py:1584 connect_all_devices rvs, exps = putils.exec_foreach2(faster_init, on_except, self.topo.duts,
2024-01-02 00:53:33,320 T0002: INFO  [10] utilities/parallel.py:219 _thread_func retvals[index] = func(*args, **kwargs)
2024-01-02 00:53:33,321 T0002: INFO  --------------------------------------------
2024-01-02 00:53:33,321 T0002: INFO  ============================================
2024-01-02 00:53:33,322 T0002: WARN  Exception(None:22): Runtime Exception: Connection Unknown Error..
2024-01-02 00:53:33,322 T0002: INFO  connection-Err..
2024-01-02 00:54:09,359 T0002: INFO  Re-Trying 10..
2024-01-02 00:54:09,360 T0002: INFO  TRY Authentication: None:22 admin YourPaSsWoRd
2024-01-02 00:54:09,362 T0002: INFO  ======== Connection: Connection Unknown Error.. ======
2024-01-02 00:54:09,364 T0002: INFO  Traceback (most recent call last):
2024-01-02 00:54:09,366 T0002: INFO    File "/repo/spytest/access/netmiko_connection.py", line 82, in __init__
2024-01-02 00:54:09,368 T0002: INFO      super(NetmikoConnection, self).__init__(**kwargs)
2024-01-02 00:54:09,370 T0002: INFO    File "/usr/local/lib/python3.8/dist-packages/netmiko/base_connection.py", line 244, in __init__
2024-01-02 00:54:09,371 T0002: INFO      raise ValueError("Either ip or host must be set")
2024-01-02 00:54:09,371 T0002: INFO  ValueError: Either ip or host must be se
2024-01-02 00:54:09,372 T0002: INFO  StackTraceCallStack:
2024-01-02 00:54:09,372 T0002: INFO  [0] spytest/access/netmiko_connection.py:104 __init__ self.log_exception(msg, call_stack=True, dump=True)
2024-01-02 00:54:09,373 T0002: INFO  [1] spytest/access/connection.py:48 _DeviceConnection return NetmikoConnection(**kwargs)
2024-01-02 00:54:09,373 T0002: INFO  [2] spytest/access/connection.py:160 DeviceConnection hndl = _DeviceConnection(devname, ip_port, logger, **kwargs)
2024-01-02 00:54:09,374 T0002: INFO  [3] spytest/net.py:694 _do_connect_cinfo net_connect = DeviceConnection(devname=dut_name, logger=self.logger, **cinfo)
2024-01-02 00:54:09,375 T0002: INFO  [4] spytest/net.py:723 _connect_to_device net_connect = self._do_connect_cinfo(cinfo, retry, msgs, devname)
2024-01-02 00:54:09,375 T0002: INFO  [5] spytest/net.py:1118 connect_to_device_real net_connect = self._connect_to_device(connection_param, access, retry=retry)
2024-01-02 00:54:09,376 T0002: INFO  [6] spytest/net.py:1064 connect_to_device show_ver_output = self.connect_to_device_real(access, retry, recon, recover)
2024-01-02 00:54:09,376 T0002: INFO  [7] utilities/parallel.py:159 _thread_func retvals[index] = func(*args, **kwargs)
2024-01-02 00:54:09,377 T0002: INFO  [8] utilities/parallel.py:182 exec_foreach2 _thread_func(*args, **kwargs)
2024-01-02 00:54:09,377 T0002: INFO  [9] spytest/net.py:1584 connect_all_devices rvs, exps = putils.exec_foreach2(faster_init, on_except, self.topo.duts,
2024-01-02 00:54:09,378 T0002: INFO  [10] utilities/parallel.py:219 _thread_func retvals[index] = func(*args, **kwargs)
2024-01-02 00:54:09,378 T0002: INFO  --------------------------------------------
2024-01-02 00:54:09,379 T0002: INFO  ============================================
2024-01-02 00:54:09,379 T0002: WARN  Exception(None:22): Runtime Exception: Connection Unknown Error..
2024-01-02 00:54:09,379 T0002: INFO  TRY ALT Authentication: None:22 admin broadcom
2024-01-02 00:54:09,379 T0002: INFO  ======== Connection: Connection Unknown Error.. ======
2024-01-02 00:54:09,380 T0002: INFO  Traceback (most recent call last):
2024-01-02 00:54:09,381 T0002: INFO    File "/repo/spytest/access/netmiko_connection.py", line 82, in __init__
2024-01-02 00:54:09,381 T0002: INFO      super(NetmikoConnection, self).__init__(**kwargs)
2024-01-02 00:54:09,382 T0002: INFO    File "/usr/local/lib/python3.8/dist-packages/netmiko/base_connection.py", line 244, in __init__
2024-01-02 00:54:09,382 T0002: INFO      raise ValueError("Either ip or host must be set")
2024-01-02 00:54:09,383 T0002: INFO  ValueError: Either ip or host must be se
2024-01-02 00:54:09,383 T0002: INFO  StackTraceCallStack:
2024-01-02 00:54:09,384 T0002: INFO  [0] spytest/access/netmiko_connection.py:104 __init__ self.log_exception(msg, call_stack=True, dump=True)
2024-01-02 00:54:09,384 T0002: INFO  [1] spytest/access/connection.py:48 _DeviceConnection return NetmikoConnection(**kwargs)
2024-01-02 00:54:09,385 T0002: INFO  [2] spytest/access/connection.py:160 DeviceConnection hndl = _DeviceConnection(devname, ip_port, logger, **kwargs)
2024-01-02 00:54:09,385 T0002: INFO  [3] spytest/net.py:694 _do_connect_cinfo net_connect = DeviceConnection(devname=dut_name, logger=self.logger, **cinfo)
2024-01-02 00:54:09,386 T0002: INFO  [4] spytest/net.py:723 _connect_to_device net_connect = self._do_connect_cinfo(cinfo, retry, msgs, devname)
2024-01-02 00:54:09,386 T0002: INFO  [5] spytest/net.py:1118 connect_to_device_real net_connect = self._connect_to_device(connection_param, access, retry=retry)
2024-01-02 00:54:09,387 T0002: INFO  [6] spytest/net.py:1064 connect_to_device show_ver_output = self.connect_to_device_real(access, retry, recon, recover)
2024-01-02 00:54:09,387 T0002: INFO  [7] utilities/parallel.py:159 _thread_func retvals[index] = func(*args, **kwargs)
2024-01-02 00:54:09,388 T0002: INFO  [8] utilities/parallel.py:182 exec_foreach2 _thread_func(*args, **kwargs)
2024-01-02 00:54:09,388 T0002: INFO  [9] spytest/net.py:1584 connect_all_devices rvs, exps = putils.exec_foreach2(faster_init, on_except, self.topo.duts,
2024-01-02 00:54:09,389 T0002: INFO  [10] utilities/parallel.py:219 _thread_func retvals[index] = func(*args, **kwargs)
2024-01-02 00:54:09,389 T0002: INFO  --------------------------------------------
2024-01-02 00:54:09,390 T0002: INFO  ============================================
2024-01-02 00:54:09,390 T0002: WARN  Exception(None:22): Runtime Exception: Connection Unknown Error..
2024-01-02 00:54:09,390 T0002: INFO  connection-Err..
2024-01-02 00:54:49,432 T0002: INFO  Re-Trying 11..
2024-01-02 00:54:49,432 T0002: INFO  TRY Authentication: None:22 admin YourPaSsWoRd
2024-01-02 00:54:49,434 T0002: INFO  ======== Connection: Connection Unknown Error.. ======
2024-01-02 00:54:49,437 T0002: INFO  Traceback (most recent call last):
2024-01-02 00:54:49,439 T0002: INFO    File "/repo/spytest/access/netmiko_connection.py", line 82, in __init__
2024-01-02 00:54:49,441 T0002: INFO      super(NetmikoConnection, self).__init__(**kwargs)
2024-01-02 00:54:49,442 T0002: INFO    File "/usr/local/lib/python3.8/dist-packages/netmiko/base_connection.py", line 244, in __init__
2024-01-02 00:54:49,443 T0002: INFO      raise ValueError("Either ip or host must be set")
2024-01-02 00:54:49,443 T0002: INFO  ValueError: Either ip or host must be se
2024-01-02 00:54:49,444 T0002: INFO  StackTraceCallStack:
2024-01-02 00:54:49,444 T0002: INFO  [0] spytest/access/netmiko_connection.py:104 __init__ self.log_exception(msg, call_stack=True, dump=True)
2024-01-02 00:54:49,445 T0002: INFO  [1] spytest/access/connection.py:48 _DeviceConnection return NetmikoConnection(**kwargs)
2024-01-02 00:54:49,446 T0002: INFO  [2] spytest/access/connection.py:160 DeviceConnection hndl = _DeviceConnection(devname, ip_port, logger, **kwargs)
2024-01-02 00:54:49,446 T0002: INFO  [3] spytest/net.py:694 _do_connect_cinfo net_connect = DeviceConnection(devname=dut_name, logger=self.logger, **cinfo)
2024-01-02 00:54:49,447 T0002: INFO  [4] spytest/net.py:723 _connect_to_device net_connect = self._do_connect_cinfo(cinfo, retry, msgs, devname)
2024-01-02 00:54:49,447 T0002: INFO  [5] spytest/net.py:1118 connect_to_device_real net_connect = self._connect_to_device(connection_param, access, retry=retry)
2024-01-02 00:54:49,448 T0002: INFO  [6] spytest/net.py:1064 connect_to_device show_ver_output = self.connect_to_device_real(access, retry, recon, recover)
2024-01-02 00:54:49,448 T0002: INFO  [7] utilities/parallel.py:159 _thread_func retvals[index] = func(*args, **kwargs)
2024-01-02 00:54:49,449 T0002: INFO  [8] utilities/parallel.py:182 exec_foreach2 _thread_func(*args, **kwargs)
2024-01-02 00:54:49,449 T0002: INFO  [9] spytest/net.py:1584 connect_all_devices rvs, exps = putils.exec_foreach2(faster_init, on_except, self.topo.duts,
2024-01-02 00:54:49,450 T0002: INFO  [10] utilities/parallel.py:219 _thread_func retvals[index] = func(*args, **kwargs)
2024-01-02 00:54:49,450 T0002: INFO  --------------------------------------------
2024-01-02 00:54:49,451 T0002: INFO  ============================================
2024-01-02 00:54:49,451 T0002: WARN  Exception(None:22): Runtime Exception: Connection Unknown Error..
2024-01-02 00:54:49,451 T0002: INFO  TRY ALT Authentication: None:22 admin broadcom
2024-01-02 00:54:49,451 T0002: INFO  ======== Connection: Connection Unknown Error.. ======
2024-01-02 00:54:49,452 T0002: INFO  Traceback (most recent call last):
2024-01-02 00:54:49,453 T0002: INFO    File "/repo/spytest/access/netmiko_connection.py", line 82, in __init__
2024-01-02 00:54:49,453 T0002: INFO      super(NetmikoConnection, self).__init__(**kwargs)
2024-01-02 00:54:49,454 T0002: INFO    File "/usr/local/lib/python3.8/dist-packages/netmiko/base_connection.py", line 244, in __init__
2024-01-02 00:54:49,454 T0002: INFO      raise ValueError("Either ip or host must be set")
2024-01-02 00:54:49,455 T0002: INFO  ValueError: Either ip or host must be se
2024-01-02 00:54:49,455 T0002: INFO  StackTraceCallStack:
2024-01-02 00:54:49,456 T0002: INFO  [0] spytest/access/netmiko_connection.py:104 __init__ self.log_exception(msg, call_stack=True, dump=True)
2024-01-02 00:54:49,456 T0002: INFO  [1] spytest/access/connection.py:48 _DeviceConnection return NetmikoConnection(**kwargs)
2024-01-02 00:54:49,457 T0002: INFO  [2] spytest/access/connection.py:160 DeviceConnection hndl = _DeviceConnection(devname, ip_port, logger, **kwargs)
2024-01-02 00:54:49,458 T0002: INFO  [3] spytest/net.py:694 _do_connect_cinfo net_connect = DeviceConnection(devname=dut_name, logger=self.logger, **cinfo)
2024-01-02 00:54:49,458 T0002: INFO  [4] spytest/net.py:723 _connect_to_device net_connect = self._do_connect_cinfo(cinfo, retry, msgs, devname)
2024-01-02 00:54:49,459 T0002: INFO  [5] spytest/net.py:1118 connect_to_device_real net_connect = self._connect_to_device(connection_param, access, retry=retry)
2024-01-02 00:54:49,459 T0002: INFO  [6] spytest/net.py:1064 connect_to_device show_ver_output = self.connect_to_device_real(access, retry, recon, recover)
2024-01-02 00:54:49,460 T0002: INFO  [7] utilities/parallel.py:159 _thread_func retvals[index] = func(*args, **kwargs)
2024-01-02 00:54:49,460 T0002: INFO  [8] utilities/parallel.py:182 exec_foreach2 _thread_func(*args, **kwargs)
2024-01-02 00:54:49,461 T0002: INFO  [9] spytest/net.py:1584 connect_all_devices rvs, exps = putils.exec_foreach2(faster_init, on_except, self.topo.duts,
2024-01-02 00:54:49,461 T0002: INFO  [10] utilities/parallel.py:219 _thread_func retvals[index] = func(*args, **kwargs)
2024-01-02 00:54:49,462 T0002: INFO  --------------------------------------------
2024-01-02 00:54:49,462 T0002: INFO  ============================================
2024-01-02 00:54:49,462 T0002: WARN  Exception(None:22): Runtime Exception: Connection Unknown Error..
2024-01-02 00:54:49,463 T0002: INFO  connection-Err..
2024-01-02 00:54:49,463 T0002: INFO  Cannot connect: None:22
2024-01-02 00:54:49,469 T0002: INFO  Existing Connections: pconn(fd=14, family=<AddressFamily.AF_INET: 2>, type=<SocketKind.SOCK_STREAM: 1>, laddr=addr(ip='127.0.0.1', port=55750), raddr=addr(ip='127.0.0.1', port=8009), status='ESTABLISHED')
2024-01-02 00:54:49,469 T0002: ERROR Failed to connect to device D1-V1
2024-01-02 00:54:49,469 T0002: ERROR Failed to connect to device
