2024-01-02 00:43:38,678 T0014: INFO  Connecting to device (V3): sonic_ssh: None:22 ..
2024-01-02 00:43:38,678 T0014: INFO  TRY Authentication: None:22 admin YourPaSsWoRd
2024-01-02 00:43:38,685 T0014: INFO  ======== Connection: Connection Unknown Error.. ======
2024-01-02 00:43:38,691 T0014: INFO  Traceback (most recent call last):
2024-01-02 00:43:38,696 T0014: INFO    File "/repo/spytest/access/netmiko_connection.py", line 82, in __init__
2024-01-02 00:43:38,697 T0014: INFO      super(NetmikoConnection, self).__init__(**kwargs)
2024-01-02 00:43:38,709 T0014: INFO    File "/usr/local/lib/python3.8/dist-packages/netmiko/base_connection.py", line 244, in __init__
2024-01-02 00:43:38,720 T0014: INFO      raise ValueError("Either ip or host must be set")
2024-01-02 00:43:38,729 T0014: INFO  ValueError: Either ip or host must be se
2024-01-02 00:43:38,730 T0014: INFO  StackTraceCallStack:
2024-01-02 00:43:38,736 T0014: INFO  [0] spytest/access/netmiko_connection.py:104 __init__ self.log_exception(msg, call_stack=True, dump=True)
2024-01-02 00:43:38,743 T0014: INFO  [1] spytest/access/connection.py:48 _DeviceConnection return NetmikoConnection(**kwargs)
2024-01-02 00:43:38,749 T0014: INFO  [2] spytest/access/connection.py:160 DeviceConnection hndl = _DeviceConnection(devname, ip_port, logger, **kwargs)
2024-01-02 00:43:38,756 T0014: INFO  [3] spytest/net.py:694 _do_connect_cinfo net_connect = DeviceConnection(devname=dut_name, logger=self.logger, **cinfo)
2024-01-02 00:43:38,762 T0014: INFO  [4] spytest/net.py:723 _connect_to_device net_connect = self._do_connect_cinfo(cinfo, retry, msgs, devname)
2024-01-02 00:43:38,768 T0014: INFO  [5] spytest/net.py:1118 connect_to_device_real net_connect = self._connect_to_device(connection_param, access, retry=retry)
2024-01-02 00:43:38,774 T0014: INFO  [6] spytest/net.py:1064 connect_to_device show_ver_output = self.connect_to_device_real(access, retry, recon, recover)
2024-01-02 00:43:38,781 T0014: INFO  [7] utilities/parallel.py:159 _thread_func retvals[index] = func(*args, **kwargs)
2024-01-02 00:43:38,788 T0014: INFO  [8] spytest/net.py:1584 connect_all_devices rvs, exps = putils.exec_foreach2(faster_init, on_except, self.topo.duts,
2024-01-02 00:43:38,795 T0014: INFO  [9] utilities/parallel.py:219 _thread_func retvals[index] = func(*args, **kwargs)
2024-01-02 00:43:38,803 T0014: INFO  --------------------------------------------
2024-01-02 00:43:38,811 T0014: INFO  ============================================
2024-01-02 00:43:38,811 T0014: WARN  Exception(None:22): Runtime Exception: Connection Unknown Error..
2024-01-02 00:43:38,812 T0014: INFO  TRY ALT Authentication: None:22 admin broadcom
2024-01-02 00:43:38,818 T0014: INFO  ======== Connection: Connection Unknown Error.. ======
2024-01-02 00:43:38,825 T0014: INFO  Traceback (most recent call last):
2024-01-02 00:43:38,831 T0014: INFO    File "/repo/spytest/access/netmiko_connection.py", line 82, in __init__
2024-01-02 00:43:38,832 T0014: INFO      super(NetmikoConnection, self).__init__(**kwargs)
2024-01-02 00:43:38,837 T0014: INFO    File "/usr/local/lib/python3.8/dist-packages/netmiko/base_connection.py", line 244, in __init__
2024-01-02 00:43:38,838 T0014: INFO      raise ValueError("Either ip or host must be set")
2024-01-02 00:43:38,839 T0014: INFO  ValueError: Either ip or host must be se
2024-01-02 00:43:38,849 T0014: INFO  StackTraceCallStack:
2024-01-02 00:43:38,855 T0014: INFO  [0] spytest/access/netmiko_connection.py:104 __init__ self.log_exception(msg, call_stack=True, dump=True)
2024-01-02 00:43:38,860 T0014: INFO  [1] spytest/access/connection.py:48 _DeviceConnection return NetmikoConnection(**kwargs)
2024-01-02 00:43:38,867 T0014: INFO  [2] spytest/access/connection.py:160 DeviceConnection hndl = _DeviceConnection(devname, ip_port, logger, **kwargs)
2024-01-02 00:43:38,873 T0014: INFO  [3] spytest/net.py:694 _do_connect_cinfo net_connect = DeviceConnection(devname=dut_name, logger=self.logger, **cinfo)
2024-01-02 00:43:38,880 T0014: INFO  [4] spytest/net.py:723 _connect_to_device net_connect = self._do_connect_cinfo(cinfo, retry, msgs, devname)
2024-01-02 00:43:38,887 T0014: INFO  [5] spytest/net.py:1118 connect_to_device_real net_connect = self._connect_to_device(connection_param, access, retry=retry)
2024-01-02 00:43:38,893 T0014: INFO  [6] spytest/net.py:1064 connect_to_device show_ver_output = self.connect_to_device_real(access, retry, recon, recover)
2024-01-02 00:43:38,899 T0014: INFO  [7] utilities/parallel.py:159 _thread_func retvals[index] = func(*args, **kwargs)
2024-01-02 00:43:38,905 T0014: INFO  [8] spytest/net.py:1584 connect_all_devices rvs, exps = putils.exec_foreach2(faster_init, on_except, self.topo.duts,
2024-01-02 00:43:38,912 T0014: INFO  [9] utilities/parallel.py:219 _thread_func retvals[index] = func(*args, **kwargs)
2024-01-02 00:43:38,919 T0014: INFO  --------------------------------------------
2024-01-02 00:43:38,925 T0014: INFO  ============================================
2024-01-02 00:43:38,926 T0014: WARN  Exception(None:22): Runtime Exception: Connection Unknown Error..
2024-01-02 00:43:38,931 T0014: INFO  connection-Err..
2024-01-02 00:43:42,939 T0014: INFO  Re-Trying 2..
2024-01-02 00:43:42,940 T0014: INFO  TRY Authentication: None:22 admin YourPaSsWoRd
2024-01-02 00:43:42,944 T0014: INFO  ======== Connection: Connection Unknown Error.. ======
2024-01-02 00:43:42,952 T0014: INFO  Traceback (most recent call last):
2024-01-02 00:43:42,958 T0014: INFO    File "/repo/spytest/access/netmiko_connection.py", line 82, in __init__
2024-01-02 00:43:42,963 T0014: INFO      super(NetmikoConnection, self).__init__(**kwargs)
2024-01-02 00:43:42,978 T0014: INFO    File "/usr/local/lib/python3.8/dist-packages/netmiko/base_connection.py", line 244, in __init__
2024-01-02 00:43:42,984 T0014: INFO      raise ValueError("Either ip or host must be set")
2024-01-02 00:43:42,995 T0014: INFO  ValueError: Either ip or host must be se
2024-01-02 00:43:43,001 T0014: INFO  StackTraceCallStack:
2024-01-02 00:43:43,007 T0014: INFO  [0] spytest/access/netmiko_connection.py:104 __init__ self.log_exception(msg, call_stack=True, dump=True)
2024-01-02 00:43:43,013 T0014: INFO  [1] spytest/access/connection.py:48 _DeviceConnection return NetmikoConnection(**kwargs)
2024-01-02 00:43:43,019 T0014: INFO  [2] spytest/access/connection.py:160 DeviceConnection hndl = _DeviceConnection(devname, ip_port, logger, **kwargs)
2024-01-02 00:43:43,026 T0014: INFO  [3] spytest/net.py:694 _do_connect_cinfo net_connect = DeviceConnection(devname=dut_name, logger=self.logger, **cinfo)
2024-01-02 00:43:43,033 T0014: INFO  [4] spytest/net.py:723 _connect_to_device net_connect = self._do_connect_cinfo(cinfo, retry, msgs, devname)
2024-01-02 00:43:43,040 T0014: INFO  [5] spytest/net.py:1118 connect_to_device_real net_connect = self._connect_to_device(connection_param, access, retry=retry)
2024-01-02 00:43:43,047 T0014: INFO  [6] spytest/net.py:1064 connect_to_device show_ver_output = self.connect_to_device_real(access, retry, recon, recover)
2024-01-02 00:43:43,054 T0014: INFO  [7] utilities/parallel.py:159 _thread_func retvals[index] = func(*args, **kwargs)
2024-01-02 00:43:43,063 T0014: INFO  [8] spytest/net.py:1584 connect_all_devices rvs, exps = putils.exec_foreach2(faster_init, on_except, self.topo.duts,
2024-01-02 00:43:43,069 T0014: INFO  [9] utilities/parallel.py:219 _thread_func retvals[index] = func(*args, **kwargs)
2024-01-02 00:43:43,075 T0014: INFO  --------------------------------------------
2024-01-02 00:43:43,082 T0014: INFO  ============================================
2024-01-02 00:43:43,082 T0014: WARN  Exception(None:22): Runtime Exception: Connection Unknown Error..
2024-01-02 00:43:43,083 T0014: INFO  TRY ALT Authentication: None:22 admin broadcom
2024-01-02 00:43:43,088 T0014: INFO  ======== Connection: Connection Unknown Error.. ======
2024-01-02 00:43:43,095 T0014: INFO  Traceback (most recent call last):
2024-01-02 00:43:43,105 T0014: INFO    File "/repo/spytest/access/netmiko_connection.py", line 82, in __init__
2024-01-02 00:43:43,106 T0014: INFO      super(NetmikoConnection, self).__init__(**kwargs)
2024-01-02 00:43:43,113 T0014: INFO    File "/usr/local/lib/python3.8/dist-packages/netmiko/base_connection.py", line 244, in __init__
2024-01-02 00:43:43,119 T0014: INFO      raise ValueError("Either ip or host must be set")
2024-01-02 00:43:43,125 T0014: INFO  ValueError: Either ip or host must be se
2024-01-02 00:43:43,127 T0014: INFO  StackTraceCallStack:
2024-01-02 00:43:43,133 T0014: INFO  [0] spytest/access/netmiko_connection.py:104 __init__ self.log_exception(msg, call_stack=True, dump=True)
2024-01-02 00:43:43,140 T0014: INFO  [1] spytest/access/connection.py:48 _DeviceConnection return NetmikoConnection(**kwargs)
2024-01-02 00:43:43,146 T0014: INFO  [2] spytest/access/connection.py:160 DeviceConnection hndl = _DeviceConnection(devname, ip_port, logger, **kwargs)
2024-01-02 00:43:43,152 T0014: INFO  [3] spytest/net.py:694 _do_connect_cinfo net_connect = DeviceConnection(devname=dut_name, logger=self.logger, **cinfo)
2024-01-02 00:43:43,159 T0014: INFO  [4] spytest/net.py:723 _connect_to_device net_connect = self._do_connect_cinfo(cinfo, retry, msgs, devname)
2024-01-02 00:43:43,166 T0014: INFO  [5] spytest/net.py:1118 connect_to_device_real net_connect = self._connect_to_device(connection_param, access, retry=retry)
2024-01-02 00:43:43,174 T0014: INFO  [6] spytest/net.py:1064 connect_to_device show_ver_output = self.connect_to_device_real(access, retry, recon, recover)
2024-01-02 00:43:43,180 T0014: INFO  [7] utilities/parallel.py:159 _thread_func retvals[index] = func(*args, **kwargs)
2024-01-02 00:43:43,187 T0014: INFO  [8] spytest/net.py:1584 connect_all_devices rvs, exps = putils.exec_foreach2(faster_init, on_except, self.topo.duts,
2024-01-02 00:43:43,193 T0014: INFO  [9] utilities/parallel.py:219 _thread_func retvals[index] = func(*args, **kwargs)
2024-01-02 00:43:43,198 T0014: INFO  --------------------------------------------
2024-01-02 00:43:43,201 T0014: INFO  ============================================
2024-01-02 00:43:43,201 T0014: WARN  Exception(None:22): Runtime Exception: Connection Unknown Error..
2024-01-02 00:43:43,202 T0014: INFO  connection-Err..
2024-01-02 00:43:51,221 T0014: INFO  Re-Trying 3..
2024-01-02 00:43:51,222 T0014: INFO  TRY Authentication: None:22 admin YourPaSsWoRd
2024-01-02 00:43:51,227 T0014: INFO  ======== Connection: Connection Unknown Error.. ======
2024-01-02 00:43:51,232 T0014: INFO  Traceback (most recent call last):
2024-01-02 00:43:51,240 T0014: INFO    File "/repo/spytest/access/netmiko_connection.py", line 82, in __init__
2024-01-02 00:43:51,241 T0014: INFO      super(NetmikoConnection, self).__init__(**kwargs)
2024-01-02 00:43:51,247 T0014: INFO    File "/usr/local/lib/python3.8/dist-packages/netmiko/base_connection.py", line 244, in __init__
2024-01-02 00:43:51,248 T0014: INFO      raise ValueError("Either ip or host must be set")
2024-01-02 00:43:51,248 T0014: INFO  ValueError: Either ip or host must be se
2024-01-02 00:43:51,249 T0014: INFO  StackTraceCallStack:
2024-01-02 00:43:51,258 T0014: INFO  [0] spytest/access/netmiko_connection.py:104 __init__ self.log_exception(msg, call_stack=True, dump=True)
2024-01-02 00:43:51,264 T0014: INFO  [1] spytest/access/connection.py:48 _DeviceConnection return NetmikoConnection(**kwargs)
2024-01-02 00:43:51,270 T0014: INFO  [2] spytest/access/connection.py:160 DeviceConnection hndl = _DeviceConnection(devname, ip_port, logger, **kwargs)
2024-01-02 00:43:51,276 T0014: INFO  [3] spytest/net.py:694 _do_connect_cinfo net_connect = DeviceConnection(devname=dut_name, logger=self.logger, **cinfo)
2024-01-02 00:43:51,283 T0014: INFO  [4] spytest/net.py:723 _connect_to_device net_connect = self._do_connect_cinfo(cinfo, retry, msgs, devname)
2024-01-02 00:43:51,290 T0014: INFO  [5] spytest/net.py:1118 connect_to_device_real net_connect = self._connect_to_device(connection_param, access, retry=retry)
2024-01-02 00:43:51,297 T0014: INFO  [6] spytest/net.py:1064 connect_to_device show_ver_output = self.connect_to_device_real(access, retry, recon, recover)
2024-01-02 00:43:51,304 T0014: INFO  [7] utilities/parallel.py:159 _thread_func retvals[index] = func(*args, **kwargs)
2024-01-02 00:43:51,311 T0014: INFO  [8] spytest/net.py:1584 connect_all_devices rvs, exps = putils.exec_foreach2(faster_init, on_except, self.topo.duts,
2024-01-02 00:43:51,318 T0014: INFO  [9] utilities/parallel.py:219 _thread_func retvals[index] = func(*args, **kwargs)
2024-01-02 00:43:51,326 T0014: INFO  --------------------------------------------
2024-01-02 00:43:51,332 T0014: INFO  ============================================
2024-01-02 00:43:51,332 T0014: WARN  Exception(None:22): Runtime Exception: Connection Unknown Error..
2024-01-02 00:43:51,332 T0014: INFO  TRY ALT Authentication: None:22 admin broadcom
2024-01-02 00:43:51,339 T0014: INFO  ======== Connection: Connection Unknown Error.. ======
2024-01-02 00:43:51,346 T0014: INFO  Traceback (most recent call last):
2024-01-02 00:43:51,352 T0014: INFO    File "/repo/spytest/access/netmiko_connection.py", line 82, in __init__
2024-01-02 00:43:51,358 T0014: INFO      super(NetmikoConnection, self).__init__(**kwargs)
2024-01-02 00:43:51,363 T0014: INFO    File "/usr/local/lib/python3.8/dist-packages/netmiko/base_connection.py", line 244, in __init__
2024-01-02 00:43:51,369 T0014: INFO      raise ValueError("Either ip or host must be set")
2024-01-02 00:43:51,375 T0014: INFO  ValueError: Either ip or host must be se
2024-01-02 00:43:51,377 T0014: INFO  StackTraceCallStack:
2024-01-02 00:43:51,383 T0014: INFO  [0] spytest/access/netmiko_connection.py:104 __init__ self.log_exception(msg, call_stack=True, dump=True)
2024-01-02 00:43:51,389 T0014: INFO  [1] spytest/access/connection.py:48 _DeviceConnection return NetmikoConnection(**kwargs)
2024-01-02 00:43:51,396 T0014: INFO  [2] spytest/access/connection.py:160 DeviceConnection hndl = _DeviceConnection(devname, ip_port, logger, **kwargs)
2024-01-02 00:43:51,402 T0014: INFO  [3] spytest/net.py:694 _do_connect_cinfo net_connect = DeviceConnection(devname=dut_name, logger=self.logger, **cinfo)
2024-01-02 00:43:51,410 T0014: INFO  [4] spytest/net.py:723 _connect_to_device net_connect = self._do_connect_cinfo(cinfo, retry, msgs, devname)
2024-01-02 00:43:51,417 T0014: INFO  [5] spytest/net.py:1118 connect_to_device_real net_connect = self._connect_to_device(connection_param, access, retry=retry)
2024-01-02 00:43:51,425 T0014: INFO  [6] spytest/net.py:1064 connect_to_device show_ver_output = self.connect_to_device_real(access, retry, recon, recover)
2024-01-02 00:43:51,432 T0014: INFO  [7] utilities/parallel.py:159 _thread_func retvals[index] = func(*args, **kwargs)
2024-01-02 00:43:51,438 T0014: INFO  [8] spytest/net.py:1584 connect_all_devices rvs, exps = putils.exec_foreach2(faster_init, on_except, self.topo.duts,
2024-01-02 00:43:51,445 T0014: INFO  [9] utilities/parallel.py:219 _thread_func retvals[index] = func(*args, **kwargs)
2024-01-02 00:43:51,452 T0014: INFO  --------------------------------------------
2024-01-02 00:43:51,459 T0014: INFO  ============================================
2024-01-02 00:43:51,460 T0014: WARN  Exception(None:22): Runtime Exception: Connection Unknown Error..
2024-01-02 00:43:51,463 T0014: INFO  connection-Err..
2024-01-02 00:44:03,482 T0014: INFO  Re-Trying 4..
2024-01-02 00:44:03,482 T0014: INFO  TRY Authentication: None:22 admin YourPaSsWoRd
2024-01-02 00:44:03,491 T0014: INFO  ======== Connection: Connection Unknown Error.. ======
2024-01-02 00:44:03,498 T0014: INFO  Traceback (most recent call last):
2024-01-02 00:44:03,504 T0014: INFO    File "/repo/spytest/access/netmiko_connection.py", line 82, in __init__
2024-01-02 00:44:03,509 T0014: INFO      super(NetmikoConnection, self).__init__(**kwargs)
2024-01-02 00:44:03,515 T0014: INFO    File "/usr/local/lib/python3.8/dist-packages/netmiko/base_connection.py", line 244, in __init__
2024-01-02 00:44:03,520 T0014: INFO      raise ValueError("Either ip or host must be set")
2024-01-02 00:44:03,522 T0014: INFO  ValueError: Either ip or host must be se
2024-01-02 00:44:03,527 T0014: INFO  StackTraceCallStack:
2024-01-02 00:44:03,534 T0014: INFO  [0] spytest/access/netmiko_connection.py:104 __init__ self.log_exception(msg, call_stack=True, dump=True)
2024-01-02 00:44:03,541 T0014: INFO  [1] spytest/access/connection.py:48 _DeviceConnection return NetmikoConnection(**kwargs)
2024-01-02 00:44:03,548 T0014: INFO  [2] spytest/access/connection.py:160 DeviceConnection hndl = _DeviceConnection(devname, ip_port, logger, **kwargs)
2024-01-02 00:44:03,555 T0014: INFO  [3] spytest/net.py:694 _do_connect_cinfo net_connect = DeviceConnection(devname=dut_name, logger=self.logger, **cinfo)
2024-01-02 00:44:03,563 T0014: INFO  [4] spytest/net.py:723 _connect_to_device net_connect = self._do_connect_cinfo(cinfo, retry, msgs, devname)
2024-01-02 00:44:03,570 T0014: INFO  [5] spytest/net.py:1118 connect_to_device_real net_connect = self._connect_to_device(connection_param, access, retry=retry)
2024-01-02 00:44:03,576 T0014: INFO  [6] spytest/net.py:1064 connect_to_device show_ver_output = self.connect_to_device_real(access, retry, recon, recover)
2024-01-02 00:44:03,581 T0014: INFO  [7] utilities/parallel.py:159 _thread_func retvals[index] = func(*args, **kwargs)
2024-01-02 00:44:03,587 T0014: INFO  [8] spytest/net.py:1584 connect_all_devices rvs, exps = putils.exec_foreach2(faster_init, on_except, self.topo.duts,
2024-01-02 00:44:03,593 T0014: INFO  [9] utilities/parallel.py:219 _thread_func retvals[index] = func(*args, **kwargs)
2024-01-02 00:44:03,599 T0014: INFO  --------------------------------------------
2024-01-02 00:44:03,605 T0014: INFO  ============================================
2024-01-02 00:44:03,605 T0014: WARN  Exception(None:22): Runtime Exception: Connection Unknown Error..
2024-01-02 00:44:03,606 T0014: INFO  TRY ALT Authentication: None:22 admin broadcom
2024-01-02 00:44:03,612 T0014: INFO  ======== Connection: Connection Unknown Error.. ======
2024-01-02 00:44:03,620 T0014: INFO  Traceback (most recent call last):
2024-01-02 00:44:03,626 T0014: INFO    File "/repo/spytest/access/netmiko_connection.py", line 82, in __init__
2024-01-02 00:44:03,632 T0014: INFO      super(NetmikoConnection, self).__init__(**kwargs)
2024-01-02 00:44:03,638 T0014: INFO    File "/usr/local/lib/python3.8/dist-packages/netmiko/base_connection.py", line 244, in __init__
2024-01-02 00:44:03,645 T0014: INFO      raise ValueError("Either ip or host must be set")
2024-01-02 00:44:03,646 T0014: INFO  ValueError: Either ip or host must be se
2024-01-02 00:44:03,647 T0014: INFO  StackTraceCallStack:
2024-01-02 00:44:03,654 T0014: INFO  [0] spytest/access/netmiko_connection.py:104 __init__ self.log_exception(msg, call_stack=True, dump=True)
2024-01-02 00:44:03,660 T0014: INFO  [1] spytest/access/connection.py:48 _DeviceConnection return NetmikoConnection(**kwargs)
2024-01-02 00:44:03,666 T0014: INFO  [2] spytest/access/connection.py:160 DeviceConnection hndl = _DeviceConnection(devname, ip_port, logger, **kwargs)
2024-01-02 00:44:03,672 T0014: INFO  [3] spytest/net.py:694 _do_connect_cinfo net_connect = DeviceConnection(devname=dut_name, logger=self.logger, **cinfo)
2024-01-02 00:44:03,679 T0014: INFO  [4] spytest/net.py:723 _connect_to_device net_connect = self._do_connect_cinfo(cinfo, retry, msgs, devname)
2024-01-02 00:44:03,687 T0014: INFO  [5] spytest/net.py:1118 connect_to_device_real net_connect = self._connect_to_device(connection_param, access, retry=retry)
2024-01-02 00:44:03,693 T0014: INFO  [6] spytest/net.py:1064 connect_to_device show_ver_output = self.connect_to_device_real(access, retry, recon, recover)
2024-01-02 00:44:03,698 T0014: INFO  [7] utilities/parallel.py:159 _thread_func retvals[index] = func(*args, **kwargs)
2024-01-02 00:44:03,703 T0014: INFO  [8] spytest/net.py:1584 connect_all_devices rvs, exps = putils.exec_foreach2(faster_init, on_except, self.topo.duts,
2024-01-02 00:44:03,707 T0014: INFO  [9] utilities/parallel.py:219 _thread_func retvals[index] = func(*args, **kwargs)
2024-01-02 00:44:03,710 T0014: INFO  --------------------------------------------
2024-01-02 00:44:03,712 T0014: INFO  ============================================
2024-01-02 00:44:03,713 T0014: WARN  Exception(None:22): Runtime Exception: Connection Unknown Error..
2024-01-02 00:44:03,715 T0014: INFO  connection-Err..
2024-01-02 00:44:19,728 T0014: INFO  Re-Trying 5..
2024-01-02 00:44:19,728 T0014: INFO  TRY Authentication: None:22 admin YourPaSsWoRd
2024-01-02 00:44:19,732 T0014: INFO  ======== Connection: Connection Unknown Error.. ======
2024-01-02 00:44:19,736 T0014: INFO  Traceback (most recent call last):
2024-01-02 00:44:19,741 T0014: INFO    File "/repo/spytest/access/netmiko_connection.py", line 82, in __init__
2024-01-02 00:44:19,742 T0014: INFO      super(NetmikoConnection, self).__init__(**kwargs)
2024-01-02 00:44:19,748 T0014: INFO    File "/usr/local/lib/python3.8/dist-packages/netmiko/base_connection.py", line 244, in __init__
2024-01-02 00:44:19,748 T0014: INFO      raise ValueError("Either ip or host must be set")
2024-01-02 00:44:19,749 T0014: INFO  ValueError: Either ip or host must be se
2024-01-02 00:44:19,754 T0014: INFO  StackTraceCallStack:
2024-01-02 00:44:19,759 T0014: INFO  [0] spytest/access/netmiko_connection.py:104 __init__ self.log_exception(msg, call_stack=True, dump=True)
2024-01-02 00:44:19,765 T0014: INFO  [1] spytest/access/connection.py:48 _DeviceConnection return NetmikoConnection(**kwargs)
2024-01-02 00:44:19,770 T0014: INFO  [2] spytest/access/connection.py:160 DeviceConnection hndl = _DeviceConnection(devname, ip_port, logger, **kwargs)
2024-01-02 00:44:19,776 T0014: INFO  [3] spytest/net.py:694 _do_connect_cinfo net_connect = DeviceConnection(devname=dut_name, logger=self.logger, **cinfo)
2024-01-02 00:44:19,783 T0014: INFO  [4] spytest/net.py:723 _connect_to_device net_connect = self._do_connect_cinfo(cinfo, retry, msgs, devname)
2024-01-02 00:44:19,789 T0014: INFO  [5] spytest/net.py:1118 connect_to_device_real net_connect = self._connect_to_device(connection_param, access, retry=retry)
2024-01-02 00:44:19,796 T0014: INFO  [6] spytest/net.py:1064 connect_to_device show_ver_output = self.connect_to_device_real(access, retry, recon, recover)
2024-01-02 00:44:19,804 T0014: INFO  [7] utilities/parallel.py:159 _thread_func retvals[index] = func(*args, **kwargs)
2024-01-02 00:44:19,813 T0014: INFO  [8] spytest/net.py:1584 connect_all_devices rvs, exps = putils.exec_foreach2(faster_init, on_except, self.topo.duts,
2024-01-02 00:44:19,818 T0014: INFO  [9] utilities/parallel.py:219 _thread_func retvals[index] = func(*args, **kwargs)
2024-01-02 00:44:19,819 T0014: INFO  --------------------------------------------
2024-01-02 00:44:19,820 T0014: INFO  ============================================
2024-01-02 00:44:19,820 T0014: WARN  Exception(None:22): Runtime Exception: Connection Unknown Error..
2024-01-02 00:44:19,820 T0014: INFO  TRY ALT Authentication: None:22 admin broadcom
2024-01-02 00:44:19,825 T0014: INFO  ======== Connection: Connection Unknown Error.. ======
2024-01-02 00:44:19,831 T0014: INFO  Traceback (most recent call last):
2024-01-02 00:44:19,837 T0014: INFO    File "/repo/spytest/access/netmiko_connection.py", line 82, in __init__
2024-01-02 00:44:19,839 T0014: INFO      super(NetmikoConnection, self).__init__(**kwargs)
2024-01-02 00:44:19,844 T0014: INFO    File "/usr/local/lib/python3.8/dist-packages/netmiko/base_connection.py", line 244, in __init__
2024-01-02 00:44:19,851 T0014: INFO      raise ValueError("Either ip or host must be set")
2024-01-02 00:44:19,857 T0014: INFO  ValueError: Either ip or host must be se
2024-01-02 00:44:19,863 T0014: INFO  StackTraceCallStack:
2024-01-02 00:44:19,870 T0014: INFO  [0] spytest/access/netmiko_connection.py:104 __init__ self.log_exception(msg, call_stack=True, dump=True)
2024-01-02 00:44:19,878 T0014: INFO  [1] spytest/access/connection.py:48 _DeviceConnection return NetmikoConnection(**kwargs)
2024-01-02 00:44:19,885 T0014: INFO  [2] spytest/access/connection.py:160 DeviceConnection hndl = _DeviceConnection(devname, ip_port, logger, **kwargs)
2024-01-02 00:44:19,891 T0014: INFO  [3] spytest/net.py:694 _do_connect_cinfo net_connect = DeviceConnection(devname=dut_name, logger=self.logger, **cinfo)
2024-01-02 00:44:19,898 T0014: INFO  [4] spytest/net.py:723 _connect_to_device net_connect = self._do_connect_cinfo(cinfo, retry, msgs, devname)
2024-01-02 00:44:19,905 T0014: INFO  [5] spytest/net.py:1118 connect_to_device_real net_connect = self._connect_to_device(connection_param, access, retry=retry)
2024-01-02 00:44:19,911 T0014: INFO  [6] spytest/net.py:1064 connect_to_device show_ver_output = self.connect_to_device_real(access, retry, recon, recover)
2024-01-02 00:44:19,917 T0014: INFO  [7] utilities/parallel.py:159 _thread_func retvals[index] = func(*args, **kwargs)
2024-01-02 00:44:19,928 T0014: INFO  [8] spytest/net.py:1584 connect_all_devices rvs, exps = putils.exec_foreach2(faster_init, on_except, self.topo.duts,
2024-01-02 00:44:19,935 T0014: INFO  [9] utilities/parallel.py:219 _thread_func retvals[index] = func(*args, **kwargs)
2024-01-02 00:44:19,940 T0014: INFO  --------------------------------------------
2024-01-02 00:44:19,943 T0014: INFO  ============================================
2024-01-02 00:44:19,943 T0014: WARN  Exception(None:22): Runtime Exception: Connection Unknown Error..
2024-01-02 00:44:19,946 T0014: INFO  connection-Err..
2024-01-02 00:44:39,966 T0014: INFO  Re-Trying 6..
2024-01-02 00:44:39,967 T0014: INFO  TRY Authentication: None:22 admin YourPaSsWoRd
2024-01-02 00:44:39,971 T0014: INFO  ======== Connection: Connection Unknown Error.. ======
2024-01-02 00:44:39,974 T0014: INFO  Traceback (most recent call last):
2024-01-02 00:44:39,975 T0014: INFO    File "/repo/spytest/access/netmiko_connection.py", line 82, in __init__
2024-01-02 00:44:39,979 T0014: INFO      super(NetmikoConnection, self).__init__(**kwargs)
2024-01-02 00:44:39,983 T0014: INFO    File "/usr/local/lib/python3.8/dist-packages/netmiko/base_connection.py", line 244, in __init__
2024-01-02 00:44:39,984 T0014: INFO      raise ValueError("Either ip or host must be set")
2024-01-02 00:44:39,984 T0014: INFO  ValueError: Either ip or host must be se
2024-01-02 00:44:39,985 T0014: INFO  StackTraceCallStack:
2024-01-02 00:44:39,986 T0014: INFO  [0] spytest/access/netmiko_connection.py:104 __init__ self.log_exception(msg, call_stack=True, dump=True)
2024-01-02 00:44:39,990 T0014: INFO  [1] spytest/access/connection.py:48 _DeviceConnection return NetmikoConnection(**kwargs)
2024-01-02 00:44:40,001 T0014: INFO  [2] spytest/access/connection.py:160 DeviceConnection hndl = _DeviceConnection(devname, ip_port, logger, **kwargs)
2024-01-02 00:44:40,010 T0014: INFO  [3] spytest/net.py:694 _do_connect_cinfo net_connect = DeviceConnection(devname=dut_name, logger=self.logger, **cinfo)
2024-01-02 00:44:40,015 T0014: INFO  [4] spytest/net.py:723 _connect_to_device net_connect = self._do_connect_cinfo(cinfo, retry, msgs, devname)
2024-01-02 00:44:40,021 T0014: INFO  [5] spytest/net.py:1118 connect_to_device_real net_connect = self._connect_to_device(connection_param, access, retry=retry)
2024-01-02 00:44:40,027 T0014: INFO  [6] spytest/net.py:1064 connect_to_device show_ver_output = self.connect_to_device_real(access, retry, recon, recover)
2024-01-02 00:44:40,034 T0014: INFO  [7] utilities/parallel.py:159 _thread_func retvals[index] = func(*args, **kwargs)
2024-01-02 00:44:40,041 T0014: INFO  [8] spytest/net.py:1584 connect_all_devices rvs, exps = putils.exec_foreach2(faster_init, on_except, self.topo.duts,
2024-01-02 00:44:40,049 T0014: INFO  [9] utilities/parallel.py:219 _thread_func retvals[index] = func(*args, **kwargs)
2024-01-02 00:44:40,050 T0014: INFO  --------------------------------------------
2024-01-02 00:44:40,056 T0014: INFO  ============================================
2024-01-02 00:44:40,057 T0014: WARN  Exception(None:22): Runtime Exception: Connection Unknown Error..
2024-01-02 00:44:40,057 T0014: INFO  TRY ALT Authentication: None:22 admin broadcom
2024-01-02 00:44:40,064 T0014: INFO  ======== Connection: Connection Unknown Error.. ======
2024-01-02 00:44:40,070 T0014: INFO  Traceback (most recent call last):
2024-01-02 00:44:40,076 T0014: INFO    File "/repo/spytest/access/netmiko_connection.py", line 82, in __init__
2024-01-02 00:44:40,087 T0014: INFO      super(NetmikoConnection, self).__init__(**kwargs)
2024-01-02 00:44:40,094 T0014: INFO    File "/usr/local/lib/python3.8/dist-packages/netmiko/base_connection.py", line 244, in __init__
2024-01-02 00:44:40,099 T0014: INFO      raise ValueError("Either ip or host must be set")
2024-01-02 00:44:40,107 T0014: INFO  ValueError: Either ip or host must be se
2024-01-02 00:44:40,114 T0014: INFO  StackTraceCallStack:
2024-01-02 00:44:40,120 T0014: INFO  [0] spytest/access/netmiko_connection.py:104 __init__ self.log_exception(msg, call_stack=True, dump=True)
2024-01-02 00:44:40,127 T0014: INFO  [1] spytest/access/connection.py:48 _DeviceConnection return NetmikoConnection(**kwargs)
2024-01-02 00:44:40,138 T0014: INFO  [2] spytest/access/connection.py:160 DeviceConnection hndl = _DeviceConnection(devname, ip_port, logger, **kwargs)
2024-01-02 00:44:40,148 T0014: INFO  [3] spytest/net.py:694 _do_connect_cinfo net_connect = DeviceConnection(devname=dut_name, logger=self.logger, **cinfo)
2024-01-02 00:44:40,154 T0014: INFO  [4] spytest/net.py:723 _connect_to_device net_connect = self._do_connect_cinfo(cinfo, retry, msgs, devname)
2024-01-02 00:44:40,161 T0014: INFO  [5] spytest/net.py:1118 connect_to_device_real net_connect = self._connect_to_device(connection_param, access, retry=retry)
2024-01-02 00:44:40,167 T0014: INFO  [6] spytest/net.py:1064 connect_to_device show_ver_output = self.connect_to_device_real(access, retry, recon, recover)
2024-01-02 00:44:40,172 T0014: INFO  [7] utilities/parallel.py:159 _thread_func retvals[index] = func(*args, **kwargs)
2024-01-02 00:44:40,177 T0014: INFO  [8] spytest/net.py:1584 connect_all_devices rvs, exps = putils.exec_foreach2(faster_init, on_except, self.topo.duts,
2024-01-02 00:44:40,181 T0014: INFO  [9] utilities/parallel.py:219 _thread_func retvals[index] = func(*args, **kwargs)
2024-01-02 00:44:40,185 T0014: INFO  --------------------------------------------
2024-01-02 00:44:40,190 T0014: INFO  ============================================
2024-01-02 00:44:40,190 T0014: WARN  Exception(None:22): Runtime Exception: Connection Unknown Error..
2024-01-02 00:44:40,194 T0014: INFO  connection-Err..
2024-01-02 00:45:04,220 T0014: INFO  Re-Trying 7..
2024-01-02 00:45:04,220 T0014: INFO  TRY Authentication: None:22 admin YourPaSsWoRd
2024-01-02 00:45:04,225 T0014: INFO  ======== Connection: Connection Unknown Error.. ======
2024-01-02 00:45:04,232 T0014: INFO  Traceback (most recent call last):
2024-01-02 00:45:04,237 T0014: INFO    File "/repo/spytest/access/netmiko_connection.py", line 82, in __init__
2024-01-02 00:45:04,240 T0014: INFO      super(NetmikoConnection, self).__init__(**kwargs)
2024-01-02 00:45:04,242 T0014: INFO    File "/usr/local/lib/python3.8/dist-packages/netmiko/base_connection.py", line 244, in __init__
2024-01-02 00:45:04,246 T0014: INFO      raise ValueError("Either ip or host must be set")
2024-01-02 00:45:04,250 T0014: INFO  ValueError: Either ip or host must be se
2024-01-02 00:45:04,251 T0014: INFO  StackTraceCallStack:
2024-01-02 00:45:04,254 T0014: INFO  [0] spytest/access/netmiko_connection.py:104 __init__ self.log_exception(msg, call_stack=True, dump=True)
2024-01-02 00:45:04,258 T0014: INFO  [1] spytest/access/connection.py:48 _DeviceConnection return NetmikoConnection(**kwargs)
2024-01-02 00:45:04,264 T0014: INFO  [2] spytest/access/connection.py:160 DeviceConnection hndl = _DeviceConnection(devname, ip_port, logger, **kwargs)
2024-01-02 00:45:04,265 T0014: INFO  [3] spytest/net.py:694 _do_connect_cinfo net_connect = DeviceConnection(devname=dut_name, logger=self.logger, **cinfo)
2024-01-02 00:45:04,268 T0014: INFO  [4] spytest/net.py:723 _connect_to_device net_connect = self._do_connect_cinfo(cinfo, retry, msgs, devname)
2024-01-02 00:45:04,272 T0014: INFO  [5] spytest/net.py:1118 connect_to_device_real net_connect = self._connect_to_device(connection_param, access, retry=retry)
2024-01-02 00:45:04,277 T0014: INFO  [6] spytest/net.py:1064 connect_to_device show_ver_output = self.connect_to_device_real(access, retry, recon, recover)
2024-01-02 00:45:04,281 T0014: INFO  [7] utilities/parallel.py:159 _thread_func retvals[index] = func(*args, **kwargs)
2024-01-02 00:45:04,285 T0014: INFO  [8] spytest/net.py:1584 connect_all_devices rvs, exps = putils.exec_foreach2(faster_init, on_except, self.topo.duts,
2024-01-02 00:45:04,289 T0014: INFO  [9] utilities/parallel.py:219 _thread_func retvals[index] = func(*args, **kwargs)
2024-01-02 00:45:04,290 T0014: INFO  --------------------------------------------
2024-01-02 00:45:04,295 T0014: INFO  ============================================
2024-01-02 00:45:04,295 T0014: WARN  Exception(None:22): Runtime Exception: Connection Unknown Error..
2024-01-02 00:45:04,295 T0014: INFO  TRY ALT Authentication: None:22 admin broadcom
2024-01-02 00:45:04,300 T0014: INFO  ======== Connection: Connection Unknown Error.. ======
2024-01-02 00:45:04,304 T0014: INFO  Traceback (most recent call last):
2024-01-02 00:45:04,307 T0014: INFO    File "/repo/spytest/access/netmiko_connection.py", line 82, in __init__
2024-01-02 00:45:04,310 T0014: INFO      super(NetmikoConnection, self).__init__(**kwargs)
2024-01-02 00:45:04,319 T0014: INFO    File "/usr/local/lib/python3.8/dist-packages/netmiko/base_connection.py", line 244, in __init__
2024-01-02 00:45:04,323 T0014: INFO      raise ValueError("Either ip or host must be set")
2024-01-02 00:45:04,326 T0014: INFO  ValueError: Either ip or host must be se
2024-01-02 00:45:04,328 T0014: INFO  StackTraceCallStack:
2024-01-02 00:45:04,331 T0014: INFO  [0] spytest/access/netmiko_connection.py:104 __init__ self.log_exception(msg, call_stack=True, dump=True)
2024-01-02 00:45:04,335 T0014: INFO  [1] spytest/access/connection.py:48 _DeviceConnection return NetmikoConnection(**kwargs)
2024-01-02 00:45:04,340 T0014: INFO  [2] spytest/access/connection.py:160 DeviceConnection hndl = _DeviceConnection(devname, ip_port, logger, **kwargs)
2024-01-02 00:45:04,344 T0014: INFO  [3] spytest/net.py:694 _do_connect_cinfo net_connect = DeviceConnection(devname=dut_name, logger=self.logger, **cinfo)
2024-01-02 00:45:04,348 T0014: INFO  [4] spytest/net.py:723 _connect_to_device net_connect = self._do_connect_cinfo(cinfo, retry, msgs, devname)
2024-01-02 00:45:04,352 T0014: INFO  [5] spytest/net.py:1118 connect_to_device_real net_connect = self._connect_to_device(connection_param, access, retry=retry)
2024-01-02 00:45:04,356 T0014: INFO  [6] spytest/net.py:1064 connect_to_device show_ver_output = self.connect_to_device_real(access, retry, recon, recover)
2024-01-02 00:45:04,361 T0014: INFO  [7] utilities/parallel.py:159 _thread_func retvals[index] = func(*args, **kwargs)
2024-01-02 00:45:04,365 T0014: INFO  [8] spytest/net.py:1584 connect_all_devices rvs, exps = putils.exec_foreach2(faster_init, on_except, self.topo.duts,
2024-01-02 00:45:04,368 T0014: INFO  [9] utilities/parallel.py:219 _thread_func retvals[index] = func(*args, **kwargs)
2024-01-02 00:45:04,369 T0014: INFO  --------------------------------------------
2024-01-02 00:45:04,371 T0014: INFO  ============================================
2024-01-02 00:45:04,372 T0014: WARN  Exception(None:22): Runtime Exception: Connection Unknown Error..
2024-01-02 00:45:04,374 T0014: INFO  connection-Err..
2024-01-02 00:45:32,400 T0014: INFO  Re-Trying 8..
2024-01-02 00:45:32,401 T0014: INFO  TRY Authentication: None:22 admin YourPaSsWoRd
2024-01-02 00:45:32,404 T0014: INFO  ======== Connection: Connection Unknown Error.. ======
2024-01-02 00:45:32,407 T0014: INFO  Traceback (most recent call last):
2024-01-02 00:45:32,408 T0014: INFO    File "/repo/spytest/access/netmiko_connection.py", line 82, in __init__
2024-01-02 00:45:32,408 T0014: INFO      super(NetmikoConnection, self).__init__(**kwargs)
2024-01-02 00:45:32,409 T0014: INFO    File "/usr/local/lib/python3.8/dist-packages/netmiko/base_connection.py", line 244, in __init__
2024-01-02 00:45:32,412 T0014: INFO      raise ValueError("Either ip or host must be set")
2024-01-02 00:45:32,413 T0014: INFO  ValueError: Either ip or host must be se
2024-01-02 00:45:32,413 T0014: INFO  StackTraceCallStack:
2024-01-02 00:45:32,414 T0014: INFO  [0] spytest/access/netmiko_connection.py:104 __init__ self.log_exception(msg, call_stack=True, dump=True)
2024-01-02 00:45:32,415 T0014: INFO  [1] spytest/access/connection.py:48 _DeviceConnection return NetmikoConnection(**kwargs)
2024-01-02 00:45:32,415 T0014: INFO  [2] spytest/access/connection.py:160 DeviceConnection hndl = _DeviceConnection(devname, ip_port, logger, **kwargs)
2024-01-02 00:45:32,417 T0014: INFO  [3] spytest/net.py:694 _do_connect_cinfo net_connect = DeviceConnection(devname=dut_name, logger=self.logger, **cinfo)
2024-01-02 00:45:32,418 T0014: INFO  [4] spytest/net.py:723 _connect_to_device net_connect = self._do_connect_cinfo(cinfo, retry, msgs, devname)
2024-01-02 00:45:32,419 T0014: INFO  [5] spytest/net.py:1118 connect_to_device_real net_connect = self._connect_to_device(connection_param, access, retry=retry)
2024-01-02 00:45:32,423 T0014: INFO  [6] spytest/net.py:1064 connect_to_device show_ver_output = self.connect_to_device_real(access, retry, recon, recover)
2024-01-02 00:45:32,426 T0014: INFO  [7] utilities/parallel.py:159 _thread_func retvals[index] = func(*args, **kwargs)
2024-01-02 00:45:32,429 T0014: INFO  [8] spytest/net.py:1584 connect_all_devices rvs, exps = putils.exec_foreach2(faster_init, on_except, self.topo.duts,
2024-01-02 00:45:32,432 T0014: INFO  [9] utilities/parallel.py:219 _thread_func retvals[index] = func(*args, **kwargs)
2024-01-02 00:45:32,433 T0014: INFO  --------------------------------------------
2024-01-02 00:45:32,434 T0014: INFO  ============================================
2024-01-02 00:45:32,434 T0014: WARN  Exception(None:22): Runtime Exception: Connection Unknown Error..
2024-01-02 00:45:32,434 T0014: INFO  TRY ALT Authentication: None:22 admin broadcom
2024-01-02 00:45:32,437 T0014: INFO  ======== Connection: Connection Unknown Error.. ======
2024-01-02 00:45:32,440 T0014: INFO  Traceback (most recent call last):
2024-01-02 00:45:32,444 T0014: INFO    File "/repo/spytest/access/netmiko_connection.py", line 82, in __init__
2024-01-02 00:45:32,445 T0014: INFO      super(NetmikoConnection, self).__init__(**kwargs)
2024-01-02 00:45:32,448 T0014: INFO    File "/usr/local/lib/python3.8/dist-packages/netmiko/base_connection.py", line 244, in __init__
2024-01-02 00:45:32,449 T0014: INFO      raise ValueError("Either ip or host must be set")
2024-01-02 00:45:32,450 T0014: INFO  ValueError: Either ip or host must be se
2024-01-02 00:45:32,450 T0014: INFO  StackTraceCallStack:
2024-01-02 00:45:32,454 T0014: INFO  [0] spytest/access/netmiko_connection.py:104 __init__ self.log_exception(msg, call_stack=True, dump=True)
2024-01-02 00:45:32,458 T0014: INFO  [1] spytest/access/connection.py:48 _DeviceConnection return NetmikoConnection(**kwargs)
2024-01-02 00:45:32,462 T0014: INFO  [2] spytest/access/connection.py:160 DeviceConnection hndl = _DeviceConnection(devname, ip_port, logger, **kwargs)
2024-01-02 00:45:32,467 T0014: INFO  [3] spytest/net.py:694 _do_connect_cinfo net_connect = DeviceConnection(devname=dut_name, logger=self.logger, **cinfo)
2024-01-02 00:45:32,470 T0014: INFO  [4] spytest/net.py:723 _connect_to_device net_connect = self._do_connect_cinfo(cinfo, retry, msgs, devname)
2024-01-02 00:45:32,473 T0014: INFO  [5] spytest/net.py:1118 connect_to_device_real net_connect = self._connect_to_device(connection_param, access, retry=retry)
2024-01-02 00:45:32,477 T0014: INFO  [6] spytest/net.py:1064 connect_to_device show_ver_output = self.connect_to_device_real(access, retry, recon, recover)
2024-01-02 00:45:32,482 T0014: INFO  [7] utilities/parallel.py:159 _thread_func retvals[index] = func(*args, **kwargs)
2024-01-02 00:45:32,485 T0014: INFO  [8] spytest/net.py:1584 connect_all_devices rvs, exps = putils.exec_foreach2(faster_init, on_except, self.topo.duts,
2024-01-02 00:45:32,489 T0014: INFO  [9] utilities/parallel.py:219 _thread_func retvals[index] = func(*args, **kwargs)
2024-01-02 00:45:32,492 T0014: INFO  --------------------------------------------
2024-01-02 00:45:32,496 T0014: INFO  ============================================
2024-01-02 00:45:32,497 T0014: WARN  Exception(None:22): Runtime Exception: Connection Unknown Error..
2024-01-02 00:45:32,500 T0014: INFO  connection-Err..
2024-01-02 00:46:04,515 T0014: INFO  Re-Trying 9..
2024-01-02 00:46:04,515 T0014: INFO  TRY Authentication: None:22 admin YourPaSsWoRd
2024-01-02 00:46:04,517 T0014: INFO  ======== Connection: Connection Unknown Error.. ======
2024-01-02 00:46:04,519 T0014: INFO  Traceback (most recent call last):
2024-01-02 00:46:04,523 T0014: INFO    File "/repo/spytest/access/netmiko_connection.py", line 82, in __init__
2024-01-02 00:46:04,527 T0014: INFO      super(NetmikoConnection, self).__init__(**kwargs)
2024-01-02 00:46:04,529 T0014: INFO    File "/usr/local/lib/python3.8/dist-packages/netmiko/base_connection.py", line 244, in __init__
2024-01-02 00:46:04,532 T0014: INFO      raise ValueError("Either ip or host must be set")
2024-01-02 00:46:04,533 T0014: INFO  ValueError: Either ip or host must be se
2024-01-02 00:46:04,535 T0014: INFO  StackTraceCallStack:
2024-01-02 00:46:04,536 T0014: INFO  [0] spytest/access/netmiko_connection.py:104 __init__ self.log_exception(msg, call_stack=True, dump=True)
2024-01-02 00:46:04,537 T0014: INFO  [1] spytest/access/connection.py:48 _DeviceConnection return NetmikoConnection(**kwargs)
2024-01-02 00:46:04,539 T0014: INFO  [2] spytest/access/connection.py:160 DeviceConnection hndl = _DeviceConnection(devname, ip_port, logger, **kwargs)
2024-01-02 00:46:04,540 T0014: INFO  [3] spytest/net.py:694 _do_connect_cinfo net_connect = DeviceConnection(devname=dut_name, logger=self.logger, **cinfo)
2024-01-02 00:46:04,541 T0014: INFO  [4] spytest/net.py:723 _connect_to_device net_connect = self._do_connect_cinfo(cinfo, retry, msgs, devname)
2024-01-02 00:46:04,543 T0014: INFO  [5] spytest/net.py:1118 connect_to_device_real net_connect = self._connect_to_device(connection_param, access, retry=retry)
2024-01-02 00:46:04,544 T0014: INFO  [6] spytest/net.py:1064 connect_to_device show_ver_output = self.connect_to_device_real(access, retry, recon, recover)
2024-01-02 00:46:04,546 T0014: INFO  [7] utilities/parallel.py:159 _thread_func retvals[index] = func(*args, **kwargs)
2024-01-02 00:46:04,547 T0014: INFO  [8] spytest/net.py:1584 connect_all_devices rvs, exps = putils.exec_foreach2(faster_init, on_except, self.topo.duts,
2024-01-02 00:46:04,549 T0014: INFO  [9] utilities/parallel.py:219 _thread_func retvals[index] = func(*args, **kwargs)
2024-01-02 00:46:04,550 T0014: INFO  --------------------------------------------
2024-01-02 00:46:04,552 T0014: INFO  ============================================
2024-01-02 00:46:04,552 T0014: WARN  Exception(None:22): Runtime Exception: Connection Unknown Error..
2024-01-02 00:46:04,552 T0014: INFO  TRY ALT Authentication: None:22 admin broadcom
2024-01-02 00:46:04,554 T0014: INFO  ======== Connection: Connection Unknown Error.. ======
2024-01-02 00:46:04,556 T0014: INFO  Traceback (most recent call last):
2024-01-02 00:46:04,557 T0014: INFO    File "/repo/spytest/access/netmiko_connection.py", line 82, in __init__
2024-01-02 00:46:04,558 T0014: INFO      super(NetmikoConnection, self).__init__(**kwargs)
2024-01-02 00:46:04,562 T0014: INFO    File "/usr/local/lib/python3.8/dist-packages/netmiko/base_connection.py", line 244, in __init__
2024-01-02 00:46:04,566 T0014: INFO      raise ValueError("Either ip or host must be set")
2024-01-02 00:46:04,567 T0014: INFO  ValueError: Either ip or host must be se
2024-01-02 00:46:04,569 T0014: INFO  StackTraceCallStack:
2024-01-02 00:46:04,575 T0014: INFO  [0] spytest/access/netmiko_connection.py:104 __init__ self.log_exception(msg, call_stack=True, dump=True)
2024-01-02 00:46:04,576 T0014: INFO  [1] spytest/access/connection.py:48 _DeviceConnection return NetmikoConnection(**kwargs)
2024-01-02 00:46:04,579 T0014: INFO  [2] spytest/access/connection.py:160 DeviceConnection hndl = _DeviceConnection(devname, ip_port, logger, **kwargs)
2024-01-02 00:46:04,583 T0014: INFO  [3] spytest/net.py:694 _do_connect_cinfo net_connect = DeviceConnection(devname=dut_name, logger=self.logger, **cinfo)
2024-01-02 00:46:04,586 T0014: INFO  [4] spytest/net.py:723 _connect_to_device net_connect = self._do_connect_cinfo(cinfo, retry, msgs, devname)
2024-01-02 00:46:04,593 T0014: INFO  [5] spytest/net.py:1118 connect_to_device_real net_connect = self._connect_to_device(connection_param, access, retry=retry)
2024-01-02 00:46:04,596 T0014: INFO  [6] spytest/net.py:1064 connect_to_device show_ver_output = self.connect_to_device_real(access, retry, recon, recover)
2024-01-02 00:46:04,600 T0014: INFO  [7] utilities/parallel.py:159 _thread_func retvals[index] = func(*args, **kwargs)
2024-01-02 00:46:04,604 T0014: INFO  [8] spytest/net.py:1584 connect_all_devices rvs, exps = putils.exec_foreach2(faster_init, on_except, self.topo.duts,
2024-01-02 00:46:04,608 T0014: INFO  [9] utilities/parallel.py:219 _thread_func retvals[index] = func(*args, **kwargs)
2024-01-02 00:46:04,609 T0014: INFO  --------------------------------------------
2024-01-02 00:46:04,610 T0014: INFO  ============================================
2024-01-02 00:46:04,610 T0014: WARN  Exception(None:22): Runtime Exception: Connection Unknown Error..
2024-01-02 00:46:04,614 T0014: INFO  connection-Err..
2024-01-02 00:46:40,651 T0014: INFO  Re-Trying 10..
2024-01-02 00:46:40,651 T0014: INFO  TRY Authentication: None:22 admin YourPaSsWoRd
2024-01-02 00:46:40,653 T0014: INFO  ======== Connection: Connection Unknown Error.. ======
2024-01-02 00:46:40,655 T0014: INFO  Traceback (most recent call last):
2024-01-02 00:46:40,657 T0014: INFO    File "/repo/spytest/access/netmiko_connection.py", line 82, in __init__
2024-01-02 00:46:40,659 T0014: INFO      super(NetmikoConnection, self).__init__(**kwargs)
2024-01-02 00:46:40,660 T0014: INFO    File "/usr/local/lib/python3.8/dist-packages/netmiko/base_connection.py", line 244, in __init__
2024-01-02 00:46:40,662 T0014: INFO      raise ValueError("Either ip or host must be set")
2024-01-02 00:46:40,663 T0014: INFO  ValueError: Either ip or host must be se
2024-01-02 00:46:40,663 T0014: INFO  StackTraceCallStack:
2024-01-02 00:46:40,664 T0014: INFO  [0] spytest/access/netmiko_connection.py:104 __init__ self.log_exception(msg, call_stack=True, dump=True)
2024-01-02 00:46:40,664 T0014: INFO  [1] spytest/access/connection.py:48 _DeviceConnection return NetmikoConnection(**kwargs)
2024-01-02 00:46:40,665 T0014: INFO  [2] spytest/access/connection.py:160 DeviceConnection hndl = _DeviceConnection(devname, ip_port, logger, **kwargs)
2024-01-02 00:46:40,665 T0014: INFO  [3] spytest/net.py:694 _do_connect_cinfo net_connect = DeviceConnection(devname=dut_name, logger=self.logger, **cinfo)
2024-01-02 00:46:40,666 T0014: INFO  [4] spytest/net.py:723 _connect_to_device net_connect = self._do_connect_cinfo(cinfo, retry, msgs, devname)
2024-01-02 00:46:40,666 T0014: INFO  [5] spytest/net.py:1118 connect_to_device_real net_connect = self._connect_to_device(connection_param, access, retry=retry)
2024-01-02 00:46:40,667 T0014: INFO  [6] spytest/net.py:1064 connect_to_device show_ver_output = self.connect_to_device_real(access, retry, recon, recover)
2024-01-02 00:46:40,667 T0014: INFO  [7] utilities/parallel.py:159 _thread_func retvals[index] = func(*args, **kwargs)
2024-01-02 00:46:40,670 T0014: INFO  [8] spytest/net.py:1584 connect_all_devices rvs, exps = putils.exec_foreach2(faster_init, on_except, self.topo.duts,
2024-01-02 00:46:40,673 T0014: INFO  [9] utilities/parallel.py:219 _thread_func retvals[index] = func(*args, **kwargs)
2024-01-02 00:46:40,675 T0014: INFO  --------------------------------------------
2024-01-02 00:46:40,678 T0014: INFO  ============================================
2024-01-02 00:46:40,678 T0014: WARN  Exception(None:22): Runtime Exception: Connection Unknown Error..
2024-01-02 00:46:40,678 T0014: INFO  TRY ALT Authentication: None:22 admin broadcom
2024-01-02 00:46:40,681 T0014: INFO  ======== Connection: Connection Unknown Error.. ======
2024-01-02 00:46:40,686 T0014: INFO  Traceback (most recent call last):
2024-01-02 00:46:40,689 T0014: INFO    File "/repo/spytest/access/netmiko_connection.py", line 82, in __init__
2024-01-02 00:46:40,693 T0014: INFO      super(NetmikoConnection, self).__init__(**kwargs)
2024-01-02 00:46:40,696 T0014: INFO    File "/usr/local/lib/python3.8/dist-packages/netmiko/base_connection.py", line 244, in __init__
2024-01-02 00:46:40,697 T0014: INFO      raise ValueError("Either ip or host must be set")
2024-01-02 00:46:40,697 T0014: INFO  ValueError: Either ip or host must be se
2024-01-02 00:46:40,698 T0014: INFO  StackTraceCallStack:
2024-01-02 00:46:40,702 T0014: INFO  [0] spytest/access/netmiko_connection.py:104 __init__ self.log_exception(msg, call_stack=True, dump=True)
2024-01-02 00:46:40,705 T0014: INFO  [1] spytest/access/connection.py:48 _DeviceConnection return NetmikoConnection(**kwargs)
2024-01-02 00:46:40,708 T0014: INFO  [2] spytest/access/connection.py:160 DeviceConnection hndl = _DeviceConnection(devname, ip_port, logger, **kwargs)
2024-01-02 00:46:40,711 T0014: INFO  [3] spytest/net.py:694 _do_connect_cinfo net_connect = DeviceConnection(devname=dut_name, logger=self.logger, **cinfo)
2024-01-02 00:46:40,719 T0014: INFO  [4] spytest/net.py:723 _connect_to_device net_connect = self._do_connect_cinfo(cinfo, retry, msgs, devname)
2024-01-02 00:46:40,723 T0014: INFO  [5] spytest/net.py:1118 connect_to_device_real net_connect = self._connect_to_device(connection_param, access, retry=retry)
2024-01-02 00:46:40,727 T0014: INFO  [6] spytest/net.py:1064 connect_to_device show_ver_output = self.connect_to_device_real(access, retry, recon, recover)
2024-01-02 00:46:40,732 T0014: INFO  [7] utilities/parallel.py:159 _thread_func retvals[index] = func(*args, **kwargs)
2024-01-02 00:46:40,738 T0014: INFO  [8] spytest/net.py:1584 connect_all_devices rvs, exps = putils.exec_foreach2(faster_init, on_except, self.topo.duts,
2024-01-02 00:46:40,742 T0014: INFO  [9] utilities/parallel.py:219 _thread_func retvals[index] = func(*args, **kwargs)
2024-01-02 00:46:40,745 T0014: INFO  --------------------------------------------
2024-01-02 00:46:40,746 T0014: INFO  ============================================
2024-01-02 00:46:40,746 T0014: WARN  Exception(None:22): Runtime Exception: Connection Unknown Error..
2024-01-02 00:46:40,750 T0014: INFO  connection-Err..
2024-01-02 00:47:20,778 T0014: INFO  Re-Trying 11..
2024-01-02 00:47:20,779 T0014: INFO  TRY Authentication: None:22 admin YourPaSsWoRd
2024-01-02 00:47:20,780 T0014: INFO  ======== Connection: Connection Unknown Error.. ======
2024-01-02 00:47:20,782 T0014: INFO  Traceback (most recent call last):
2024-01-02 00:47:20,784 T0014: INFO    File "/repo/spytest/access/netmiko_connection.py", line 82, in __init__
2024-01-02 00:47:20,786 T0014: INFO      super(NetmikoConnection, self).__init__(**kwargs)
2024-01-02 00:47:20,787 T0014: INFO    File "/usr/local/lib/python3.8/dist-packages/netmiko/base_connection.py", line 244, in __init__
2024-01-02 00:47:20,787 T0014: INFO      raise ValueError("Either ip or host must be set")
2024-01-02 00:47:20,788 T0014: INFO  ValueError: Either ip or host must be se
2024-01-02 00:47:20,788 T0014: INFO  StackTraceCallStack:
2024-01-02 00:47:20,789 T0014: INFO  [0] spytest/access/netmiko_connection.py:104 __init__ self.log_exception(msg, call_stack=True, dump=True)
2024-01-02 00:47:20,789 T0014: INFO  [1] spytest/access/connection.py:48 _DeviceConnection return NetmikoConnection(**kwargs)
2024-01-02 00:47:20,790 T0014: INFO  [2] spytest/access/connection.py:160 DeviceConnection hndl = _DeviceConnection(devname, ip_port, logger, **kwargs)
2024-01-02 00:47:20,790 T0014: INFO  [3] spytest/net.py:694 _do_connect_cinfo net_connect = DeviceConnection(devname=dut_name, logger=self.logger, **cinfo)
2024-01-02 00:47:20,791 T0014: INFO  [4] spytest/net.py:723 _connect_to_device net_connect = self._do_connect_cinfo(cinfo, retry, msgs, devname)
2024-01-02 00:47:20,791 T0014: INFO  [5] spytest/net.py:1118 connect_to_device_real net_connect = self._connect_to_device(connection_param, access, retry=retry)
2024-01-02 00:47:20,792 T0014: INFO  [6] spytest/net.py:1064 connect_to_device show_ver_output = self.connect_to_device_real(access, retry, recon, recover)
2024-01-02 00:47:20,792 T0014: INFO  [7] utilities/parallel.py:159 _thread_func retvals[index] = func(*args, **kwargs)
2024-01-02 00:47:20,793 T0014: INFO  [8] spytest/net.py:1584 connect_all_devices rvs, exps = putils.exec_foreach2(faster_init, on_except, self.topo.duts,
2024-01-02 00:47:20,793 T0014: INFO  [9] utilities/parallel.py:219 _thread_func retvals[index] = func(*args, **kwargs)
2024-01-02 00:47:20,794 T0014: INFO  --------------------------------------------
2024-01-02 00:47:20,794 T0014: INFO  ============================================
2024-01-02 00:47:20,794 T0014: WARN  Exception(None:22): Runtime Exception: Connection Unknown Error..
2024-01-02 00:47:20,794 T0014: INFO  TRY ALT Authentication: None:22 admin broadcom
2024-01-02 00:47:20,795 T0014: INFO  ======== Connection: Connection Unknown Error.. ======
2024-01-02 00:47:20,795 T0014: INFO  Traceback (most recent call last):
2024-01-02 00:47:20,796 T0014: INFO    File "/repo/spytest/access/netmiko_connection.py", line 82, in __init__
2024-01-02 00:47:20,796 T0014: INFO      super(NetmikoConnection, self).__init__(**kwargs)
2024-01-02 00:47:20,797 T0014: INFO    File "/usr/local/lib/python3.8/dist-packages/netmiko/base_connection.py", line 244, in __init__
2024-01-02 00:47:20,797 T0014: INFO      raise ValueError("Either ip or host must be set")
2024-01-02 00:47:20,798 T0014: INFO  ValueError: Either ip or host must be se
2024-01-02 00:47:20,798 T0014: INFO  StackTraceCallStack:
2024-01-02 00:47:20,799 T0014: INFO  [0] spytest/access/netmiko_connection.py:104 __init__ self.log_exception(msg, call_stack=True, dump=True)
2024-01-02 00:47:20,799 T0014: INFO  [1] spytest/access/connection.py:48 _DeviceConnection return NetmikoConnection(**kwargs)
2024-01-02 00:47:20,800 T0014: INFO  [2] spytest/access/connection.py:160 DeviceConnection hndl = _DeviceConnection(devname, ip_port, logger, **kwargs)
2024-01-02 00:47:20,800 T0014: INFO  [3] spytest/net.py:694 _do_connect_cinfo net_connect = DeviceConnection(devname=dut_name, logger=self.logger, **cinfo)
2024-01-02 00:47:20,801 T0014: INFO  [4] spytest/net.py:723 _connect_to_device net_connect = self._do_connect_cinfo(cinfo, retry, msgs, devname)
2024-01-02 00:47:20,801 T0014: INFO  [5] spytest/net.py:1118 connect_to_device_real net_connect = self._connect_to_device(connection_param, access, retry=retry)
2024-01-02 00:47:20,802 T0014: INFO  [6] spytest/net.py:1064 connect_to_device show_ver_output = self.connect_to_device_real(access, retry, recon, recover)
2024-01-02 00:47:20,802 T0014: INFO  [7] utilities/parallel.py:159 _thread_func retvals[index] = func(*args, **kwargs)
2024-01-02 00:47:20,803 T0014: INFO  [8] spytest/net.py:1584 connect_all_devices rvs, exps = putils.exec_foreach2(faster_init, on_except, self.topo.duts,
2024-01-02 00:47:20,803 T0014: INFO  [9] utilities/parallel.py:219 _thread_func retvals[index] = func(*args, **kwargs)
2024-01-02 00:47:20,804 T0014: INFO  --------------------------------------------
2024-01-02 00:47:20,804 T0014: INFO  ============================================
2024-01-02 00:47:20,804 T0014: WARN  Exception(None:22): Runtime Exception: Connection Unknown Error..
2024-01-02 00:47:20,804 T0014: INFO  connection-Err..
2024-01-02 00:47:20,805 T0014: INFO  Cannot connect: None:22
2024-01-02 00:47:20,809 T0014: INFO  Existing Connections: pconn(fd=14, family=<AddressFamily.AF_INET: 2>, type=<SocketKind.SOCK_STREAM: 1>, laddr=addr(ip='127.0.0.1', port=38470), raddr=addr(ip='127.0.0.1', port=8009), status='ESTABLISHED')
2024-01-02 00:47:20,810 T0014: ERROR Failed to connect to device D3-V3
2024-01-02 00:47:20,899 T0011: ERROR Failed to connect to device
