ordering items took 0:00:01
Tests considered 72 and ignored 317
2024-01-02 00:51:05,224 T0000: NOTICE WORKER = gw7
2024-01-02 00:51:05,225 T0000: NOTICE using testbed file /data/work/logs/docker-master-445589-l3/testbed_1_1_4.yaml
2024-01-02 00:51:05,225 T0000: NOTICE Execution Start Time: 2024-01-02 00:51:05.223512
2024-01-02 00:51:05,225 T0000: NOTICE LOGS PATH: /data/work/logs/docker-master-445589-l3/gw7
2024-01-02 00:51:05,696 T0000: NOTICE VERSION: UNKNOWN UNKNOWN UNKNOWN
2024-01-02 00:51:05,697 T0000: NOTICE HOST: sonicmgmtmaster MEM: 376gb 43.0%
2024-01-02 00:51:05,697 T0000: NOTICE ROOT_PATH: /repo
2024-01-02 00:51:05,697 T0000: NOTICE Python: 3.8.10
2024-01-02 00:51:05,697 T0000: NOTICE Topology unknown: D1T1:4
2024-01-02 00:51:05,697 T0000: DEBUG 
SUITE ARGS: --load-image none --max-time module 9000 --max-time function 5400 --max-time session 3600 --logs-level=debug --topology-check=function --env SPYTEST_TESTBED_IGNORE_CONSTRAINTS TG,TGCARD,TGSPEED,CHIP,MODEL --noop --env SPYTEST_RESET_CONSOLES 0 --noop --env SPYTEST_ONREBOOT_RENEW_MGMT_IP 1 --noop --env SPYTEST_RECOVERY_CR_PER_CMD_POST_OP 1 --noop --env SPYTEST_BATCH_POLL_STATUS_TIME 300 --noop --env SPYTEST_BATCH_DEAD_NODE_MAX_TIME 7200 --noop --breakout-mode none --env SPYTEST_SHUTDOWN_FREE_PORTS 1 --env SPYTEST_HOOKS_BREAKOUT_UITYPE click --env SPYTEST_ONREBOOT_RENEW_MGMT_IP 0 --env SPYTEST_VERIFY_CSV_MIN_TOPOLOGY 1 --env SPYTEST_CMD_FAIL_RESULT_SUPPORT 0 --env SPYTEST_ROUTING_CONFIG_MODE split --env SPYTEST_CLEAR_DEVICE_METADATA_BGP_ASN 1 --env SPYTEST_TEXTFSM_USE_BUNDLED_PARSER 1 --feature-group master --ifname-type native --feature-disable bcmcmd --feature-disable warm-reboot --save config-db module --tclist-csv TestBGPConfed.test_confed_route_distribution_with_rmap,TestBGPConfed.test_ipv6_confed_route_distribution,TestBGPConfed.test_ipv6_confed_with_rr,TestBGPIPvxRouteAdvertisementFilter.test_bgp_ebgp4_nbr_authentication,TestBGPIPvxRouteAdvertisementFilter.test_bgp_ebgp4_nbr_update_source,TestBGPIPvxRouteAdvertisementFilter.test_bgp_route_map_with_community,TestBGPIPvxRouteAdvertisementFilter.test_default_originate_ipv4,TestBGPIPvxRouteAdvertisementFilter.test_distribute_list_in_ipv4,TestBGPIPvxRouteAdvertisementFilter.test_distribute_list_in_ipv6,TestBGPIPvxRouteAdvertisementFilter.test_filter_list_in_ipv4,TestBGPIPvxRouteAdvertisementFilter.test_filter_list_in_ipv6,TestBGPIPvxRouteAdvertisementFilter.test_filter_list_out_ipv6,TestBGPIPvxRouteAdvertisementFilter.test_prefix_list_out_ipv4,TestBGPIPvxRouteAdvertisementFilter.test_prefix_list_out_ipv6,TestBGPIPvxRouteAdvertisementFilter.test_route_aggregate_ipv6,TestBGPIPvxRouteAdvertisementFilter.test_route_map_in_ipv4,TestBGPIPvxRouteAdvertisementFilter.test_route_map_in_ipv6,TestBGPIPvxRouteAdvertisementFilter.test_static_blackhole_rt_redistribute_with_routemap_ipv6,TestBGPL3Lag.test_ft_bgp_l3lag_peer_traffic_check,TestBGPRif.test_bgp_route_aggregation_4byteASN,TestBGPRif.test_ft_bgp_clear,TestBGPRif.test_ft_bgp_graceful_restart_and_aware_routers,TestBGPRif.test_ft_bgp_peer_traffic_check,TestBGPRif.test_ft_bgp_rmap,TestBGPRif.test_ft_bgp_v4_dyn_nbr,TestBGPRif.test_ft_bgp_v6_dyn_nbr,TestBGPRif.test_ft_bgp_v6_link_local_bgp,TestBGPRrTraffic.test_ft_bgp6_rr_traffic_check,TestBGPVeLag.test_ft_bgp_clear,TestBGPVeLag.test_ft_bgp_peer_traffic_check,test_VrfFun001_06,test_VrfFun_05_50,test_VrfFun_10_12_14,test_VrfFun_20_24_25_32_33_44_45,test_VrfFun_26_27,test_cli_validation_bgp_router_config,test_cli_validation_ip_address,test_ft_arp_dynamic_renew_traffic_test,test_ft_bgp_ebgp_community_map,test_ft_bgp_ibgp_RR_Loop,test_ft_ip6_static_route_traffic_forward_blackhole,test_ft_ip_static_ip_on_mgmt_intrf,test_ft_ip_static_route_traffic_forward,test_ft_ip_v4_v6_L2_L3_translation,test_ft_ipv6_neighbor_entry,test_ft_l3_performance_enhancements_v4_route_intstall_withdraw,test_ft_nat_docker_restart,test_ft_ping_v4_v6_after_ip_change_pc,test_ft_ping_v4_v6_vlan,test_ft_qos_config_mgmt_verifying_config_with_save_reboot,test_ft_sflow_max_sflow_collector_config,test_ft_sflow_sampling_v6_sFlow_collector,test_ft_system_config_mgmt_verifying_config_with_save_reboot_sflow,test_ft_verify_interfaces_order,test_l2_to_l3_port,test_l3_v4_route_po_1,test_vrf_bgp,test_vrf_reload,test_vrf_route_leak,test_vrf_scale,TestBGPRif.test_ft_bgp_ipv4_no_route_aggregation_for_exact_prefix_match,TestBGPRif.test_ft_bgp_ipv4_route_aggregation_atomic_aggregate_without_as_set,TestBGPRif.test_ft_bgp_ipv6_route_aggregation_with_as_set,TestBGPRif.test_ft_bgp_v4_max_dyn_nbr,TestBGPIPvxRouteAdvertisementFilter.test_redistribute_connected_ipv4,TestBGPIPvxRouteAdvertisementFilter.test_redistribute_static_ipv4,TestBGPIPvxRouteAdvertisementFilter.test_redistribute_connected_ipv6,TestBGPIPvxRouteAdvertisementFilter.test_redistribute_static_ipv6,TestBGPIPvxRouteAdvertisementFilter.test_default_originate_ipv6,test_spytest_infra_first,test_spytest_infra_second,test_spytest_infra_last --noop

2024-01-02 00:51:05,697 T0000: NOTICE ARGS: --logs-level debug --results-prefix=results --get-tech-support none --fetch-core-files none --syslog-check none --save config-db module --topology-check module --logs-path logs/2024-01-02-00-43-25 --continue-on-collection-errors --max-time session 0 --max-time module 0 --max-time function 0 --noop --tryssh=0 --testbed-file testbed.yaml --env SPYTEST_RPS_DEBUG 0 --tclist-bucket 1,2,4 --test-suite community-vs-l3 --email rama.kristipati@broadcom.com --env SPYTEST_SCAPY_DBG_LVL 2 --noop --env SPYTEST_EMAIL_FROM SPyTest-VSNet@broadcom.com --noop --logs-path logs/docker-master-445589-l3 --env SPYTEST_EMAIL_BODY_PREFIX http://10.193.81.56:8080/sonic_mgmt_master/work/logs/docker-master-445589-l3/dashboard.html --email-subject-nargs VSNet-sonic_mgmt_master-DOCKER-L3-{{bldver}} : {{passrate}}: {{pass_cnt}}/{{executed}} docker-master-445589-l3 --noop --feature-group master
2024-01-02 00:51:06,278 T0000: DEBUG 'errors' not set in properties for V4 assuming 'default'
2024-01-02 00:51:06,279 T0000: INFO  TGEN-IP 127.0.0.1
2024-01-02 00:51:06,279 T0000: WARN  Registering Topology
2024-01-02 00:51:06,293 T0000: INFO  Connecting all devices
2024-01-02 00:51:06,297 T0000: INFO  Loading scapy:1.0 127.0.0.1 Ports: ['1/13', '1/14', '1/15', '1/16'] skip: False
2024-01-02 00:51:06,488 T0002: INFO  [D1-V4] Connecting to device (V4): sonic_ssh: None:22 ..
2024-01-02 00:51:06,488 T0002: INFO  [D1-V4] TRY Authentication: None:22 admin YourPaSsWoRd
2024-01-02 00:51:06,489 T0002: INFO  [D1-V4] ======== Connection: Connection Unknown Error.. ======
2024-01-02 00:51:06,490 T0002: INFO  [D1-V4] Traceback (most recent call last):
2024-01-02 00:51:06,491 T0002: INFO  [D1-V4]   File "/repo/spytest/access/netmiko_connection.py", line 82, in __init__
2024-01-02 00:51:06,491 T0002: INFO  [D1-V4]     super(NetmikoConnection, self).__init__(**kwargs)
2024-01-02 00:51:06,492 T0002: INFO  [D1-V4]   File "/usr/local/lib/python3.8/dist-packages/netmiko/base_connection.py", line 244, in __init__
2024-01-02 00:51:06,493 T0002: INFO  [D1-V4]     raise ValueError("Either ip or host must be set")
2024-01-02 00:51:06,493 T0002: INFO  [D1-V4] ValueError: Either ip or host must be se
2024-01-02 00:51:06,494 T0002: INFO  [D1-V4] StackTraceCallStack:
2024-01-02 00:51:06,494 T0002: INFO  [D1-V4] [0] spytest/access/netmiko_connection.py:104 __init__ self.log_exception(msg, call_stack=True, dump=True)
2024-01-02 00:51:06,495 T0002: INFO  [D1-V4] [1] spytest/access/connection.py:48 _DeviceConnection return NetmikoConnection(**kwargs)
2024-01-02 00:51:06,496 T0002: INFO  [D1-V4] [2] spytest/access/connection.py:160 DeviceConnection hndl = _DeviceConnection(devname, ip_port, logger, **kwargs)
2024-01-02 00:51:06,496 T0002: INFO  [D1-V4] [3] spytest/net.py:694 _do_connect_cinfo net_connect = DeviceConnection(devname=dut_name, logger=self.logger, **cinfo)
2024-01-02 00:51:06,497 T0002: INFO  [D1-V4] [4] spytest/net.py:723 _connect_to_device net_connect = self._do_connect_cinfo(cinfo, retry, msgs, devname)
2024-01-02 00:51:06,497 T0002: INFO  [D1-V4] [5] spytest/net.py:1118 connect_to_device_real net_connect = self._connect_to_device(connection_param, access, retry=retry)
2024-01-02 00:51:06,498 T0002: INFO  [D1-V4] [6] spytest/net.py:1064 connect_to_device show_ver_output = self.connect_to_device_real(access, retry, recon, recover)
2024-01-02 00:51:06,499 T0002: INFO  [D1-V4] [7] utilities/parallel.py:159 _thread_func retvals[index] = func(*args, **kwargs)
2024-01-02 00:51:06,499 T0002: INFO  [D1-V4] [8] utilities/parallel.py:182 exec_foreach2 _thread_func(*args, **kwargs)
2024-01-02 00:51:06,500 T0002: INFO  [D1-V4] [9] spytest/net.py:1584 connect_all_devices rvs, exps = putils.exec_foreach2(faster_init, on_except, self.topo.duts,
2024-01-02 00:51:06,500 T0002: INFO  [D1-V4] [10] utilities/parallel.py:219 _thread_func retvals[index] = func(*args, **kwargs)
2024-01-02 00:51:06,501 T0002: INFO  [D1-V4] --------------------------------------------
2024-01-02 00:51:06,501 T0002: INFO  [D1-V4] ============================================
2024-01-02 00:51:06,502 T0002: WARN  [D1-V4] Exception(None:22): Runtime Exception: Connection Unknown Error..
2024-01-02 00:51:06,502 T0002: INFO  [D1-V4] TRY ALT Authentication: None:22 admin broadcom
2024-01-02 00:51:06,502 T0002: INFO  [D1-V4] ======== Connection: Connection Unknown Error.. ======
2024-01-02 00:51:06,503 T0002: INFO  [D1-V4] Traceback (most recent call last):
2024-01-02 00:51:06,504 T0002: INFO  [D1-V4]   File "/repo/spytest/access/netmiko_connection.py", line 82, in __init__
2024-01-02 00:51:06,504 T0002: INFO  [D1-V4]     super(NetmikoConnection, self).__init__(**kwargs)
2024-01-02 00:51:06,505 T0002: INFO  [D1-V4]   File "/usr/local/lib/python3.8/dist-packages/netmiko/base_connection.py", line 244, in __init__
2024-01-02 00:51:06,505 T0002: INFO  [D1-V4]     raise ValueError("Either ip or host must be set")
2024-01-02 00:51:06,506 T0002: INFO  [D1-V4] ValueError: Either ip or host must be se
2024-01-02 00:51:06,507 T0002: INFO  [D1-V4] StackTraceCallStack:
2024-01-02 00:51:06,507 T0002: INFO  [D1-V4] [0] spytest/access/netmiko_connection.py:104 __init__ self.log_exception(msg, call_stack=True, dump=True)
2024-01-02 00:51:06,508 T0002: INFO  [D1-V4] [1] spytest/access/connection.py:48 _DeviceConnection return NetmikoConnection(**kwargs)
2024-01-02 00:51:06,508 T0002: INFO  [D1-V4] [2] spytest/access/connection.py:160 DeviceConnection hndl = _DeviceConnection(devname, ip_port, logger, **kwargs)
2024-01-02 00:51:06,509 T0002: INFO  [D1-V4] [3] spytest/net.py:694 _do_connect_cinfo net_connect = DeviceConnection(devname=dut_name, logger=self.logger, **cinfo)
2024-01-02 00:51:06,510 T0002: INFO  [D1-V4] [4] spytest/net.py:723 _connect_to_device net_connect = self._do_connect_cinfo(cinfo, retry, msgs, devname)
2024-01-02 00:51:06,510 T0002: INFO  [D1-V4] [5] spytest/net.py:1118 connect_to_device_real net_connect = self._connect_to_device(connection_param, access, retry=retry)
2024-01-02 00:51:06,511 T0002: INFO  [D1-V4] [6] spytest/net.py:1064 connect_to_device show_ver_output = self.connect_to_device_real(access, retry, recon, recover)
2024-01-02 00:51:06,511 T0002: INFO  [D1-V4] [7] utilities/parallel.py:159 _thread_func retvals[index] = func(*args, **kwargs)
2024-01-02 00:51:06,512 T0002: INFO  [D1-V4] [8] utilities/parallel.py:182 exec_foreach2 _thread_func(*args, **kwargs)
2024-01-02 00:51:06,513 T0002: INFO  [D1-V4] [9] spytest/net.py:1584 connect_all_devices rvs, exps = putils.exec_foreach2(faster_init, on_except, self.topo.duts,
2024-01-02 00:51:06,513 T0002: INFO  [D1-V4] [10] utilities/parallel.py:219 _thread_func retvals[index] = func(*args, **kwargs)
2024-01-02 00:51:06,514 T0002: INFO  [D1-V4] --------------------------------------------
2024-01-02 00:51:06,514 T0002: INFO  [D1-V4] ============================================
2024-01-02 00:51:06,514 T0002: WARN  [D1-V4] Exception(None:22): Runtime Exception: Connection Unknown Error..
2024-01-02 00:51:06,515 T0002: INFO  [D1-V4] connection-Err..
2024-01-02 00:51:07,323 T0000: INFO  TG Scapy Init
2024-01-02 00:51:07,323 T0000: INFO  TG Base Init skip: False
2024-01-02 00:51:07,334 T0000: INFO  TG Scapy Connect 127.0.0.1:8009
2024-01-02 00:51:07,477 T0000: INFO  Server Logs Path /data/work/scapy-tgen/logs/current/inst-2024_01_02_00_51_07_361787/gw7/default.log
2024-01-02 00:51:07,493 T0000: DEBUG REQ: tg_connect(port_list=['1/13', '1/14', '1/15', '1/16'])
2024-01-02 00:51:10,521 T0002: INFO  [D1-V4] Re-Trying 2..
2024-01-02 00:51:10,521 T0002: INFO  [D1-V4] TRY Authentication: None:22 admin YourPaSsWoRd
2024-01-02 00:51:10,523 T0002: INFO  [D1-V4] ======== Connection: Connection Unknown Error.. ======
2024-01-02 00:51:10,526 T0002: INFO  [D1-V4] Traceback (most recent call last):
2024-01-02 00:51:10,528 T0002: INFO  [D1-V4]   File "/repo/spytest/access/netmiko_connection.py", line 82, in __init__
2024-01-02 00:51:10,530 T0002: INFO  [D1-V4]     super(NetmikoConnection, self).__init__(**kwargs)
2024-01-02 00:51:10,531 T0002: INFO  [D1-V4]   File "/usr/local/lib/python3.8/dist-packages/netmiko/base_connection.py", line 244, in __init__
2024-01-02 00:51:10,532 T0002: INFO  [D1-V4]     raise ValueError("Either ip or host must be set")
2024-01-02 00:51:10,532 T0002: INFO  [D1-V4] ValueError: Either ip or host must be se
2024-01-02 00:51:10,533 T0002: INFO  [D1-V4] StackTraceCallStack:
2024-01-02 00:51:10,533 T0002: INFO  [D1-V4] [0] spytest/access/netmiko_connection.py:104 __init__ self.log_exception(msg, call_stack=True, dump=True)
2024-01-02 00:51:10,534 T0002: INFO  [D1-V4] [1] spytest/access/connection.py:48 _DeviceConnection return NetmikoConnection(**kwargs)
2024-01-02 00:51:10,534 T0002: INFO  [D1-V4] [2] spytest/access/connection.py:160 DeviceConnection hndl = _DeviceConnection(devname, ip_port, logger, **kwargs)
2024-01-02 00:51:10,535 T0002: INFO  [D1-V4] [3] spytest/net.py:694 _do_connect_cinfo net_connect = DeviceConnection(devname=dut_name, logger=self.logger, **cinfo)
2024-01-02 00:51:10,535 T0002: INFO  [D1-V4] [4] spytest/net.py:723 _connect_to_device net_connect = self._do_connect_cinfo(cinfo, retry, msgs, devname)
2024-01-02 00:51:10,536 T0002: INFO  [D1-V4] [5] spytest/net.py:1118 connect_to_device_real net_connect = self._connect_to_device(connection_param, access, retry=retry)
2024-01-02 00:51:10,537 T0002: INFO  [D1-V4] [6] spytest/net.py:1064 connect_to_device show_ver_output = self.connect_to_device_real(access, retry, recon, recover)
2024-01-02 00:51:10,537 T0002: INFO  [D1-V4] [7] utilities/parallel.py:159 _thread_func retvals[index] = func(*args, **kwargs)
2024-01-02 00:51:10,538 T0002: INFO  [D1-V4] [8] utilities/parallel.py:182 exec_foreach2 _thread_func(*args, **kwargs)
2024-01-02 00:51:10,538 T0002: INFO  [D1-V4] [9] spytest/net.py:1584 connect_all_devices rvs, exps = putils.exec_foreach2(faster_init, on_except, self.topo.duts,
2024-01-02 00:51:10,539 T0002: INFO  [D1-V4] [10] utilities/parallel.py:219 _thread_func retvals[index] = func(*args, **kwargs)
2024-01-02 00:51:10,539 T0002: INFO  [D1-V4] --------------------------------------------
2024-01-02 00:51:10,540 T0002: INFO  [D1-V4] ============================================
2024-01-02 00:51:10,540 T0002: WARN  [D1-V4] Exception(None:22): Runtime Exception: Connection Unknown Error..
2024-01-02 00:51:10,540 T0002: INFO  [D1-V4] TRY ALT Authentication: None:22 admin broadcom
2024-01-02 00:51:10,541 T0002: INFO  [D1-V4] ======== Connection: Connection Unknown Error.. ======
2024-01-02 00:51:10,541 T0002: INFO  [D1-V4] Traceback (most recent call last):
2024-01-02 00:51:10,542 T0002: INFO  [D1-V4]   File "/repo/spytest/access/netmiko_connection.py", line 82, in __init__
2024-01-02 00:51:10,542 T0002: INFO  [D1-V4]     super(NetmikoConnection, self).__init__(**kwargs)
2024-01-02 00:51:10,543 T0002: INFO  [D1-V4]   File "/usr/local/lib/python3.8/dist-packages/netmiko/base_connection.py", line 244, in __init__
2024-01-02 00:51:10,544 T0002: INFO  [D1-V4]     raise ValueError("Either ip or host must be set")
2024-01-02 00:51:10,544 T0002: INFO  [D1-V4] ValueError: Either ip or host must be se
2024-01-02 00:51:10,545 T0002: INFO  [D1-V4] StackTraceCallStack:
2024-01-02 00:51:10,545 T0002: INFO  [D1-V4] [0] spytest/access/netmiko_connection.py:104 __init__ self.log_exception(msg, call_stack=True, dump=True)
2024-01-02 00:51:10,546 T0002: INFO  [D1-V4] [1] spytest/access/connection.py:48 _DeviceConnection return NetmikoConnection(**kwargs)
2024-01-02 00:51:10,546 T0002: INFO  [D1-V4] [2] spytest/access/connection.py:160 DeviceConnection hndl = _DeviceConnection(devname, ip_port, logger, **kwargs)
2024-01-02 00:51:10,547 T0002: INFO  [D1-V4] [3] spytest/net.py:694 _do_connect_cinfo net_connect = DeviceConnection(devname=dut_name, logger=self.logger, **cinfo)
2024-01-02 00:51:10,547 T0002: INFO  [D1-V4] [4] spytest/net.py:723 _connect_to_device net_connect = self._do_connect_cinfo(cinfo, retry, msgs, devname)
2024-01-02 00:51:10,548 T0002: INFO  [D1-V4] [5] spytest/net.py:1118 connect_to_device_real net_connect = self._connect_to_device(connection_param, access, retry=retry)
2024-01-02 00:51:10,548 T0002: INFO  [D1-V4] [6] spytest/net.py:1064 connect_to_device show_ver_output = self.connect_to_device_real(access, retry, recon, recover)
2024-01-02 00:51:10,549 T0002: INFO  [D1-V4] [7] utilities/parallel.py:159 _thread_func retvals[index] = func(*args, **kwargs)
2024-01-02 00:51:10,549 T0002: INFO  [D1-V4] [8] utilities/parallel.py:182 exec_foreach2 _thread_func(*args, **kwargs)
2024-01-02 00:51:10,550 T0002: INFO  [D1-V4] [9] spytest/net.py:1584 connect_all_devices rvs, exps = putils.exec_foreach2(faster_init, on_except, self.topo.duts,
2024-01-02 00:51:10,551 T0002: INFO  [D1-V4] [10] utilities/parallel.py:219 _thread_func retvals[index] = func(*args, **kwargs)
2024-01-02 00:51:10,551 T0002: INFO  [D1-V4] --------------------------------------------
2024-01-02 00:51:10,552 T0002: INFO  [D1-V4] ============================================
2024-01-02 00:51:10,552 T0002: WARN  [D1-V4] Exception(None:22): Runtime Exception: Connection Unknown Error..
2024-01-02 00:51:10,552 T0002: INFO  [D1-V4] connection-Err..
2024-01-02 00:51:14,522 T0000: DEBUG RESP: tg_connect {"port_handle": {"1/13": "port-13", "1/14": "port-14", "1/15": "port-15", "1/16": "port-16"}, "status": 1}
2024-01-02 00:51:14,533 T0000: INFO  TG Connection: Success
2024-01-02 00:51:14,533 T0000: INFO  TG Connect...done
2024-01-02 00:51:18,562 T0002: INFO  [D1-V4] Re-Trying 3..
2024-01-02 00:51:18,562 T0002: INFO  [D1-V4] TRY Authentication: None:22 admin YourPaSsWoRd
2024-01-02 00:51:18,564 T0002: INFO  [D1-V4] ======== Connection: Connection Unknown Error.. ======
2024-01-02 00:51:18,567 T0002: INFO  [D1-V4] Traceback (most recent call last):
2024-01-02 00:51:18,569 T0002: INFO  [D1-V4]   File "/repo/spytest/access/netmiko_connection.py", line 82, in __init__
2024-01-02 00:51:18,570 T0002: INFO  [D1-V4]     super(NetmikoConnection, self).__init__(**kwargs)
2024-01-02 00:51:18,572 T0002: INFO  [D1-V4]   File "/usr/local/lib/python3.8/dist-packages/netmiko/base_connection.py", line 244, in __init__
2024-01-02 00:51:18,574 T0002: INFO  [D1-V4]     raise ValueError("Either ip or host must be set")
2024-01-02 00:51:18,575 T0002: INFO  [D1-V4] ValueError: Either ip or host must be se
2024-01-02 00:51:18,575 T0002: INFO  [D1-V4] StackTraceCallStack:
2024-01-02 00:51:18,576 T0002: INFO  [D1-V4] [0] spytest/access/netmiko_connection.py:104 __init__ self.log_exception(msg, call_stack=True, dump=True)
2024-01-02 00:51:18,576 T0002: INFO  [D1-V4] [1] spytest/access/connection.py:48 _DeviceConnection return NetmikoConnection(**kwargs)
2024-01-02 00:51:18,577 T0002: INFO  [D1-V4] [2] spytest/access/connection.py:160 DeviceConnection hndl = _DeviceConnection(devname, ip_port, logger, **kwargs)
2024-01-02 00:51:18,577 T0002: INFO  [D1-V4] [3] spytest/net.py:694 _do_connect_cinfo net_connect = DeviceConnection(devname=dut_name, logger=self.logger, **cinfo)
2024-01-02 00:51:18,578 T0002: INFO  [D1-V4] [4] spytest/net.py:723 _connect_to_device net_connect = self._do_connect_cinfo(cinfo, retry, msgs, devname)
2024-01-02 00:51:18,578 T0002: INFO  [D1-V4] [5] spytest/net.py:1118 connect_to_device_real net_connect = self._connect_to_device(connection_param, access, retry=retry)
2024-01-02 00:51:18,579 T0002: INFO  [D1-V4] [6] spytest/net.py:1064 connect_to_device show_ver_output = self.connect_to_device_real(access, retry, recon, recover)
2024-01-02 00:51:18,579 T0002: INFO  [D1-V4] [7] utilities/parallel.py:159 _thread_func retvals[index] = func(*args, **kwargs)
2024-01-02 00:51:18,580 T0002: INFO  [D1-V4] [8] utilities/parallel.py:182 exec_foreach2 _thread_func(*args, **kwargs)
2024-01-02 00:51:18,580 T0002: INFO  [D1-V4] [9] spytest/net.py:1584 connect_all_devices rvs, exps = putils.exec_foreach2(faster_init, on_except, self.topo.duts,
2024-01-02 00:51:18,581 T0002: INFO  [D1-V4] [10] utilities/parallel.py:219 _thread_func retvals[index] = func(*args, **kwargs)
2024-01-02 00:51:18,581 T0002: INFO  [D1-V4] --------------------------------------------
2024-01-02 00:51:18,582 T0002: INFO  [D1-V4] ============================================
2024-01-02 00:51:18,582 T0002: WARN  [D1-V4] Exception(None:22): Runtime Exception: Connection Unknown Error..
2024-01-02 00:51:18,582 T0002: INFO  [D1-V4] TRY ALT Authentication: None:22 admin broadcom
2024-01-02 00:51:18,583 T0002: INFO  [D1-V4] ======== Connection: Connection Unknown Error.. ======
2024-01-02 00:51:18,583 T0002: INFO  [D1-V4] Traceback (most recent call last):
2024-01-02 00:51:18,584 T0002: INFO  [D1-V4]   File "/repo/spytest/access/netmiko_connection.py", line 82, in __init__
2024-01-02 00:51:18,584 T0002: INFO  [D1-V4]     super(NetmikoConnection, self).__init__(**kwargs)
2024-01-02 00:51:18,585 T0002: INFO  [D1-V4]   File "/usr/local/lib/python3.8/dist-packages/netmiko/base_connection.py", line 244, in __init__
2024-01-02 00:51:18,585 T0002: INFO  [D1-V4]     raise ValueError("Either ip or host must be set")
2024-01-02 00:51:18,586 T0002: INFO  [D1-V4] ValueError: Either ip or host must be se
2024-01-02 00:51:18,586 T0002: INFO  [D1-V4] StackTraceCallStack:
2024-01-02 00:51:18,587 T0002: INFO  [D1-V4] [0] spytest/access/netmiko_connection.py:104 __init__ self.log_exception(msg, call_stack=True, dump=True)
2024-01-02 00:51:18,587 T0002: INFO  [D1-V4] [1] spytest/access/connection.py:48 _DeviceConnection return NetmikoConnection(**kwargs)
2024-01-02 00:51:18,588 T0002: INFO  [D1-V4] [2] spytest/access/connection.py:160 DeviceConnection hndl = _DeviceConnection(devname, ip_port, logger, **kwargs)
2024-01-02 00:51:18,588 T0002: INFO  [D1-V4] [3] spytest/net.py:694 _do_connect_cinfo net_connect = DeviceConnection(devname=dut_name, logger=self.logger, **cinfo)
2024-01-02 00:51:18,589 T0002: INFO  [D1-V4] [4] spytest/net.py:723 _connect_to_device net_connect = self._do_connect_cinfo(cinfo, retry, msgs, devname)
2024-01-02 00:51:18,589 T0002: INFO  [D1-V4] [5] spytest/net.py:1118 connect_to_device_real net_connect = self._connect_to_device(connection_param, access, retry=retry)
2024-01-02 00:51:18,590 T0002: INFO  [D1-V4] [6] spytest/net.py:1064 connect_to_device show_ver_output = self.connect_to_device_real(access, retry, recon, recover)
2024-01-02 00:51:18,591 T0002: INFO  [D1-V4] [7] utilities/parallel.py:159 _thread_func retvals[index] = func(*args, **kwargs)
2024-01-02 00:51:18,591 T0002: INFO  [D1-V4] [8] utilities/parallel.py:182 exec_foreach2 _thread_func(*args, **kwargs)
2024-01-02 00:51:18,592 T0002: INFO  [D1-V4] [9] spytest/net.py:1584 connect_all_devices rvs, exps = putils.exec_foreach2(faster_init, on_except, self.topo.duts,
2024-01-02 00:51:18,592 T0002: INFO  [D1-V4] [10] utilities/parallel.py:219 _thread_func retvals[index] = func(*args, **kwargs)
2024-01-02 00:51:18,593 T0002: INFO  [D1-V4] --------------------------------------------
2024-01-02 00:51:18,594 T0002: INFO  [D1-V4] ============================================
2024-01-02 00:51:18,594 T0002: WARN  [D1-V4] Exception(None:22): Runtime Exception: Connection Unknown Error..
2024-01-02 00:51:18,594 T0002: INFO  [D1-V4] connection-Err..
2024-01-02 00:51:30,608 T0002: INFO  [D1-V4] Re-Trying 4..
2024-01-02 00:51:30,608 T0002: INFO  [D1-V4] TRY Authentication: None:22 admin YourPaSsWoRd
2024-01-02 00:51:30,610 T0002: INFO  [D1-V4] ======== Connection: Connection Unknown Error.. ======
2024-01-02 00:51:30,613 T0002: INFO  [D1-V4] Traceback (most recent call last):
2024-01-02 00:51:30,615 T0002: INFO  [D1-V4]   File "/repo/spytest/access/netmiko_connection.py", line 82, in __init__
2024-01-02 00:51:30,617 T0002: INFO  [D1-V4]     super(NetmikoConnection, self).__init__(**kwargs)
2024-01-02 00:51:30,618 T0002: INFO  [D1-V4]   File "/usr/local/lib/python3.8/dist-packages/netmiko/base_connection.py", line 244, in __init__
2024-01-02 00:51:30,619 T0002: INFO  [D1-V4]     raise ValueError("Either ip or host must be set")
2024-01-02 00:51:30,620 T0002: INFO  [D1-V4] ValueError: Either ip or host must be se
2024-01-02 00:51:30,621 T0002: INFO  [D1-V4] StackTraceCallStack:
2024-01-02 00:51:30,622 T0002: INFO  [D1-V4] [0] spytest/access/netmiko_connection.py:104 __init__ self.log_exception(msg, call_stack=True, dump=True)
2024-01-02 00:51:30,623 T0002: INFO  [D1-V4] [1] spytest/access/connection.py:48 _DeviceConnection return NetmikoConnection(**kwargs)
2024-01-02 00:51:30,623 T0002: INFO  [D1-V4] [2] spytest/access/connection.py:160 DeviceConnection hndl = _DeviceConnection(devname, ip_port, logger, **kwargs)
2024-01-02 00:51:30,624 T0002: INFO  [D1-V4] [3] spytest/net.py:694 _do_connect_cinfo net_connect = DeviceConnection(devname=dut_name, logger=self.logger, **cinfo)
2024-01-02 00:51:30,624 T0002: INFO  [D1-V4] [4] spytest/net.py:723 _connect_to_device net_connect = self._do_connect_cinfo(cinfo, retry, msgs, devname)
2024-01-02 00:51:30,625 T0002: INFO  [D1-V4] [5] spytest/net.py:1118 connect_to_device_real net_connect = self._connect_to_device(connection_param, access, retry=retry)
2024-01-02 00:51:30,626 T0002: INFO  [D1-V4] [6] spytest/net.py:1064 connect_to_device show_ver_output = self.connect_to_device_real(access, retry, recon, recover)
2024-01-02 00:51:30,626 T0002: INFO  [D1-V4] [7] utilities/parallel.py:159 _thread_func retvals[index] = func(*args, **kwargs)
2024-01-02 00:51:30,627 T0002: INFO  [D1-V4] [8] utilities/parallel.py:182 exec_foreach2 _thread_func(*args, **kwargs)
2024-01-02 00:51:30,627 T0002: INFO  [D1-V4] [9] spytest/net.py:1584 connect_all_devices rvs, exps = putils.exec_foreach2(faster_init, on_except, self.topo.duts,
2024-01-02 00:51:30,628 T0002: INFO  [D1-V4] [10] utilities/parallel.py:219 _thread_func retvals[index] = func(*args, **kwargs)
2024-01-02 00:51:30,628 T0002: INFO  [D1-V4] --------------------------------------------
2024-01-02 00:51:30,629 T0002: INFO  [D1-V4] ============================================
2024-01-02 00:51:30,629 T0002: WARN  [D1-V4] Exception(None:22): Runtime Exception: Connection Unknown Error..
2024-01-02 00:51:30,629 T0002: INFO  [D1-V4] TRY ALT Authentication: None:22 admin broadcom
2024-01-02 00:51:30,630 T0002: INFO  [D1-V4] ======== Connection: Connection Unknown Error.. ======
2024-01-02 00:51:30,630 T0002: INFO  [D1-V4] Traceback (most recent call last):
2024-01-02 00:51:30,631 T0002: INFO  [D1-V4]   File "/repo/spytest/access/netmiko_connection.py", line 82, in __init__
2024-01-02 00:51:30,631 T0002: INFO  [D1-V4]     super(NetmikoConnection, self).__init__(**kwargs)
2024-01-02 00:51:30,632 T0002: INFO  [D1-V4]   File "/usr/local/lib/python3.8/dist-packages/netmiko/base_connection.py", line 244, in __init__
2024-01-02 00:51:30,633 T0002: INFO  [D1-V4]     raise ValueError("Either ip or host must be set")
2024-01-02 00:51:30,633 T0002: INFO  [D1-V4] ValueError: Either ip or host must be se
2024-01-02 00:51:30,634 T0002: INFO  [D1-V4] StackTraceCallStack:
2024-01-02 00:51:30,634 T0002: INFO  [D1-V4] [0] spytest/access/netmiko_connection.py:104 __init__ self.log_exception(msg, call_stack=True, dump=True)
2024-01-02 00:51:30,635 T0002: INFO  [D1-V4] [1] spytest/access/connection.py:48 _DeviceConnection return NetmikoConnection(**kwargs)
2024-01-02 00:51:30,635 T0002: INFO  [D1-V4] [2] spytest/access/connection.py:160 DeviceConnection hndl = _DeviceConnection(devname, ip_port, logger, **kwargs)
2024-01-02 00:51:30,636 T0002: INFO  [D1-V4] [3] spytest/net.py:694 _do_connect_cinfo net_connect = DeviceConnection(devname=dut_name, logger=self.logger, **cinfo)
2024-01-02 00:51:30,636 T0002: INFO  [D1-V4] [4] spytest/net.py:723 _connect_to_device net_connect = self._do_connect_cinfo(cinfo, retry, msgs, devname)
2024-01-02 00:51:30,637 T0002: INFO  [D1-V4] [5] spytest/net.py:1118 connect_to_device_real net_connect = self._connect_to_device(connection_param, access, retry=retry)
2024-01-02 00:51:30,637 T0002: INFO  [D1-V4] [6] spytest/net.py:1064 connect_to_device show_ver_output = self.connect_to_device_real(access, retry, recon, recover)
2024-01-02 00:51:30,638 T0002: INFO  [D1-V4] [7] utilities/parallel.py:159 _thread_func retvals[index] = func(*args, **kwargs)
2024-01-02 00:51:30,638 T0002: INFO  [D1-V4] [8] utilities/parallel.py:182 exec_foreach2 _thread_func(*args, **kwargs)
2024-01-02 00:51:30,639 T0002: INFO  [D1-V4] [9] spytest/net.py:1584 connect_all_devices rvs, exps = putils.exec_foreach2(faster_init, on_except, self.topo.duts,
2024-01-02 00:51:30,640 T0002: INFO  [D1-V4] [10] utilities/parallel.py:219 _thread_func retvals[index] = func(*args, **kwargs)
2024-01-02 00:51:30,640 T0002: INFO  [D1-V4] --------------------------------------------
2024-01-02 00:51:30,641 T0002: INFO  [D1-V4] ============================================
2024-01-02 00:51:30,641 T0002: WARN  [D1-V4] Exception(None:22): Runtime Exception: Connection Unknown Error..
2024-01-02 00:51:30,641 T0002: INFO  [D1-V4] connection-Err..
2024-01-02 00:51:46,644 T0002: INFO  [D1-V4] Re-Trying 5..
2024-01-02 00:51:46,644 T0002: INFO  [D1-V4] TRY Authentication: None:22 admin YourPaSsWoRd
2024-01-02 00:51:46,646 T0002: INFO  [D1-V4] ======== Connection: Connection Unknown Error.. ======
2024-01-02 00:51:46,649 T0002: INFO  [D1-V4] Traceback (most recent call last):
2024-01-02 00:51:46,651 T0002: INFO  [D1-V4]   File "/repo/spytest/access/netmiko_connection.py", line 82, in __init__
2024-01-02 00:51:46,652 T0002: INFO  [D1-V4]     super(NetmikoConnection, self).__init__(**kwargs)
2024-01-02 00:51:46,654 T0002: INFO  [D1-V4]   File "/usr/local/lib/python3.8/dist-packages/netmiko/base_connection.py", line 244, in __init__
2024-01-02 00:51:46,655 T0002: INFO  [D1-V4]     raise ValueError("Either ip or host must be set")
2024-01-02 00:51:46,655 T0002: INFO  [D1-V4] ValueError: Either ip or host must be se
2024-01-02 00:51:46,656 T0002: INFO  [D1-V4] StackTraceCallStack:
2024-01-02 00:51:46,656 T0002: INFO  [D1-V4] [0] spytest/access/netmiko_connection.py:104 __init__ self.log_exception(msg, call_stack=True, dump=True)
2024-01-02 00:51:46,657 T0002: INFO  [D1-V4] [1] spytest/access/connection.py:48 _DeviceConnection return NetmikoConnection(**kwargs)
2024-01-02 00:51:46,657 T0002: INFO  [D1-V4] [2] spytest/access/connection.py:160 DeviceConnection hndl = _DeviceConnection(devname, ip_port, logger, **kwargs)
2024-01-02 00:51:46,658 T0002: INFO  [D1-V4] [3] spytest/net.py:694 _do_connect_cinfo net_connect = DeviceConnection(devname=dut_name, logger=self.logger, **cinfo)
2024-01-02 00:51:46,658 T0002: INFO  [D1-V4] [4] spytest/net.py:723 _connect_to_device net_connect = self._do_connect_cinfo(cinfo, retry, msgs, devname)
2024-01-02 00:51:46,659 T0002: INFO  [D1-V4] [5] spytest/net.py:1118 connect_to_device_real net_connect = self._connect_to_device(connection_param, access, retry=retry)
2024-01-02 00:51:46,659 T0002: INFO  [D1-V4] [6] spytest/net.py:1064 connect_to_device show_ver_output = self.connect_to_device_real(access, retry, recon, recover)
2024-01-02 00:51:46,660 T0002: INFO  [D1-V4] [7] utilities/parallel.py:159 _thread_func retvals[index] = func(*args, **kwargs)
2024-01-02 00:51:46,660 T0002: INFO  [D1-V4] [8] utilities/parallel.py:182 exec_foreach2 _thread_func(*args, **kwargs)
2024-01-02 00:51:46,661 T0002: INFO  [D1-V4] [9] spytest/net.py:1584 connect_all_devices rvs, exps = putils.exec_foreach2(faster_init, on_except, self.topo.duts,
2024-01-02 00:51:46,661 T0002: INFO  [D1-V4] [10] utilities/parallel.py:219 _thread_func retvals[index] = func(*args, **kwargs)
2024-01-02 00:51:46,662 T0002: INFO  [D1-V4] --------------------------------------------
2024-01-02 00:51:46,662 T0002: INFO  [D1-V4] ============================================
2024-01-02 00:51:46,663 T0002: WARN  [D1-V4] Exception(None:22): Runtime Exception: Connection Unknown Error..
2024-01-02 00:51:46,663 T0002: INFO  [D1-V4] TRY ALT Authentication: None:22 admin broadcom
2024-01-02 00:51:46,663 T0002: INFO  [D1-V4] ======== Connection: Connection Unknown Error.. ======
2024-01-02 00:51:46,664 T0002: INFO  [D1-V4] Traceback (most recent call last):
2024-01-02 00:51:46,664 T0002: INFO  [D1-V4]   File "/repo/spytest/access/netmiko_connection.py", line 82, in __init__
2024-01-02 00:51:46,665 T0002: INFO  [D1-V4]     super(NetmikoConnection, self).__init__(**kwargs)
2024-01-02 00:51:46,665 T0002: INFO  [D1-V4]   File "/usr/local/lib/python3.8/dist-packages/netmiko/base_connection.py", line 244, in __init__
2024-01-02 00:51:46,666 T0002: INFO  [D1-V4]     raise ValueError("Either ip or host must be set")
2024-01-02 00:51:46,666 T0002: INFO  [D1-V4] ValueError: Either ip or host must be se
2024-01-02 00:51:46,667 T0002: INFO  [D1-V4] StackTraceCallStack:
2024-01-02 00:51:46,667 T0002: INFO  [D1-V4] [0] spytest/access/netmiko_connection.py:104 __init__ self.log_exception(msg, call_stack=True, dump=True)
2024-01-02 00:51:46,668 T0002: INFO  [D1-V4] [1] spytest/access/connection.py:48 _DeviceConnection return NetmikoConnection(**kwargs)
2024-01-02 00:51:46,668 T0002: INFO  [D1-V4] [2] spytest/access/connection.py:160 DeviceConnection hndl = _DeviceConnection(devname, ip_port, logger, **kwargs)
2024-01-02 00:51:46,669 T0002: INFO  [D1-V4] [3] spytest/net.py:694 _do_connect_cinfo net_connect = DeviceConnection(devname=dut_name, logger=self.logger, **cinfo)
2024-01-02 00:51:46,670 T0002: INFO  [D1-V4] [4] spytest/net.py:723 _connect_to_device net_connect = self._do_connect_cinfo(cinfo, retry, msgs, devname)
2024-01-02 00:51:46,670 T0002: INFO  [D1-V4] [5] spytest/net.py:1118 connect_to_device_real net_connect = self._connect_to_device(connection_param, access, retry=retry)
2024-01-02 00:51:46,671 T0002: INFO  [D1-V4] [6] spytest/net.py:1064 connect_to_device show_ver_output = self.connect_to_device_real(access, retry, recon, recover)
2024-01-02 00:51:46,671 T0002: INFO  [D1-V4] [7] utilities/parallel.py:159 _thread_func retvals[index] = func(*args, **kwargs)
2024-01-02 00:51:46,672 T0002: INFO  [D1-V4] [8] utilities/parallel.py:182 exec_foreach2 _thread_func(*args, **kwargs)
2024-01-02 00:51:46,672 T0002: INFO  [D1-V4] [9] spytest/net.py:1584 connect_all_devices rvs, exps = putils.exec_foreach2(faster_init, on_except, self.topo.duts,
2024-01-02 00:51:46,673 T0002: INFO  [D1-V4] [10] utilities/parallel.py:219 _thread_func retvals[index] = func(*args, **kwargs)
2024-01-02 00:51:46,673 T0002: INFO  [D1-V4] --------------------------------------------
2024-01-02 00:51:46,674 T0002: INFO  [D1-V4] ============================================
2024-01-02 00:51:46,674 T0002: WARN  [D1-V4] Exception(None:22): Runtime Exception: Connection Unknown Error..
2024-01-02 00:51:46,674 T0002: INFO  [D1-V4] connection-Err..
2024-01-02 00:52:06,696 T0002: INFO  [D1-V4] Re-Trying 6..
2024-01-02 00:52:06,696 T0002: INFO  [D1-V4] TRY Authentication: None:22 admin YourPaSsWoRd
2024-01-02 00:52:06,698 T0002: INFO  [D1-V4] ======== Connection: Connection Unknown Error.. ======
2024-01-02 00:52:06,701 T0002: INFO  [D1-V4] Traceback (most recent call last):
2024-01-02 00:52:06,703 T0002: INFO  [D1-V4]   File "/repo/spytest/access/netmiko_connection.py", line 82, in __init__
2024-01-02 00:52:06,704 T0002: INFO  [D1-V4]     super(NetmikoConnection, self).__init__(**kwargs)
2024-01-02 00:52:06,706 T0002: INFO  [D1-V4]   File "/usr/local/lib/python3.8/dist-packages/netmiko/base_connection.py", line 244, in __init__
2024-01-02 00:52:06,707 T0002: INFO  [D1-V4]     raise ValueError("Either ip or host must be set")
2024-01-02 00:52:06,708 T0002: INFO  [D1-V4] ValueError: Either ip or host must be se
2024-01-02 00:52:06,708 T0002: INFO  [D1-V4] StackTraceCallStack:
2024-01-02 00:52:06,709 T0002: INFO  [D1-V4] [0] spytest/access/netmiko_connection.py:104 __init__ self.log_exception(msg, call_stack=True, dump=True)
2024-01-02 00:52:06,709 T0002: INFO  [D1-V4] [1] spytest/access/connection.py:48 _DeviceConnection return NetmikoConnection(**kwargs)
2024-01-02 00:52:06,710 T0002: INFO  [D1-V4] [2] spytest/access/connection.py:160 DeviceConnection hndl = _DeviceConnection(devname, ip_port, logger, **kwargs)
2024-01-02 00:52:06,710 T0002: INFO  [D1-V4] [3] spytest/net.py:694 _do_connect_cinfo net_connect = DeviceConnection(devname=dut_name, logger=self.logger, **cinfo)
2024-01-02 00:52:06,711 T0002: INFO  [D1-V4] [4] spytest/net.py:723 _connect_to_device net_connect = self._do_connect_cinfo(cinfo, retry, msgs, devname)
2024-01-02 00:52:06,711 T0002: INFO  [D1-V4] [5] spytest/net.py:1118 connect_to_device_real net_connect = self._connect_to_device(connection_param, access, retry=retry)
2024-01-02 00:52:06,712 T0002: INFO  [D1-V4] [6] spytest/net.py:1064 connect_to_device show_ver_output = self.connect_to_device_real(access, retry, recon, recover)
2024-01-02 00:52:06,712 T0002: INFO  [D1-V4] [7] utilities/parallel.py:159 _thread_func retvals[index] = func(*args, **kwargs)
2024-01-02 00:52:06,713 T0002: INFO  [D1-V4] [8] utilities/parallel.py:182 exec_foreach2 _thread_func(*args, **kwargs)
2024-01-02 00:52:06,713 T0002: INFO  [D1-V4] [9] spytest/net.py:1584 connect_all_devices rvs, exps = putils.exec_foreach2(faster_init, on_except, self.topo.duts,
2024-01-02 00:52:06,714 T0002: INFO  [D1-V4] [10] utilities/parallel.py:219 _thread_func retvals[index] = func(*args, **kwargs)
2024-01-02 00:52:06,714 T0002: INFO  [D1-V4] --------------------------------------------
2024-01-02 00:52:06,715 T0002: INFO  [D1-V4] ============================================
2024-01-02 00:52:06,715 T0002: WARN  [D1-V4] Exception(None:22): Runtime Exception: Connection Unknown Error..
2024-01-02 00:52:06,715 T0002: INFO  [D1-V4] TRY ALT Authentication: None:22 admin broadcom
2024-01-02 00:52:06,715 T0002: INFO  [D1-V4] ======== Connection: Connection Unknown Error.. ======
2024-01-02 00:52:06,716 T0002: INFO  [D1-V4] Traceback (most recent call last):
2024-01-02 00:52:06,717 T0002: INFO  [D1-V4]   File "/repo/spytest/access/netmiko_connection.py", line 82, in __init__
2024-01-02 00:52:06,717 T0002: INFO  [D1-V4]     super(NetmikoConnection, self).__init__(**kwargs)
2024-01-02 00:52:06,718 T0002: INFO  [D1-V4]   File "/usr/local/lib/python3.8/dist-packages/netmiko/base_connection.py", line 244, in __init__
2024-01-02 00:52:06,718 T0002: INFO  [D1-V4]     raise ValueError("Either ip or host must be set")
2024-01-02 00:52:06,719 T0002: INFO  [D1-V4] ValueError: Either ip or host must be se
2024-01-02 00:52:06,719 T0002: INFO  [D1-V4] StackTraceCallStack:
2024-01-02 00:52:06,720 T0002: INFO  [D1-V4] [0] spytest/access/netmiko_connection.py:104 __init__ self.log_exception(msg, call_stack=True, dump=True)
2024-01-02 00:52:06,720 T0002: INFO  [D1-V4] [1] spytest/access/connection.py:48 _DeviceConnection return NetmikoConnection(**kwargs)
2024-01-02 00:52:06,721 T0002: INFO  [D1-V4] [2] spytest/access/connection.py:160 DeviceConnection hndl = _DeviceConnection(devname, ip_port, logger, **kwargs)
2024-01-02 00:52:06,721 T0002: INFO  [D1-V4] [3] spytest/net.py:694 _do_connect_cinfo net_connect = DeviceConnection(devname=dut_name, logger=self.logger, **cinfo)
2024-01-02 00:52:06,722 T0002: INFO  [D1-V4] [4] spytest/net.py:723 _connect_to_device net_connect = self._do_connect_cinfo(cinfo, retry, msgs, devname)
2024-01-02 00:52:06,722 T0002: INFO  [D1-V4] [5] spytest/net.py:1118 connect_to_device_real net_connect = self._connect_to_device(connection_param, access, retry=retry)
2024-01-02 00:52:06,723 T0002: INFO  [D1-V4] [6] spytest/net.py:1064 connect_to_device show_ver_output = self.connect_to_device_real(access, retry, recon, recover)
2024-01-02 00:52:06,723 T0002: INFO  [D1-V4] [7] utilities/parallel.py:159 _thread_func retvals[index] = func(*args, **kwargs)
2024-01-02 00:52:06,724 T0002: INFO  [D1-V4] [8] utilities/parallel.py:182 exec_foreach2 _thread_func(*args, **kwargs)
2024-01-02 00:52:06,724 T0002: INFO  [D1-V4] [9] spytest/net.py:1584 connect_all_devices rvs, exps = putils.exec_foreach2(faster_init, on_except, self.topo.duts,
2024-01-02 00:52:06,725 T0002: INFO  [D1-V4] [10] utilities/parallel.py:219 _thread_func retvals[index] = func(*args, **kwargs)
2024-01-02 00:52:06,725 T0002: INFO  [D1-V4] --------------------------------------------
2024-01-02 00:52:06,726 T0002: INFO  [D1-V4] ============================================
2024-01-02 00:52:06,726 T0002: WARN  [D1-V4] Exception(None:22): Runtime Exception: Connection Unknown Error..
2024-01-02 00:52:06,726 T0002: INFO  [D1-V4] connection-Err..
2024-01-02 00:52:30,752 T0002: INFO  [D1-V4] Re-Trying 7..
2024-01-02 00:52:30,752 T0002: INFO  [D1-V4] TRY Authentication: None:22 admin YourPaSsWoRd
2024-01-02 00:52:30,754 T0002: INFO  [D1-V4] ======== Connection: Connection Unknown Error.. ======
2024-01-02 00:52:30,757 T0002: INFO  [D1-V4] Traceback (most recent call last):
2024-01-02 00:52:30,759 T0002: INFO  [D1-V4]   File "/repo/spytest/access/netmiko_connection.py", line 82, in __init__
2024-01-02 00:52:30,761 T0002: INFO  [D1-V4]     super(NetmikoConnection, self).__init__(**kwargs)
2024-01-02 00:52:30,762 T0002: INFO  [D1-V4]   File "/usr/local/lib/python3.8/dist-packages/netmiko/base_connection.py", line 244, in __init__
2024-01-02 00:52:30,763 T0002: INFO  [D1-V4]     raise ValueError("Either ip or host must be set")
2024-01-02 00:52:30,763 T0002: INFO  [D1-V4] ValueError: Either ip or host must be se
2024-01-02 00:52:30,764 T0002: INFO  [D1-V4] StackTraceCallStack:
2024-01-02 00:52:30,764 T0002: INFO  [D1-V4] [0] spytest/access/netmiko_connection.py:104 __init__ self.log_exception(msg, call_stack=True, dump=True)
2024-01-02 00:52:30,765 T0002: INFO  [D1-V4] [1] spytest/access/connection.py:48 _DeviceConnection return NetmikoConnection(**kwargs)
2024-01-02 00:52:30,765 T0002: INFO  [D1-V4] [2] spytest/access/connection.py:160 DeviceConnection hndl = _DeviceConnection(devname, ip_port, logger, **kwargs)
2024-01-02 00:52:30,766 T0002: INFO  [D1-V4] [3] spytest/net.py:694 _do_connect_cinfo net_connect = DeviceConnection(devname=dut_name, logger=self.logger, **cinfo)
2024-01-02 00:52:30,766 T0002: INFO  [D1-V4] [4] spytest/net.py:723 _connect_to_device net_connect = self._do_connect_cinfo(cinfo, retry, msgs, devname)
2024-01-02 00:52:30,767 T0002: INFO  [D1-V4] [5] spytest/net.py:1118 connect_to_device_real net_connect = self._connect_to_device(connection_param, access, retry=retry)
2024-01-02 00:52:30,767 T0002: INFO  [D1-V4] [6] spytest/net.py:1064 connect_to_device show_ver_output = self.connect_to_device_real(access, retry, recon, recover)
2024-01-02 00:52:30,768 T0002: INFO  [D1-V4] [7] utilities/parallel.py:159 _thread_func retvals[index] = func(*args, **kwargs)
2024-01-02 00:52:30,768 T0002: INFO  [D1-V4] [8] utilities/parallel.py:182 exec_foreach2 _thread_func(*args, **kwargs)
2024-01-02 00:52:30,769 T0002: INFO  [D1-V4] [9] spytest/net.py:1584 connect_all_devices rvs, exps = putils.exec_foreach2(faster_init, on_except, self.topo.duts,
2024-01-02 00:52:30,769 T0002: INFO  [D1-V4] [10] utilities/parallel.py:219 _thread_func retvals[index] = func(*args, **kwargs)
2024-01-02 00:52:30,770 T0002: INFO  [D1-V4] --------------------------------------------
2024-01-02 00:52:30,770 T0002: INFO  [D1-V4] ============================================
2024-01-02 00:52:30,771 T0002: WARN  [D1-V4] Exception(None:22): Runtime Exception: Connection Unknown Error..
2024-01-02 00:52:30,771 T0002: INFO  [D1-V4] TRY ALT Authentication: None:22 admin broadcom
2024-01-02 00:52:30,771 T0002: INFO  [D1-V4] ======== Connection: Connection Unknown Error.. ======
2024-01-02 00:52:30,772 T0002: INFO  [D1-V4] Traceback (most recent call last):
2024-01-02 00:52:30,772 T0002: INFO  [D1-V4]   File "/repo/spytest/access/netmiko_connection.py", line 82, in __init__
2024-01-02 00:52:30,773 T0002: INFO  [D1-V4]     super(NetmikoConnection, self).__init__(**kwargs)
2024-01-02 00:52:30,773 T0002: INFO  [D1-V4]   File "/usr/local/lib/python3.8/dist-packages/netmiko/base_connection.py", line 244, in __init__
2024-01-02 00:52:30,774 T0002: INFO  [D1-V4]     raise ValueError("Either ip or host must be set")
2024-01-02 00:52:30,774 T0002: INFO  [D1-V4] ValueError: Either ip or host must be se
2024-01-02 00:52:30,775 T0002: INFO  [D1-V4] StackTraceCallStack:
2024-01-02 00:52:30,775 T0002: INFO  [D1-V4] [0] spytest/access/netmiko_connection.py:104 __init__ self.log_exception(msg, call_stack=True, dump=True)
2024-01-02 00:52:30,776 T0002: INFO  [D1-V4] [1] spytest/access/connection.py:48 _DeviceConnection return NetmikoConnection(**kwargs)
2024-01-02 00:52:30,776 T0002: INFO  [D1-V4] [2] spytest/access/connection.py:160 DeviceConnection hndl = _DeviceConnection(devname, ip_port, logger, **kwargs)
2024-01-02 00:52:30,777 T0002: INFO  [D1-V4] [3] spytest/net.py:694 _do_connect_cinfo net_connect = DeviceConnection(devname=dut_name, logger=self.logger, **cinfo)
2024-01-02 00:52:30,777 T0002: INFO  [D1-V4] [4] spytest/net.py:723 _connect_to_device net_connect = self._do_connect_cinfo(cinfo, retry, msgs, devname)
2024-01-02 00:52:30,778 T0002: INFO  [D1-V4] [5] spytest/net.py:1118 connect_to_device_real net_connect = self._connect_to_device(connection_param, access, retry=retry)
2024-01-02 00:52:30,778 T0002: INFO  [D1-V4] [6] spytest/net.py:1064 connect_to_device show_ver_output = self.connect_to_device_real(access, retry, recon, recover)
2024-01-02 00:52:30,779 T0002: INFO  [D1-V4] [7] utilities/parallel.py:159 _thread_func retvals[index] = func(*args, **kwargs)
2024-01-02 00:52:30,779 T0002: INFO  [D1-V4] [8] utilities/parallel.py:182 exec_foreach2 _thread_func(*args, **kwargs)
2024-01-02 00:52:30,780 T0002: INFO  [D1-V4] [9] spytest/net.py:1584 connect_all_devices rvs, exps = putils.exec_foreach2(faster_init, on_except, self.topo.duts,
2024-01-02 00:52:30,781 T0002: INFO  [D1-V4] [10] utilities/parallel.py:219 _thread_func retvals[index] = func(*args, **kwargs)
2024-01-02 00:52:30,781 T0002: INFO  [D1-V4] --------------------------------------------
2024-01-02 00:52:30,781 T0002: INFO  [D1-V4] ============================================
2024-01-02 00:52:30,782 T0002: WARN  [D1-V4] Exception(None:22): Runtime Exception: Connection Unknown Error..
2024-01-02 00:52:30,782 T0002: INFO  [D1-V4] connection-Err..
2024-01-02 00:52:58,812 T0002: INFO  [D1-V4] Re-Trying 8..
2024-01-02 00:52:58,812 T0002: INFO  [D1-V4] TRY Authentication: None:22 admin YourPaSsWoRd
2024-01-02 00:52:58,814 T0002: INFO  [D1-V4] ======== Connection: Connection Unknown Error.. ======
2024-01-02 00:52:58,816 T0002: INFO  [D1-V4] Traceback (most recent call last):
2024-01-02 00:52:58,818 T0002: INFO  [D1-V4]   File "/repo/spytest/access/netmiko_connection.py", line 82, in __init__
2024-01-02 00:52:58,820 T0002: INFO  [D1-V4]     super(NetmikoConnection, self).__init__(**kwargs)
2024-01-02 00:52:58,822 T0002: INFO  [D1-V4]   File "/usr/local/lib/python3.8/dist-packages/netmiko/base_connection.py", line 244, in __init__
2024-01-02 00:52:58,823 T0002: INFO  [D1-V4]     raise ValueError("Either ip or host must be set")
2024-01-02 00:52:58,823 T0002: INFO  [D1-V4] ValueError: Either ip or host must be se
2024-01-02 00:52:58,824 T0002: INFO  [D1-V4] StackTraceCallStack:
2024-01-02 00:52:58,824 T0002: INFO  [D1-V4] [0] spytest/access/netmiko_connection.py:104 __init__ self.log_exception(msg, call_stack=True, dump=True)
2024-01-02 00:52:58,825 T0002: INFO  [D1-V4] [1] spytest/access/connection.py:48 _DeviceConnection return NetmikoConnection(**kwargs)
2024-01-02 00:52:58,825 T0002: INFO  [D1-V4] [2] spytest/access/connection.py:160 DeviceConnection hndl = _DeviceConnection(devname, ip_port, logger, **kwargs)
2024-01-02 00:52:58,826 T0002: INFO  [D1-V4] [3] spytest/net.py:694 _do_connect_cinfo net_connect = DeviceConnection(devname=dut_name, logger=self.logger, **cinfo)
2024-01-02 00:52:58,826 T0002: INFO  [D1-V4] [4] spytest/net.py:723 _connect_to_device net_connect = self._do_connect_cinfo(cinfo, retry, msgs, devname)
2024-01-02 00:52:58,827 T0002: INFO  [D1-V4] [5] spytest/net.py:1118 connect_to_device_real net_connect = self._connect_to_device(connection_param, access, retry=retry)
2024-01-02 00:52:58,827 T0002: INFO  [D1-V4] [6] spytest/net.py:1064 connect_to_device show_ver_output = self.connect_to_device_real(access, retry, recon, recover)
2024-01-02 00:52:58,828 T0002: INFO  [D1-V4] [7] utilities/parallel.py:159 _thread_func retvals[index] = func(*args, **kwargs)
2024-01-02 00:52:58,828 T0002: INFO  [D1-V4] [8] utilities/parallel.py:182 exec_foreach2 _thread_func(*args, **kwargs)
2024-01-02 00:52:58,829 T0002: INFO  [D1-V4] [9] spytest/net.py:1584 connect_all_devices rvs, exps = putils.exec_foreach2(faster_init, on_except, self.topo.duts,
2024-01-02 00:52:58,829 T0002: INFO  [D1-V4] [10] utilities/parallel.py:219 _thread_func retvals[index] = func(*args, **kwargs)
2024-01-02 00:52:58,830 T0002: INFO  [D1-V4] --------------------------------------------
2024-01-02 00:52:58,830 T0002: INFO  [D1-V4] ============================================
2024-01-02 00:52:58,830 T0002: WARN  [D1-V4] Exception(None:22): Runtime Exception: Connection Unknown Error..
2024-01-02 00:52:58,830 T0002: INFO  [D1-V4] TRY ALT Authentication: None:22 admin broadcom
2024-01-02 00:52:58,831 T0002: INFO  [D1-V4] ======== Connection: Connection Unknown Error.. ======
2024-01-02 00:52:58,832 T0002: INFO  [D1-V4] Traceback (most recent call last):
2024-01-02 00:52:58,832 T0002: INFO  [D1-V4]   File "/repo/spytest/access/netmiko_connection.py", line 82, in __init__
2024-01-02 00:52:58,833 T0002: INFO  [D1-V4]     super(NetmikoConnection, self).__init__(**kwargs)
2024-01-02 00:52:58,833 T0002: INFO  [D1-V4]   File "/usr/local/lib/python3.8/dist-packages/netmiko/base_connection.py", line 244, in __init__
2024-01-02 00:52:58,834 T0002: INFO  [D1-V4]     raise ValueError("Either ip or host must be set")
2024-01-02 00:52:58,834 T0002: INFO  [D1-V4] ValueError: Either ip or host must be se
2024-01-02 00:52:58,835 T0002: INFO  [D1-V4] StackTraceCallStack:
2024-01-02 00:52:58,835 T0002: INFO  [D1-V4] [0] spytest/access/netmiko_connection.py:104 __init__ self.log_exception(msg, call_stack=True, dump=True)
2024-01-02 00:52:58,836 T0002: INFO  [D1-V4] [1] spytest/access/connection.py:48 _DeviceConnection return NetmikoConnection(**kwargs)
2024-01-02 00:52:58,836 T0002: INFO  [D1-V4] [2] spytest/access/connection.py:160 DeviceConnection hndl = _DeviceConnection(devname, ip_port, logger, **kwargs)
2024-01-02 00:52:58,837 T0002: INFO  [D1-V4] [3] spytest/net.py:694 _do_connect_cinfo net_connect = DeviceConnection(devname=dut_name, logger=self.logger, **cinfo)
2024-01-02 00:52:58,837 T0002: INFO  [D1-V4] [4] spytest/net.py:723 _connect_to_device net_connect = self._do_connect_cinfo(cinfo, retry, msgs, devname)
2024-01-02 00:52:58,838 T0002: INFO  [D1-V4] [5] spytest/net.py:1118 connect_to_device_real net_connect = self._connect_to_device(connection_param, access, retry=retry)
2024-01-02 00:52:58,838 T0002: INFO  [D1-V4] [6] spytest/net.py:1064 connect_to_device show_ver_output = self.connect_to_device_real(access, retry, recon, recover)
2024-01-02 00:52:58,839 T0002: INFO  [D1-V4] [7] utilities/parallel.py:159 _thread_func retvals[index] = func(*args, **kwargs)
2024-01-02 00:52:58,839 T0002: INFO  [D1-V4] [8] utilities/parallel.py:182 exec_foreach2 _thread_func(*args, **kwargs)
2024-01-02 00:52:58,840 T0002: INFO  [D1-V4] [9] spytest/net.py:1584 connect_all_devices rvs, exps = putils.exec_foreach2(faster_init, on_except, self.topo.duts,
2024-01-02 00:52:58,840 T0002: INFO  [D1-V4] [10] utilities/parallel.py:219 _thread_func retvals[index] = func(*args, **kwargs)
2024-01-02 00:52:58,841 T0002: INFO  [D1-V4] --------------------------------------------
2024-01-02 00:52:58,841 T0002: INFO  [D1-V4] ============================================
2024-01-02 00:52:58,841 T0002: WARN  [D1-V4] Exception(None:22): Runtime Exception: Connection Unknown Error..
2024-01-02 00:52:58,842 T0002: INFO  [D1-V4] connection-Err..
2024-01-02 00:53:30,875 T0002: INFO  [D1-V4] Re-Trying 9..
2024-01-02 00:53:30,876 T0002: INFO  [D1-V4] TRY Authentication: None:22 admin YourPaSsWoRd
2024-01-02 00:53:30,878 T0002: INFO  [D1-V4] ======== Connection: Connection Unknown Error.. ======
2024-01-02 00:53:30,880 T0002: INFO  [D1-V4] Traceback (most recent call last):
2024-01-02 00:53:30,882 T0002: INFO  [D1-V4]   File "/repo/spytest/access/netmiko_connection.py", line 82, in __init__
2024-01-02 00:53:30,884 T0002: INFO  [D1-V4]     super(NetmikoConnection, self).__init__(**kwargs)
2024-01-02 00:53:30,886 T0002: INFO  [D1-V4]   File "/usr/local/lib/python3.8/dist-packages/netmiko/base_connection.py", line 244, in __init__
2024-01-02 00:53:30,887 T0002: INFO  [D1-V4]     raise ValueError("Either ip or host must be set")
2024-01-02 00:53:30,887 T0002: INFO  [D1-V4] ValueError: Either ip or host must be se
2024-01-02 00:53:30,888 T0002: INFO  [D1-V4] StackTraceCallStack:
2024-01-02 00:53:30,888 T0002: INFO  [D1-V4] [0] spytest/access/netmiko_connection.py:104 __init__ self.log_exception(msg, call_stack=True, dump=True)
2024-01-02 00:53:30,889 T0002: INFO  [D1-V4] [1] spytest/access/connection.py:48 _DeviceConnection return NetmikoConnection(**kwargs)
2024-01-02 00:53:30,889 T0002: INFO  [D1-V4] [2] spytest/access/connection.py:160 DeviceConnection hndl = _DeviceConnection(devname, ip_port, logger, **kwargs)
2024-01-02 00:53:30,890 T0002: INFO  [D1-V4] [3] spytest/net.py:694 _do_connect_cinfo net_connect = DeviceConnection(devname=dut_name, logger=self.logger, **cinfo)
2024-01-02 00:53:30,890 T0002: INFO  [D1-V4] [4] spytest/net.py:723 _connect_to_device net_connect = self._do_connect_cinfo(cinfo, retry, msgs, devname)
2024-01-02 00:53:30,891 T0002: INFO  [D1-V4] [5] spytest/net.py:1118 connect_to_device_real net_connect = self._connect_to_device(connection_param, access, retry=retry)
2024-01-02 00:53:30,891 T0002: INFO  [D1-V4] [6] spytest/net.py:1064 connect_to_device show_ver_output = self.connect_to_device_real(access, retry, recon, recover)
2024-01-02 00:53:30,892 T0002: INFO  [D1-V4] [7] utilities/parallel.py:159 _thread_func retvals[index] = func(*args, **kwargs)
2024-01-02 00:53:30,892 T0002: INFO  [D1-V4] [8] utilities/parallel.py:182 exec_foreach2 _thread_func(*args, **kwargs)
2024-01-02 00:53:30,893 T0002: INFO  [D1-V4] [9] spytest/net.py:1584 connect_all_devices rvs, exps = putils.exec_foreach2(faster_init, on_except, self.topo.duts,
2024-01-02 00:53:30,893 T0002: INFO  [D1-V4] [10] utilities/parallel.py:219 _thread_func retvals[index] = func(*args, **kwargs)
2024-01-02 00:53:30,894 T0002: INFO  [D1-V4] --------------------------------------------
2024-01-02 00:53:30,894 T0002: INFO  [D1-V4] ============================================
2024-01-02 00:53:30,894 T0002: WARN  [D1-V4] Exception(None:22): Runtime Exception: Connection Unknown Error..
2024-01-02 00:53:30,895 T0002: INFO  [D1-V4] TRY ALT Authentication: None:22 admin broadcom
2024-01-02 00:53:30,895 T0002: INFO  [D1-V4] ======== Connection: Connection Unknown Error.. ======
2024-01-02 00:53:30,896 T0002: INFO  [D1-V4] Traceback (most recent call last):
2024-01-02 00:53:30,896 T0002: INFO  [D1-V4]   File "/repo/spytest/access/netmiko_connection.py", line 82, in __init__
2024-01-02 00:53:30,897 T0002: INFO  [D1-V4]     super(NetmikoConnection, self).__init__(**kwargs)
2024-01-02 00:53:30,897 T0002: INFO  [D1-V4]   File "/usr/local/lib/python3.8/dist-packages/netmiko/base_connection.py", line 244, in __init__
2024-01-02 00:53:30,898 T0002: INFO  [D1-V4]     raise ValueError("Either ip or host must be set")
2024-01-02 00:53:30,898 T0002: INFO  [D1-V4] ValueError: Either ip or host must be se
2024-01-02 00:53:30,899 T0002: INFO  [D1-V4] StackTraceCallStack:
2024-01-02 00:53:30,899 T0002: INFO  [D1-V4] [0] spytest/access/netmiko_connection.py:104 __init__ self.log_exception(msg, call_stack=True, dump=True)
2024-01-02 00:53:30,900 T0002: INFO  [D1-V4] [1] spytest/access/connection.py:48 _DeviceConnection return NetmikoConnection(**kwargs)
2024-01-02 00:53:30,900 T0002: INFO  [D1-V4] [2] spytest/access/connection.py:160 DeviceConnection hndl = _DeviceConnection(devname, ip_port, logger, **kwargs)
2024-01-02 00:53:30,901 T0002: INFO  [D1-V4] [3] spytest/net.py:694 _do_connect_cinfo net_connect = DeviceConnection(devname=dut_name, logger=self.logger, **cinfo)
2024-01-02 00:53:30,901 T0002: INFO  [D1-V4] [4] spytest/net.py:723 _connect_to_device net_connect = self._do_connect_cinfo(cinfo, retry, msgs, devname)
2024-01-02 00:53:30,902 T0002: INFO  [D1-V4] [5] spytest/net.py:1118 connect_to_device_real net_connect = self._connect_to_device(connection_param, access, retry=retry)
2024-01-02 00:53:30,902 T0002: INFO  [D1-V4] [6] spytest/net.py:1064 connect_to_device show_ver_output = self.connect_to_device_real(access, retry, recon, recover)
2024-01-02 00:53:30,903 T0002: INFO  [D1-V4] [7] utilities/parallel.py:159 _thread_func retvals[index] = func(*args, **kwargs)
2024-01-02 00:53:30,903 T0002: INFO  [D1-V4] [8] utilities/parallel.py:182 exec_foreach2 _thread_func(*args, **kwargs)
2024-01-02 00:53:30,904 T0002: INFO  [D1-V4] [9] spytest/net.py:1584 connect_all_devices rvs, exps = putils.exec_foreach2(faster_init, on_except, self.topo.duts,
2024-01-02 00:53:30,904 T0002: INFO  [D1-V4] [10] utilities/parallel.py:219 _thread_func retvals[index] = func(*args, **kwargs)
2024-01-02 00:53:30,905 T0002: INFO  [D1-V4] --------------------------------------------
2024-01-02 00:53:30,905 T0002: INFO  [D1-V4] ============================================
2024-01-02 00:53:30,905 T0002: WARN  [D1-V4] Exception(None:22): Runtime Exception: Connection Unknown Error..
2024-01-02 00:53:30,906 T0002: INFO  [D1-V4] connection-Err..
2024-01-02 00:54:06,944 T0002: INFO  [D1-V4] Re-Trying 10..
2024-01-02 00:54:06,944 T0002: INFO  [D1-V4] TRY Authentication: None:22 admin YourPaSsWoRd
2024-01-02 00:54:06,946 T0002: INFO  [D1-V4] ======== Connection: Connection Unknown Error.. ======
2024-01-02 00:54:06,948 T0002: INFO  [D1-V4] Traceback (most recent call last):
2024-01-02 00:54:06,950 T0002: INFO  [D1-V4]   File "/repo/spytest/access/netmiko_connection.py", line 82, in __init__
2024-01-02 00:54:06,952 T0002: INFO  [D1-V4]     super(NetmikoConnection, self).__init__(**kwargs)
2024-01-02 00:54:06,954 T0002: INFO  [D1-V4]   File "/usr/local/lib/python3.8/dist-packages/netmiko/base_connection.py", line 244, in __init__
2024-01-02 00:54:06,955 T0002: INFO  [D1-V4]     raise ValueError("Either ip or host must be set")
2024-01-02 00:54:06,955 T0002: INFO  [D1-V4] ValueError: Either ip or host must be se
2024-01-02 00:54:06,956 T0002: INFO  [D1-V4] StackTraceCallStack:
2024-01-02 00:54:06,956 T0002: INFO  [D1-V4] [0] spytest/access/netmiko_connection.py:104 __init__ self.log_exception(msg, call_stack=True, dump=True)
2024-01-02 00:54:06,957 T0002: INFO  [D1-V4] [1] spytest/access/connection.py:48 _DeviceConnection return NetmikoConnection(**kwargs)
2024-01-02 00:54:06,957 T0002: INFO  [D1-V4] [2] spytest/access/connection.py:160 DeviceConnection hndl = _DeviceConnection(devname, ip_port, logger, **kwargs)
2024-01-02 00:54:06,958 T0002: INFO  [D1-V4] [3] spytest/net.py:694 _do_connect_cinfo net_connect = DeviceConnection(devname=dut_name, logger=self.logger, **cinfo)
2024-01-02 00:54:06,958 T0002: INFO  [D1-V4] [4] spytest/net.py:723 _connect_to_device net_connect = self._do_connect_cinfo(cinfo, retry, msgs, devname)
2024-01-02 00:54:06,959 T0002: INFO  [D1-V4] [5] spytest/net.py:1118 connect_to_device_real net_connect = self._connect_to_device(connection_param, access, retry=retry)
2024-01-02 00:54:06,960 T0002: INFO  [D1-V4] [6] spytest/net.py:1064 connect_to_device show_ver_output = self.connect_to_device_real(access, retry, recon, recover)
2024-01-02 00:54:06,960 T0002: INFO  [D1-V4] [7] utilities/parallel.py:159 _thread_func retvals[index] = func(*args, **kwargs)
2024-01-02 00:54:06,961 T0002: INFO  [D1-V4] [8] utilities/parallel.py:182 exec_foreach2 _thread_func(*args, **kwargs)
2024-01-02 00:54:06,961 T0002: INFO  [D1-V4] [9] spytest/net.py:1584 connect_all_devices rvs, exps = putils.exec_foreach2(faster_init, on_except, self.topo.duts,
2024-01-02 00:54:06,962 T0002: INFO  [D1-V4] [10] utilities/parallel.py:219 _thread_func retvals[index] = func(*args, **kwargs)
2024-01-02 00:54:06,962 T0002: INFO  [D1-V4] --------------------------------------------
2024-01-02 00:54:06,962 T0002: INFO  [D1-V4] ============================================
2024-01-02 00:54:06,963 T0002: WARN  [D1-V4] Exception(None:22): Runtime Exception: Connection Unknown Error..
2024-01-02 00:54:06,963 T0002: INFO  [D1-V4] TRY ALT Authentication: None:22 admin broadcom
2024-01-02 00:54:06,963 T0002: INFO  [D1-V4] ======== Connection: Connection Unknown Error.. ======
2024-01-02 00:54:06,964 T0002: INFO  [D1-V4] Traceback (most recent call last):
2024-01-02 00:54:06,964 T0002: INFO  [D1-V4]   File "/repo/spytest/access/netmiko_connection.py", line 82, in __init__
2024-01-02 00:54:06,965 T0002: INFO  [D1-V4]     super(NetmikoConnection, self).__init__(**kwargs)
2024-01-02 00:54:06,965 T0002: INFO  [D1-V4]   File "/usr/local/lib/python3.8/dist-packages/netmiko/base_connection.py", line 244, in __init__
2024-01-02 00:54:06,966 T0002: INFO  [D1-V4]     raise ValueError("Either ip or host must be set")
2024-01-02 00:54:06,966 T0002: INFO  [D1-V4] ValueError: Either ip or host must be se
2024-01-02 00:54:06,967 T0002: INFO  [D1-V4] StackTraceCallStack:
2024-01-02 00:54:06,967 T0002: INFO  [D1-V4] [0] spytest/access/netmiko_connection.py:104 __init__ self.log_exception(msg, call_stack=True, dump=True)
2024-01-02 00:54:06,968 T0002: INFO  [D1-V4] [1] spytest/access/connection.py:48 _DeviceConnection return NetmikoConnection(**kwargs)
2024-01-02 00:54:06,968 T0002: INFO  [D1-V4] [2] spytest/access/connection.py:160 DeviceConnection hndl = _DeviceConnection(devname, ip_port, logger, **kwargs)
2024-01-02 00:54:06,969 T0002: INFO  [D1-V4] [3] spytest/net.py:694 _do_connect_cinfo net_connect = DeviceConnection(devname=dut_name, logger=self.logger, **cinfo)
2024-01-02 00:54:06,969 T0002: INFO  [D1-V4] [4] spytest/net.py:723 _connect_to_device net_connect = self._do_connect_cinfo(cinfo, retry, msgs, devname)
2024-01-02 00:54:06,970 T0002: INFO  [D1-V4] [5] spytest/net.py:1118 connect_to_device_real net_connect = self._connect_to_device(connection_param, access, retry=retry)
2024-01-02 00:54:06,970 T0002: INFO  [D1-V4] [6] spytest/net.py:1064 connect_to_device show_ver_output = self.connect_to_device_real(access, retry, recon, recover)
2024-01-02 00:54:06,971 T0002: INFO  [D1-V4] [7] utilities/parallel.py:159 _thread_func retvals[index] = func(*args, **kwargs)
2024-01-02 00:54:06,971 T0002: INFO  [D1-V4] [8] utilities/parallel.py:182 exec_foreach2 _thread_func(*args, **kwargs)
2024-01-02 00:54:06,972 T0002: INFO  [D1-V4] [9] spytest/net.py:1584 connect_all_devices rvs, exps = putils.exec_foreach2(faster_init, on_except, self.topo.duts,
2024-01-02 00:54:06,973 T0002: INFO  [D1-V4] [10] utilities/parallel.py:219 _thread_func retvals[index] = func(*args, **kwargs)
2024-01-02 00:54:06,973 T0002: INFO  [D1-V4] --------------------------------------------
2024-01-02 00:54:06,973 T0002: INFO  [D1-V4] ============================================
2024-01-02 00:54:06,974 T0002: WARN  [D1-V4] Exception(None:22): Runtime Exception: Connection Unknown Error..
2024-01-02 00:54:06,974 T0002: INFO  [D1-V4] connection-Err..
2024-01-02 00:54:47,016 T0002: INFO  [D1-V4] Re-Trying 11..
2024-01-02 00:54:47,016 T0002: INFO  [D1-V4] TRY Authentication: None:22 admin YourPaSsWoRd
2024-01-02 00:54:47,018 T0002: INFO  [D1-V4] ======== Connection: Connection Unknown Error.. ======
2024-01-02 00:54:47,021 T0002: INFO  [D1-V4] Traceback (most recent call last):
2024-01-02 00:54:47,022 T0002: INFO  [D1-V4]   File "/repo/spytest/access/netmiko_connection.py", line 82, in __init__
2024-01-02 00:54:47,024 T0002: INFO  [D1-V4]     super(NetmikoConnection, self).__init__(**kwargs)
2024-01-02 00:54:47,026 T0002: INFO  [D1-V4]   File "/usr/local/lib/python3.8/dist-packages/netmiko/base_connection.py", line 244, in __init__
2024-01-02 00:54:47,027 T0002: INFO  [D1-V4]     raise ValueError("Either ip or host must be set")
2024-01-02 00:54:47,027 T0002: INFO  [D1-V4] ValueError: Either ip or host must be se
2024-01-02 00:54:47,028 T0002: INFO  [D1-V4] StackTraceCallStack:
2024-01-02 00:54:47,028 T0002: INFO  [D1-V4] [0] spytest/access/netmiko_connection.py:104 __init__ self.log_exception(msg, call_stack=True, dump=True)
2024-01-02 00:54:47,029 T0002: INFO  [D1-V4] [1] spytest/access/connection.py:48 _DeviceConnection return NetmikoConnection(**kwargs)
2024-01-02 00:54:47,030 T0002: INFO  [D1-V4] [2] spytest/access/connection.py:160 DeviceConnection hndl = _DeviceConnection(devname, ip_port, logger, **kwargs)
2024-01-02 00:54:47,030 T0002: INFO  [D1-V4] [3] spytest/net.py:694 _do_connect_cinfo net_connect = DeviceConnection(devname=dut_name, logger=self.logger, **cinfo)
2024-01-02 00:54:47,031 T0002: INFO  [D1-V4] [4] spytest/net.py:723 _connect_to_device net_connect = self._do_connect_cinfo(cinfo, retry, msgs, devname)
2024-01-02 00:54:47,031 T0002: INFO  [D1-V4] [5] spytest/net.py:1118 connect_to_device_real net_connect = self._connect_to_device(connection_param, access, retry=retry)
2024-01-02 00:54:47,032 T0002: INFO  [D1-V4] [6] spytest/net.py:1064 connect_to_device show_ver_output = self.connect_to_device_real(access, retry, recon, recover)
2024-01-02 00:54:47,032 T0002: INFO  [D1-V4] [7] utilities/parallel.py:159 _thread_func retvals[index] = func(*args, **kwargs)
2024-01-02 00:54:47,033 T0002: INFO  [D1-V4] [8] utilities/parallel.py:182 exec_foreach2 _thread_func(*args, **kwargs)
2024-01-02 00:54:47,033 T0002: INFO  [D1-V4] [9] spytest/net.py:1584 connect_all_devices rvs, exps = putils.exec_foreach2(faster_init, on_except, self.topo.duts,
2024-01-02 00:54:47,034 T0002: INFO  [D1-V4] [10] utilities/parallel.py:219 _thread_func retvals[index] = func(*args, **kwargs)
2024-01-02 00:54:47,034 T0002: INFO  [D1-V4] --------------------------------------------
2024-01-02 00:54:47,035 T0002: INFO  [D1-V4] ============================================
2024-01-02 00:54:47,035 T0002: WARN  [D1-V4] Exception(None:22): Runtime Exception: Connection Unknown Error..
2024-01-02 00:54:47,035 T0002: INFO  [D1-V4] TRY ALT Authentication: None:22 admin broadcom
2024-01-02 00:54:47,036 T0002: INFO  [D1-V4] ======== Connection: Connection Unknown Error.. ======
2024-01-02 00:54:47,036 T0002: INFO  [D1-V4] Traceback (most recent call last):
2024-01-02 00:54:47,037 T0002: INFO  [D1-V4]   File "/repo/spytest/access/netmiko_connection.py", line 82, in __init__
2024-01-02 00:54:47,037 T0002: INFO  [D1-V4]     super(NetmikoConnection, self).__init__(**kwargs)
2024-01-02 00:54:47,038 T0002: INFO  [D1-V4]   File "/usr/local/lib/python3.8/dist-packages/netmiko/base_connection.py", line 244, in __init__
2024-01-02 00:54:47,038 T0002: INFO  [D1-V4]     raise ValueError("Either ip or host must be set")
2024-01-02 00:54:47,039 T0002: INFO  [D1-V4] ValueError: Either ip or host must be se
2024-01-02 00:54:47,039 T0002: INFO  [D1-V4] StackTraceCallStack:
2024-01-02 00:54:47,040 T0002: INFO  [D1-V4] [0] spytest/access/netmiko_connection.py:104 __init__ self.log_exception(msg, call_stack=True, dump=True)
2024-01-02 00:54:47,040 T0002: INFO  [D1-V4] [1] spytest/access/connection.py:48 _DeviceConnection return NetmikoConnection(**kwargs)
2024-01-02 00:54:47,041 T0002: INFO  [D1-V4] [2] spytest/access/connection.py:160 DeviceConnection hndl = _DeviceConnection(devname, ip_port, logger, **kwargs)
2024-01-02 00:54:47,041 T0002: INFO  [D1-V4] [3] spytest/net.py:694 _do_connect_cinfo net_connect = DeviceConnection(devname=dut_name, logger=self.logger, **cinfo)
2024-01-02 00:54:47,042 T0002: INFO  [D1-V4] [4] spytest/net.py:723 _connect_to_device net_connect = self._do_connect_cinfo(cinfo, retry, msgs, devname)
2024-01-02 00:54:47,042 T0002: INFO  [D1-V4] [5] spytest/net.py:1118 connect_to_device_real net_connect = self._connect_to_device(connection_param, access, retry=retry)
2024-01-02 00:54:47,043 T0002: INFO  [D1-V4] [6] spytest/net.py:1064 connect_to_device show_ver_output = self.connect_to_device_real(access, retry, recon, recover)
2024-01-02 00:54:47,043 T0002: INFO  [D1-V4] [7] utilities/parallel.py:159 _thread_func retvals[index] = func(*args, **kwargs)
2024-01-02 00:54:47,044 T0002: INFO  [D1-V4] [8] utilities/parallel.py:182 exec_foreach2 _thread_func(*args, **kwargs)
2024-01-02 00:54:47,044 T0002: INFO  [D1-V4] [9] spytest/net.py:1584 connect_all_devices rvs, exps = putils.exec_foreach2(faster_init, on_except, self.topo.duts,
2024-01-02 00:54:47,045 T0002: INFO  [D1-V4] [10] utilities/parallel.py:219 _thread_func retvals[index] = func(*args, **kwargs)
2024-01-02 00:54:47,045 T0002: INFO  [D1-V4] --------------------------------------------
2024-01-02 00:54:47,046 T0002: INFO  [D1-V4] ============================================
2024-01-02 00:54:47,046 T0002: WARN  [D1-V4] Exception(None:22): Runtime Exception: Connection Unknown Error..
2024-01-02 00:54:47,046 T0002: INFO  [D1-V4] connection-Err..
2024-01-02 00:54:47,047 T0002: INFO  [D1-V4] Cannot connect: None:22
2024-01-02 00:54:47,052 T0002: INFO  [D1-V4] Existing Connections: pconn(fd=14, family=<AddressFamily.AF_INET: 2>, type=<SocketKind.SOCK_STREAM: 1>, laddr=addr(ip='127.0.0.1', port=38172), raddr=addr(ip='127.0.0.1', port=8009), status='ESTABLISHED')
2024-01-02 00:54:47,052 T0002: ERROR [D1-V4] Failed to connect to device D1-V4
2024-01-02 00:54:47,052 T0002: ERROR [D1-V4] Failed to connect to device
2024-01-02 00:54:47,053 T0000: ERROR Failed to connect (['V4'])
2024-01-02 00:54:47,053 T0000: INFO  --FINISH--RUN--4 @559
