2024-01-02 00:51:09,088 T0002: INFO  Connecting to device (V4): sonic_ssh: None:22 ..
2024-01-02 00:51:09,089 T0002: INFO  TRY Authentication: None:22 admin YourPaSsWoRd
2024-01-02 00:51:09,090 T0002: INFO  ======== Connection: Connection Unknown Error.. ======
2024-01-02 00:51:09,091 T0002: INFO  Traceback (most recent call last):
2024-01-02 00:51:09,092 T0002: INFO    File "/repo/spytest/access/netmiko_connection.py", line 82, in __init__
2024-01-02 00:51:09,092 T0002: INFO      super(NetmikoConnection, self).__init__(**kwargs)
2024-01-02 00:51:09,093 T0002: INFO    File "/usr/local/lib/python3.8/dist-packages/netmiko/base_connection.py", line 244, in __init__
2024-01-02 00:51:09,093 T0002: INFO      raise ValueError("Either ip or host must be set")
2024-01-02 00:51:09,094 T0002: INFO  ValueError: Either ip or host must be se
2024-01-02 00:51:09,095 T0002: INFO  StackTraceCallStack:
2024-01-02 00:51:09,095 T0002: INFO  [0] spytest/access/netmiko_connection.py:104 __init__ self.log_exception(msg, call_stack=True, dump=True)
2024-01-02 00:51:09,096 T0002: INFO  [1] spytest/access/connection.py:48 _DeviceConnection return NetmikoConnection(**kwargs)
2024-01-02 00:51:09,096 T0002: INFO  [2] spytest/access/connection.py:160 DeviceConnection hndl = _DeviceConnection(devname, ip_port, logger, **kwargs)
2024-01-02 00:51:09,097 T0002: INFO  [3] spytest/net.py:694 _do_connect_cinfo net_connect = DeviceConnection(devname=dut_name, logger=self.logger, **cinfo)
2024-01-02 00:51:09,098 T0002: INFO  [4] spytest/net.py:723 _connect_to_device net_connect = self._do_connect_cinfo(cinfo, retry, msgs, devname)
2024-01-02 00:51:09,098 T0002: INFO  [5] spytest/net.py:1118 connect_to_device_real net_connect = self._connect_to_device(connection_param, access, retry=retry)
2024-01-02 00:51:09,099 T0002: INFO  [6] spytest/net.py:1064 connect_to_device show_ver_output = self.connect_to_device_real(access, retry, recon, recover)
2024-01-02 00:51:09,100 T0002: INFO  [7] utilities/parallel.py:159 _thread_func retvals[index] = func(*args, **kwargs)
2024-01-02 00:51:09,100 T0002: INFO  [8] utilities/parallel.py:182 exec_foreach2 _thread_func(*args, **kwargs)
2024-01-02 00:51:09,101 T0002: INFO  [9] spytest/net.py:1584 connect_all_devices rvs, exps = putils.exec_foreach2(faster_init, on_except, self.topo.duts,
2024-01-02 00:51:09,101 T0002: INFO  [10] utilities/parallel.py:219 _thread_func retvals[index] = func(*args, **kwargs)
2024-01-02 00:51:09,102 T0002: INFO  --------------------------------------------
2024-01-02 00:51:09,102 T0002: INFO  ============================================
2024-01-02 00:51:09,103 T0002: WARN  Exception(None:22): Runtime Exception: Connection Unknown Error..
2024-01-02 00:51:09,103 T0002: INFO  TRY ALT Authentication: None:22 admin broadcom
2024-01-02 00:51:09,103 T0002: INFO  ======== Connection: Connection Unknown Error.. ======
2024-01-02 00:51:09,104 T0002: INFO  Traceback (most recent call last):
2024-01-02 00:51:09,105 T0002: INFO    File "/repo/spytest/access/netmiko_connection.py", line 82, in __init__
2024-01-02 00:51:09,105 T0002: INFO      super(NetmikoConnection, self).__init__(**kwargs)
2024-01-02 00:51:09,106 T0002: INFO    File "/usr/local/lib/python3.8/dist-packages/netmiko/base_connection.py", line 244, in __init__
2024-01-02 00:51:09,106 T0002: INFO      raise ValueError("Either ip or host must be set")
2024-01-02 00:51:09,107 T0002: INFO  ValueError: Either ip or host must be se
2024-01-02 00:51:09,108 T0002: INFO  StackTraceCallStack:
2024-01-02 00:51:09,108 T0002: INFO  [0] spytest/access/netmiko_connection.py:104 __init__ self.log_exception(msg, call_stack=True, dump=True)
2024-01-02 00:51:09,109 T0002: INFO  [1] spytest/access/connection.py:48 _DeviceConnection return NetmikoConnection(**kwargs)
2024-01-02 00:51:09,109 T0002: INFO  [2] spytest/access/connection.py:160 DeviceConnection hndl = _DeviceConnection(devname, ip_port, logger, **kwargs)
2024-01-02 00:51:09,110 T0002: INFO  [3] spytest/net.py:694 _do_connect_cinfo net_connect = DeviceConnection(devname=dut_name, logger=self.logger, **cinfo)
2024-01-02 00:51:09,111 T0002: INFO  [4] spytest/net.py:723 _connect_to_device net_connect = self._do_connect_cinfo(cinfo, retry, msgs, devname)
2024-01-02 00:51:09,111 T0002: INFO  [5] spytest/net.py:1118 connect_to_device_real net_connect = self._connect_to_device(connection_param, access, retry=retry)
2024-01-02 00:51:09,112 T0002: INFO  [6] spytest/net.py:1064 connect_to_device show_ver_output = self.connect_to_device_real(access, retry, recon, recover)
2024-01-02 00:51:09,113 T0002: INFO  [7] utilities/parallel.py:159 _thread_func retvals[index] = func(*args, **kwargs)
2024-01-02 00:51:09,113 T0002: INFO  [8] utilities/parallel.py:182 exec_foreach2 _thread_func(*args, **kwargs)
2024-01-02 00:51:09,114 T0002: INFO  [9] spytest/net.py:1584 connect_all_devices rvs, exps = putils.exec_foreach2(faster_init, on_except, self.topo.duts,
2024-01-02 00:51:09,115 T0002: INFO  [10] utilities/parallel.py:219 _thread_func retvals[index] = func(*args, **kwargs)
2024-01-02 00:51:09,115 T0002: INFO  --------------------------------------------
2024-01-02 00:51:09,116 T0002: INFO  ============================================
2024-01-02 00:51:09,116 T0002: WARN  Exception(None:22): Runtime Exception: Connection Unknown Error..
2024-01-02 00:51:09,116 T0002: INFO  connection-Err..
2024-01-02 00:51:13,122 T0002: INFO  Re-Trying 2..
2024-01-02 00:51:13,122 T0002: INFO  TRY Authentication: None:22 admin YourPaSsWoRd
2024-01-02 00:51:13,124 T0002: INFO  ======== Connection: Connection Unknown Error.. ======
2024-01-02 00:51:13,127 T0002: INFO  Traceback (most recent call last):
2024-01-02 00:51:13,129 T0002: INFO    File "/repo/spytest/access/netmiko_connection.py", line 82, in __init__
2024-01-02 00:51:13,131 T0002: INFO      super(NetmikoConnection, self).__init__(**kwargs)
2024-01-02 00:51:13,133 T0002: INFO    File "/usr/local/lib/python3.8/dist-packages/netmiko/base_connection.py", line 244, in __init__
2024-01-02 00:51:13,134 T0002: INFO      raise ValueError("Either ip or host must be set")
2024-01-02 00:51:13,135 T0002: INFO  ValueError: Either ip or host must be se
2024-01-02 00:51:13,135 T0002: INFO  StackTraceCallStack:
2024-01-02 00:51:13,136 T0002: INFO  [0] spytest/access/netmiko_connection.py:104 __init__ self.log_exception(msg, call_stack=True, dump=True)
2024-01-02 00:51:13,136 T0002: INFO  [1] spytest/access/connection.py:48 _DeviceConnection return NetmikoConnection(**kwargs)
2024-01-02 00:51:13,137 T0002: INFO  [2] spytest/access/connection.py:160 DeviceConnection hndl = _DeviceConnection(devname, ip_port, logger, **kwargs)
2024-01-02 00:51:13,137 T0002: INFO  [3] spytest/net.py:694 _do_connect_cinfo net_connect = DeviceConnection(devname=dut_name, logger=self.logger, **cinfo)
2024-01-02 00:51:13,138 T0002: INFO  [4] spytest/net.py:723 _connect_to_device net_connect = self._do_connect_cinfo(cinfo, retry, msgs, devname)
2024-01-02 00:51:13,139 T0002: INFO  [5] spytest/net.py:1118 connect_to_device_real net_connect = self._connect_to_device(connection_param, access, retry=retry)
2024-01-02 00:51:13,139 T0002: INFO  [6] spytest/net.py:1064 connect_to_device show_ver_output = self.connect_to_device_real(access, retry, recon, recover)
2024-01-02 00:51:13,140 T0002: INFO  [7] utilities/parallel.py:159 _thread_func retvals[index] = func(*args, **kwargs)
2024-01-02 00:51:13,140 T0002: INFO  [8] utilities/parallel.py:182 exec_foreach2 _thread_func(*args, **kwargs)
2024-01-02 00:51:13,141 T0002: INFO  [9] spytest/net.py:1584 connect_all_devices rvs, exps = putils.exec_foreach2(faster_init, on_except, self.topo.duts,
2024-01-02 00:51:13,141 T0002: INFO  [10] utilities/parallel.py:219 _thread_func retvals[index] = func(*args, **kwargs)
2024-01-02 00:51:13,142 T0002: INFO  --------------------------------------------
2024-01-02 00:51:13,142 T0002: INFO  ============================================
2024-01-02 00:51:13,143 T0002: WARN  Exception(None:22): Runtime Exception: Connection Unknown Error..
2024-01-02 00:51:13,143 T0002: INFO  TRY ALT Authentication: None:22 admin broadcom
2024-01-02 00:51:13,143 T0002: INFO  ======== Connection: Connection Unknown Error.. ======
2024-01-02 00:51:13,144 T0002: INFO  Traceback (most recent call last):
2024-01-02 00:51:13,144 T0002: INFO    File "/repo/spytest/access/netmiko_connection.py", line 82, in __init__
2024-01-02 00:51:13,145 T0002: INFO      super(NetmikoConnection, self).__init__(**kwargs)
2024-01-02 00:51:13,146 T0002: INFO    File "/usr/local/lib/python3.8/dist-packages/netmiko/base_connection.py", line 244, in __init__
2024-01-02 00:51:13,146 T0002: INFO      raise ValueError("Either ip or host must be set")
2024-01-02 00:51:13,147 T0002: INFO  ValueError: Either ip or host must be se
2024-01-02 00:51:13,147 T0002: INFO  StackTraceCallStack:
2024-01-02 00:51:13,148 T0002: INFO  [0] spytest/access/netmiko_connection.py:104 __init__ self.log_exception(msg, call_stack=True, dump=True)
2024-01-02 00:51:13,148 T0002: INFO  [1] spytest/access/connection.py:48 _DeviceConnection return NetmikoConnection(**kwargs)
2024-01-02 00:51:13,149 T0002: INFO  [2] spytest/access/connection.py:160 DeviceConnection hndl = _DeviceConnection(devname, ip_port, logger, **kwargs)
2024-01-02 00:51:13,150 T0002: INFO  [3] spytest/net.py:694 _do_connect_cinfo net_connect = DeviceConnection(devname=dut_name, logger=self.logger, **cinfo)
2024-01-02 00:51:13,150 T0002: INFO  [4] spytest/net.py:723 _connect_to_device net_connect = self._do_connect_cinfo(cinfo, retry, msgs, devname)
2024-01-02 00:51:13,151 T0002: INFO  [5] spytest/net.py:1118 connect_to_device_real net_connect = self._connect_to_device(connection_param, access, retry=retry)
2024-01-02 00:51:13,151 T0002: INFO  [6] spytest/net.py:1064 connect_to_device show_ver_output = self.connect_to_device_real(access, retry, recon, recover)
2024-01-02 00:51:13,152 T0002: INFO  [7] utilities/parallel.py:159 _thread_func retvals[index] = func(*args, **kwargs)
2024-01-02 00:51:13,153 T0002: INFO  [8] utilities/parallel.py:182 exec_foreach2 _thread_func(*args, **kwargs)
2024-01-02 00:51:13,153 T0002: INFO  [9] spytest/net.py:1584 connect_all_devices rvs, exps = putils.exec_foreach2(faster_init, on_except, self.topo.duts,
2024-01-02 00:51:13,154 T0002: INFO  [10] utilities/parallel.py:219 _thread_func retvals[index] = func(*args, **kwargs)
2024-01-02 00:51:13,154 T0002: INFO  --------------------------------------------
2024-01-02 00:51:13,155 T0002: INFO  ============================================
2024-01-02 00:51:13,155 T0002: WARN  Exception(None:22): Runtime Exception: Connection Unknown Error..
2024-01-02 00:51:13,155 T0002: INFO  connection-Err..
2024-01-02 00:51:16,333 T0000: INFO  
2024-01-02 00:51:16,333 T0000: INFO  ================== batch/test_spytest_infra_1.py::test_spytest_infra_first ==================
2024-01-02 00:51:16,340 T0000: INFO  Report():batch/test_spytest_infra_1.py::test_spytest_infra_first 0:00:00 module configuration failed.  @5445
